2022-12-29 16:14:15,640 Exception on /lookup [POST]
Traceback (most recent call last):
  File "src\pymssql\_pymssql.pyx", line 646, in pymssql._pymssql.connect
  File "src\pymssql\_mssql.pyx", line 2108, in pymssql._mssql.connect
  File "src\pymssql\_mssql.pyx", line 700, in pymssql._mssql.MSSQLConnection.__init__
  File "src\pymssql\_mssql.pyx", line 1817, in pymssql._mssql.maybe_raise_MSSQLDatabaseException
  File "src\pymssql\_mssql.pyx", line 1834, in pymssql._mssql.raise_MSSQLDatabaseException
pymssql._mssql.MSSQLDatabaseException: (18456, b"Login failed for user 'CDL_VPOD'.DB-Lib error message 20018, severity 14:\nGeneral SQL Server error: Check messages from the SQL Server\nDB-Lib error message 20002, severity 9:\nAdaptive Server connection failed (172.24.32.210)\nDB-Lib error message 20002, severity 9:\nAdaptive Server connection failed (172.24.32.210)\n")

During handling of the above exception, another exception occurred:

Traceback (most recent call last):
  File "D:\CDL\CDL-Barcode-Checker\cdl_barcode_checker\lib\site-packages\sqlalchemy\engine\base.py", line 2336, in _wrap_pool_connect
    return fn()
  File "D:\CDL\CDL-Barcode-Checker\cdl_barcode_checker\lib\site-packages\sqlalchemy\pool\base.py", line 364, in connect
    return _ConnectionFairy._checkout(self)
  File "D:\CDL\CDL-Barcode-Checker\cdl_barcode_checker\lib\site-packages\sqlalchemy\pool\base.py", line 778, in _checkout
    fairy = _ConnectionRecord.checkout(pool)
  File "D:\CDL\CDL-Barcode-Checker\cdl_barcode_checker\lib\site-packages\sqlalchemy\pool\base.py", line 495, in checkout
    rec = pool._do_get()
  File "D:\CDL\CDL-Barcode-Checker\cdl_barcode_checker\lib\site-packages\sqlalchemy\pool\impl.py", line 139, in _do_get
    with util.safe_reraise():
  File "D:\CDL\CDL-Barcode-Checker\cdl_barcode_checker\lib\site-packages\sqlalchemy\util\langhelpers.py", line 68, in __exit__
    compat.raise_(
  File "D:\CDL\CDL-Barcode-Checker\cdl_barcode_checker\lib\site-packages\sqlalchemy\util\compat.py", line 182, in raise_
    raise exception
  File "D:\CDL\CDL-Barcode-Checker\cdl_barcode_checker\lib\site-packages\sqlalchemy\pool\impl.py", line 137, in _do_get
    return self._create_connection()
  File "D:\CDL\CDL-Barcode-Checker\cdl_barcode_checker\lib\site-packages\sqlalchemy\pool\base.py", line 309, in _create_connection
    return _ConnectionRecord(self)
  File "D:\CDL\CDL-Barcode-Checker\cdl_barcode_checker\lib\site-packages\sqlalchemy\pool\base.py", line 440, in __init__
    self.__connect(first_connect_check=True)
  File "D:\CDL\CDL-Barcode-Checker\cdl_barcode_checker\lib\site-packages\sqlalchemy\pool\base.py", line 660, in __connect
    with util.safe_reraise():
  File "D:\CDL\CDL-Barcode-Checker\cdl_barcode_checker\lib\site-packages\sqlalchemy\util\langhelpers.py", line 68, in __exit__
    compat.raise_(
  File "D:\CDL\CDL-Barcode-Checker\cdl_barcode_checker\lib\site-packages\sqlalchemy\util\compat.py", line 182, in raise_
    raise exception
  File "D:\CDL\CDL-Barcode-Checker\cdl_barcode_checker\lib\site-packages\sqlalchemy\pool\base.py", line 656, in __connect
    connection = pool._invoke_creator(self)
  File "D:\CDL\CDL-Barcode-Checker\cdl_barcode_checker\lib\site-packages\sqlalchemy\engine\strategies.py", line 114, in connect
    return dialect.connect(*cargs, **cparams)
  File "D:\CDL\CDL-Barcode-Checker\cdl_barcode_checker\lib\site-packages\sqlalchemy\engine\default.py", line 508, in connect
    return self.dbapi.connect(*cargs, **cparams)
  File "src\pymssql\_pymssql.pyx", line 652, in pymssql._pymssql.connect
pymssql._pymssql.OperationalError: (18456, b"Login failed for user 'CDL_VPOD'.DB-Lib error message 20018, severity 14:\nGeneral SQL Server error: Check messages from the SQL Server\nDB-Lib error message 20002, severity 9:\nAdaptive Server connection failed (172.24.32.210)\nDB-Lib error message 20002, severity 9:\nAdaptive Server connection failed (172.24.32.210)\n")

The above exception was the direct cause of the following exception:

Traceback (most recent call last):
  File "D:\CDL\CDL-Barcode-Checker\cdl_barcode_checker\lib\site-packages\flask\app.py", line 2525, in wsgi_app
    response = self.full_dispatch_request()
  File "D:\CDL\CDL-Barcode-Checker\cdl_barcode_checker\lib\site-packages\flask\app.py", line 1822, in full_dispatch_request
    rv = self.handle_user_exception(e)
  File "D:\CDL\CDL-Barcode-Checker\cdl_barcode_checker\lib\site-packages\flask\app.py", line 1820, in full_dispatch_request
    rv = self.dispatch_request()
  File "D:\CDL\CDL-Barcode-Checker\cdl_barcode_checker\lib\site-packages\flask\app.py", line 1796, in dispatch_request
    return self.ensure_sync(self.view_functions[rule.endpoint])(**view_args)
  File "D:\CDL\CDL-Barcode-Checker\.\barcode_checker\main\routes.py", line 34, in lookup_rte
    records = [r._asdict() for r in dbquery.all()]
  File "D:\CDL\CDL-Barcode-Checker\cdl_barcode_checker\lib\site-packages\sqlalchemy\orm\query.py", line 3373, in all
    return list(self)
  File "D:\CDL\CDL-Barcode-Checker\cdl_barcode_checker\lib\site-packages\sqlalchemy\orm\query.py", line 3535, in __iter__
    return self._execute_and_instances(context)
  File "D:\CDL\CDL-Barcode-Checker\cdl_barcode_checker\lib\site-packages\sqlalchemy\orm\query.py", line 3556, in _execute_and_instances
    conn = self._get_bind_args(
  File "D:\CDL\CDL-Barcode-Checker\cdl_barcode_checker\lib\site-packages\sqlalchemy\orm\query.py", line 3571, in _get_bind_args
    return fn(
  File "D:\CDL\CDL-Barcode-Checker\cdl_barcode_checker\lib\site-packages\sqlalchemy\orm\query.py", line 3550, in _connection_from_session
    conn = self.session.connection(**kw)
  File "D:\CDL\CDL-Barcode-Checker\cdl_barcode_checker\lib\site-packages\sqlalchemy\orm\session.py", line 1142, in connection
    return self._connection_for_bind(
  File "D:\CDL\CDL-Barcode-Checker\cdl_barcode_checker\lib\site-packages\sqlalchemy\orm\session.py", line 1150, in _connection_for_bind
    return self.transaction._connection_for_bind(
  File "D:\CDL\CDL-Barcode-Checker\cdl_barcode_checker\lib\site-packages\sqlalchemy\orm\session.py", line 433, in _connection_for_bind
    conn = bind._contextual_connect()
  File "D:\CDL\CDL-Barcode-Checker\cdl_barcode_checker\lib\site-packages\sqlalchemy\engine\base.py", line 2302, in _contextual_connect
    self._wrap_pool_connect(self.pool.connect, None),
  File "D:\CDL\CDL-Barcode-Checker\cdl_barcode_checker\lib\site-packages\sqlalchemy\engine\base.py", line 2339, in _wrap_pool_connect
    Connection._handle_dbapi_exception_noconnection(
  File "D:\CDL\CDL-Barcode-Checker\cdl_barcode_checker\lib\site-packages\sqlalchemy\engine\base.py", line 1583, in _handle_dbapi_exception_noconnection
    util.raise_(
  File "D:\CDL\CDL-Barcode-Checker\cdl_barcode_checker\lib\site-packages\sqlalchemy\util\compat.py", line 182, in raise_
    raise exception
  File "D:\CDL\CDL-Barcode-Checker\cdl_barcode_checker\lib\site-packages\sqlalchemy\engine\base.py", line 2336, in _wrap_pool_connect
    return fn()
  File "D:\CDL\CDL-Barcode-Checker\cdl_barcode_checker\lib\site-packages\sqlalchemy\pool\base.py", line 364, in connect
    return _ConnectionFairy._checkout(self)
  File "D:\CDL\CDL-Barcode-Checker\cdl_barcode_checker\lib\site-packages\sqlalchemy\pool\base.py", line 778, in _checkout
    fairy = _ConnectionRecord.checkout(pool)
  File "D:\CDL\CDL-Barcode-Checker\cdl_barcode_checker\lib\site-packages\sqlalchemy\pool\base.py", line 495, in checkout
    rec = pool._do_get()
  File "D:\CDL\CDL-Barcode-Checker\cdl_barcode_checker\lib\site-packages\sqlalchemy\pool\impl.py", line 139, in _do_get
    with util.safe_reraise():
  File "D:\CDL\CDL-Barcode-Checker\cdl_barcode_checker\lib\site-packages\sqlalchemy\util\langhelpers.py", line 68, in __exit__
    compat.raise_(
  File "D:\CDL\CDL-Barcode-Checker\cdl_barcode_checker\lib\site-packages\sqlalchemy\util\compat.py", line 182, in raise_
    raise exception
  File "D:\CDL\CDL-Barcode-Checker\cdl_barcode_checker\lib\site-packages\sqlalchemy\pool\impl.py", line 137, in _do_get
    return self._create_connection()
  File "D:\CDL\CDL-Barcode-Checker\cdl_barcode_checker\lib\site-packages\sqlalchemy\pool\base.py", line 309, in _create_connection
    return _ConnectionRecord(self)
  File "D:\CDL\CDL-Barcode-Checker\cdl_barcode_checker\lib\site-packages\sqlalchemy\pool\base.py", line 440, in __init__
    self.__connect(first_connect_check=True)
  File "D:\CDL\CDL-Barcode-Checker\cdl_barcode_checker\lib\site-packages\sqlalchemy\pool\base.py", line 660, in __connect
    with util.safe_reraise():
  File "D:\CDL\CDL-Barcode-Checker\cdl_barcode_checker\lib\site-packages\sqlalchemy\util\langhelpers.py", line 68, in __exit__
    compat.raise_(
  File "D:\CDL\CDL-Barcode-Checker\cdl_barcode_checker\lib\site-packages\sqlalchemy\util\compat.py", line 182, in raise_
    raise exception
  File "D:\CDL\CDL-Barcode-Checker\cdl_barcode_checker\lib\site-packages\sqlalchemy\pool\base.py", line 656, in __connect
    connection = pool._invoke_creator(self)
  File "D:\CDL\CDL-Barcode-Checker\cdl_barcode_checker\lib\site-packages\sqlalchemy\engine\strategies.py", line 114, in connect
    return dialect.connect(*cargs, **cparams)
  File "D:\CDL\CDL-Barcode-Checker\cdl_barcode_checker\lib\site-packages\sqlalchemy\engine\default.py", line 508, in connect
    return self.dbapi.connect(*cargs, **cparams)
  File "src\pymssql\_pymssql.pyx", line 652, in pymssql._pymssql.connect
sqlalchemy.exc.OperationalError: (pymssql._pymssql.OperationalError) (18456, b"Login failed for user 'CDL_VPOD'.DB-Lib error message 20018, severity 14:\nGeneral SQL Server error: Check messages from the SQL Server\nDB-Lib error message 20002, severity 9:\nAdaptive Server connection failed (172.24.32.210)\nDB-Lib error message 20002, severity 9:\nAdaptive Server connection failed (172.24.32.210)\n")
(Background on this error at: http://sqlalche.me/e/13/e3q8)
2022-12-29 16:14:25,339 Exception on /lookup [POST]
Traceback (most recent call last):
  File "src\pymssql\_pymssql.pyx", line 646, in pymssql._pymssql.connect
  File "src\pymssql\_mssql.pyx", line 2108, in pymssql._mssql.connect
  File "src\pymssql\_mssql.pyx", line 700, in pymssql._mssql.MSSQLConnection.__init__
  File "src\pymssql\_mssql.pyx", line 1817, in pymssql._mssql.maybe_raise_MSSQLDatabaseException
  File "src\pymssql\_mssql.pyx", line 1834, in pymssql._mssql.raise_MSSQLDatabaseException
pymssql._mssql.MSSQLDatabaseException: (18456, b'DB-Lib error message 20018, severity 14:\nGeneral SQL Server error: Check messages from the SQL Server\nDB-Lib error message 20002, severity 9:\nAdaptive Server connection failed (172.24.32.210)\nDB-Lib error message 20002, severity 9:\nAdaptive Server connection failed (172.24.32.210)\n')

During handling of the above exception, another exception occurred:

Traceback (most recent call last):
  File "D:\CDL\CDL-Barcode-Checker\cdl_barcode_checker\lib\site-packages\sqlalchemy\engine\base.py", line 2336, in _wrap_pool_connect
    return fn()
  File "D:\CDL\CDL-Barcode-Checker\cdl_barcode_checker\lib\site-packages\sqlalchemy\pool\base.py", line 364, in connect
    return _ConnectionFairy._checkout(self)
  File "D:\CDL\CDL-Barcode-Checker\cdl_barcode_checker\lib\site-packages\sqlalchemy\pool\base.py", line 778, in _checkout
    fairy = _ConnectionRecord.checkout(pool)
  File "D:\CDL\CDL-Barcode-Checker\cdl_barcode_checker\lib\site-packages\sqlalchemy\pool\base.py", line 495, in checkout
    rec = pool._do_get()
  File "D:\CDL\CDL-Barcode-Checker\cdl_barcode_checker\lib\site-packages\sqlalchemy\pool\impl.py", line 139, in _do_get
    with util.safe_reraise():
  File "D:\CDL\CDL-Barcode-Checker\cdl_barcode_checker\lib\site-packages\sqlalchemy\util\langhelpers.py", line 68, in __exit__
    compat.raise_(
  File "D:\CDL\CDL-Barcode-Checker\cdl_barcode_checker\lib\site-packages\sqlalchemy\util\compat.py", line 182, in raise_
    raise exception
  File "D:\CDL\CDL-Barcode-Checker\cdl_barcode_checker\lib\site-packages\sqlalchemy\pool\impl.py", line 137, in _do_get
    return self._create_connection()
  File "D:\CDL\CDL-Barcode-Checker\cdl_barcode_checker\lib\site-packages\sqlalchemy\pool\base.py", line 309, in _create_connection
    return _ConnectionRecord(self)
  File "D:\CDL\CDL-Barcode-Checker\cdl_barcode_checker\lib\site-packages\sqlalchemy\pool\base.py", line 440, in __init__
    self.__connect(first_connect_check=True)
  File "D:\CDL\CDL-Barcode-Checker\cdl_barcode_checker\lib\site-packages\sqlalchemy\pool\base.py", line 660, in __connect
    with util.safe_reraise():
  File "D:\CDL\CDL-Barcode-Checker\cdl_barcode_checker\lib\site-packages\sqlalchemy\util\langhelpers.py", line 68, in __exit__
    compat.raise_(
  File "D:\CDL\CDL-Barcode-Checker\cdl_barcode_checker\lib\site-packages\sqlalchemy\util\compat.py", line 182, in raise_
    raise exception
  File "D:\CDL\CDL-Barcode-Checker\cdl_barcode_checker\lib\site-packages\sqlalchemy\pool\base.py", line 656, in __connect
    connection = pool._invoke_creator(self)
  File "D:\CDL\CDL-Barcode-Checker\cdl_barcode_checker\lib\site-packages\sqlalchemy\engine\strategies.py", line 114, in connect
    return dialect.connect(*cargs, **cparams)
  File "D:\CDL\CDL-Barcode-Checker\cdl_barcode_checker\lib\site-packages\sqlalchemy\engine\default.py", line 508, in connect
    return self.dbapi.connect(*cargs, **cparams)
  File "src\pymssql\_pymssql.pyx", line 652, in pymssql._pymssql.connect
pymssql._pymssql.OperationalError: (18456, b'DB-Lib error message 20018, severity 14:\nGeneral SQL Server error: Check messages from the SQL Server\nDB-Lib error message 20002, severity 9:\nAdaptive Server connection failed (172.24.32.210)\nDB-Lib error message 20002, severity 9:\nAdaptive Server connection failed (172.24.32.210)\n')

The above exception was the direct cause of the following exception:

Traceback (most recent call last):
  File "D:\CDL\CDL-Barcode-Checker\cdl_barcode_checker\lib\site-packages\flask\app.py", line 2525, in wsgi_app
    response = self.full_dispatch_request()
  File "D:\CDL\CDL-Barcode-Checker\cdl_barcode_checker\lib\site-packages\flask\app.py", line 1822, in full_dispatch_request
    rv = self.handle_user_exception(e)
  File "D:\CDL\CDL-Barcode-Checker\cdl_barcode_checker\lib\site-packages\flask\app.py", line 1820, in full_dispatch_request
    rv = self.dispatch_request()
  File "D:\CDL\CDL-Barcode-Checker\cdl_barcode_checker\lib\site-packages\flask\app.py", line 1796, in dispatch_request
    return self.ensure_sync(self.view_functions[rule.endpoint])(**view_args)
  File "D:\CDL\CDL-Barcode-Checker\.\barcode_checker\main\routes.py", line 34, in lookup_rte
    records = [r._asdict() for r in dbquery.all()]
  File "D:\CDL\CDL-Barcode-Checker\cdl_barcode_checker\lib\site-packages\sqlalchemy\orm\query.py", line 3373, in all
    return list(self)
  File "D:\CDL\CDL-Barcode-Checker\cdl_barcode_checker\lib\site-packages\sqlalchemy\orm\query.py", line 3535, in __iter__
    return self._execute_and_instances(context)
  File "D:\CDL\CDL-Barcode-Checker\cdl_barcode_checker\lib\site-packages\sqlalchemy\orm\query.py", line 3556, in _execute_and_instances
    conn = self._get_bind_args(
  File "D:\CDL\CDL-Barcode-Checker\cdl_barcode_checker\lib\site-packages\sqlalchemy\orm\query.py", line 3571, in _get_bind_args
    return fn(
  File "D:\CDL\CDL-Barcode-Checker\cdl_barcode_checker\lib\site-packages\sqlalchemy\orm\query.py", line 3550, in _connection_from_session
    conn = self.session.connection(**kw)
  File "D:\CDL\CDL-Barcode-Checker\cdl_barcode_checker\lib\site-packages\sqlalchemy\orm\session.py", line 1142, in connection
    return self._connection_for_bind(
  File "D:\CDL\CDL-Barcode-Checker\cdl_barcode_checker\lib\site-packages\sqlalchemy\orm\session.py", line 1150, in _connection_for_bind
    return self.transaction._connection_for_bind(
  File "D:\CDL\CDL-Barcode-Checker\cdl_barcode_checker\lib\site-packages\sqlalchemy\orm\session.py", line 433, in _connection_for_bind
    conn = bind._contextual_connect()
  File "D:\CDL\CDL-Barcode-Checker\cdl_barcode_checker\lib\site-packages\sqlalchemy\engine\base.py", line 2302, in _contextual_connect
    self._wrap_pool_connect(self.pool.connect, None),
  File "D:\CDL\CDL-Barcode-Checker\cdl_barcode_checker\lib\site-packages\sqlalchemy\engine\base.py", line 2339, in _wrap_pool_connect
    Connection._handle_dbapi_exception_noconnection(
  File "D:\CDL\CDL-Barcode-Checker\cdl_barcode_checker\lib\site-packages\sqlalchemy\engine\base.py", line 1583, in _handle_dbapi_exception_noconnection
    util.raise_(
  File "D:\CDL\CDL-Barcode-Checker\cdl_barcode_checker\lib\site-packages\sqlalchemy\util\compat.py", line 182, in raise_
    raise exception
  File "D:\CDL\CDL-Barcode-Checker\cdl_barcode_checker\lib\site-packages\sqlalchemy\engine\base.py", line 2336, in _wrap_pool_connect
    return fn()
  File "D:\CDL\CDL-Barcode-Checker\cdl_barcode_checker\lib\site-packages\sqlalchemy\pool\base.py", line 364, in connect
    return _ConnectionFairy._checkout(self)
  File "D:\CDL\CDL-Barcode-Checker\cdl_barcode_checker\lib\site-packages\sqlalchemy\pool\base.py", line 778, in _checkout
    fairy = _ConnectionRecord.checkout(pool)
  File "D:\CDL\CDL-Barcode-Checker\cdl_barcode_checker\lib\site-packages\sqlalchemy\pool\base.py", line 495, in checkout
    rec = pool._do_get()
  File "D:\CDL\CDL-Barcode-Checker\cdl_barcode_checker\lib\site-packages\sqlalchemy\pool\impl.py", line 139, in _do_get
    with util.safe_reraise():
  File "D:\CDL\CDL-Barcode-Checker\cdl_barcode_checker\lib\site-packages\sqlalchemy\util\langhelpers.py", line 68, in __exit__
    compat.raise_(
  File "D:\CDL\CDL-Barcode-Checker\cdl_barcode_checker\lib\site-packages\sqlalchemy\util\compat.py", line 182, in raise_
    raise exception
  File "D:\CDL\CDL-Barcode-Checker\cdl_barcode_checker\lib\site-packages\sqlalchemy\pool\impl.py", line 137, in _do_get
    return self._create_connection()
  File "D:\CDL\CDL-Barcode-Checker\cdl_barcode_checker\lib\site-packages\sqlalchemy\pool\base.py", line 309, in _create_connection
    return _ConnectionRecord(self)
  File "D:\CDL\CDL-Barcode-Checker\cdl_barcode_checker\lib\site-packages\sqlalchemy\pool\base.py", line 440, in __init__
    self.__connect(first_connect_check=True)
  File "D:\CDL\CDL-Barcode-Checker\cdl_barcode_checker\lib\site-packages\sqlalchemy\pool\base.py", line 660, in __connect
    with util.safe_reraise():
  File "D:\CDL\CDL-Barcode-Checker\cdl_barcode_checker\lib\site-packages\sqlalchemy\util\langhelpers.py", line 68, in __exit__
    compat.raise_(
  File "D:\CDL\CDL-Barcode-Checker\cdl_barcode_checker\lib\site-packages\sqlalchemy\util\compat.py", line 182, in raise_
    raise exception
  File "D:\CDL\CDL-Barcode-Checker\cdl_barcode_checker\lib\site-packages\sqlalchemy\pool\base.py", line 656, in __connect
    connection = pool._invoke_creator(self)
  File "D:\CDL\CDL-Barcode-Checker\cdl_barcode_checker\lib\site-packages\sqlalchemy\engine\strategies.py", line 114, in connect
    return dialect.connect(*cargs, **cparams)
  File "D:\CDL\CDL-Barcode-Checker\cdl_barcode_checker\lib\site-packages\sqlalchemy\engine\default.py", line 508, in connect
    return self.dbapi.connect(*cargs, **cparams)
  File "src\pymssql\_pymssql.pyx", line 652, in pymssql._pymssql.connect
sqlalchemy.exc.OperationalError: (pymssql._pymssql.OperationalError) (18456, b'DB-Lib error message 20018, severity 14:\nGeneral SQL Server error: Check messages from the SQL Server\nDB-Lib error message 20002, severity 9:\nAdaptive Server connection failed (172.24.32.210)\nDB-Lib error message 20002, severity 9:\nAdaptive Server connection failed (172.24.32.210)\n')
(Background on this error at: http://sqlalche.me/e/13/e3q8)
2022-12-29 16:14:37,884 Exception on /lookup [POST]
Traceback (most recent call last):
  File "src\pymssql\_pymssql.pyx", line 646, in pymssql._pymssql.connect
  File "src\pymssql\_mssql.pyx", line 2108, in pymssql._mssql.connect
  File "src\pymssql\_mssql.pyx", line 700, in pymssql._mssql.MSSQLConnection.__init__
  File "src\pymssql\_mssql.pyx", line 1817, in pymssql._mssql.maybe_raise_MSSQLDatabaseException
  File "src\pymssql\_mssql.pyx", line 1834, in pymssql._mssql.raise_MSSQLDatabaseException
pymssql._mssql.MSSQLDatabaseException: (18456, b'DB-Lib error message 20018, severity 14:\nGeneral SQL Server error: Check messages from the SQL Server\nDB-Lib error message 20002, severity 9:\nAdaptive Server connection failed (172.24.32.210)\nDB-Lib error message 20002, severity 9:\nAdaptive Server connection failed (172.24.32.210)\n')

During handling of the above exception, another exception occurred:

Traceback (most recent call last):
  File "D:\CDL\CDL-Barcode-Checker\cdl_barcode_checker\lib\site-packages\sqlalchemy\engine\base.py", line 2336, in _wrap_pool_connect
    return fn()
  File "D:\CDL\CDL-Barcode-Checker\cdl_barcode_checker\lib\site-packages\sqlalchemy\pool\base.py", line 364, in connect
    return _ConnectionFairy._checkout(self)
  File "D:\CDL\CDL-Barcode-Checker\cdl_barcode_checker\lib\site-packages\sqlalchemy\pool\base.py", line 778, in _checkout
    fairy = _ConnectionRecord.checkout(pool)
  File "D:\CDL\CDL-Barcode-Checker\cdl_barcode_checker\lib\site-packages\sqlalchemy\pool\base.py", line 495, in checkout
    rec = pool._do_get()
  File "D:\CDL\CDL-Barcode-Checker\cdl_barcode_checker\lib\site-packages\sqlalchemy\pool\impl.py", line 139, in _do_get
    with util.safe_reraise():
  File "D:\CDL\CDL-Barcode-Checker\cdl_barcode_checker\lib\site-packages\sqlalchemy\util\langhelpers.py", line 68, in __exit__
    compat.raise_(
  File "D:\CDL\CDL-Barcode-Checker\cdl_barcode_checker\lib\site-packages\sqlalchemy\util\compat.py", line 182, in raise_
    raise exception
  File "D:\CDL\CDL-Barcode-Checker\cdl_barcode_checker\lib\site-packages\sqlalchemy\pool\impl.py", line 137, in _do_get
    return self._create_connection()
  File "D:\CDL\CDL-Barcode-Checker\cdl_barcode_checker\lib\site-packages\sqlalchemy\pool\base.py", line 309, in _create_connection
    return _ConnectionRecord(self)
  File "D:\CDL\CDL-Barcode-Checker\cdl_barcode_checker\lib\site-packages\sqlalchemy\pool\base.py", line 440, in __init__
    self.__connect(first_connect_check=True)
  File "D:\CDL\CDL-Barcode-Checker\cdl_barcode_checker\lib\site-packages\sqlalchemy\pool\base.py", line 660, in __connect
    with util.safe_reraise():
  File "D:\CDL\CDL-Barcode-Checker\cdl_barcode_checker\lib\site-packages\sqlalchemy\util\langhelpers.py", line 68, in __exit__
    compat.raise_(
  File "D:\CDL\CDL-Barcode-Checker\cdl_barcode_checker\lib\site-packages\sqlalchemy\util\compat.py", line 182, in raise_
    raise exception
  File "D:\CDL\CDL-Barcode-Checker\cdl_barcode_checker\lib\site-packages\sqlalchemy\pool\base.py", line 656, in __connect
    connection = pool._invoke_creator(self)
  File "D:\CDL\CDL-Barcode-Checker\cdl_barcode_checker\lib\site-packages\sqlalchemy\engine\strategies.py", line 114, in connect
    return dialect.connect(*cargs, **cparams)
  File "D:\CDL\CDL-Barcode-Checker\cdl_barcode_checker\lib\site-packages\sqlalchemy\engine\default.py", line 508, in connect
    return self.dbapi.connect(*cargs, **cparams)
  File "src\pymssql\_pymssql.pyx", line 652, in pymssql._pymssql.connect
pymssql._pymssql.OperationalError: (18456, b'DB-Lib error message 20018, severity 14:\nGeneral SQL Server error: Check messages from the SQL Server\nDB-Lib error message 20002, severity 9:\nAdaptive Server connection failed (172.24.32.210)\nDB-Lib error message 20002, severity 9:\nAdaptive Server connection failed (172.24.32.210)\n')

The above exception was the direct cause of the following exception:

Traceback (most recent call last):
  File "D:\CDL\CDL-Barcode-Checker\cdl_barcode_checker\lib\site-packages\flask\app.py", line 2525, in wsgi_app
    response = self.full_dispatch_request()
  File "D:\CDL\CDL-Barcode-Checker\cdl_barcode_checker\lib\site-packages\flask\app.py", line 1822, in full_dispatch_request
    rv = self.handle_user_exception(e)
  File "D:\CDL\CDL-Barcode-Checker\cdl_barcode_checker\lib\site-packages\flask\app.py", line 1820, in full_dispatch_request
    rv = self.dispatch_request()
  File "D:\CDL\CDL-Barcode-Checker\cdl_barcode_checker\lib\site-packages\flask\app.py", line 1796, in dispatch_request
    return self.ensure_sync(self.view_functions[rule.endpoint])(**view_args)
  File "D:\CDL\CDL-Barcode-Checker\.\barcode_checker\main\routes.py", line 34, in lookup_rte
    records = [r._asdict() for r in dbquery.all()]
  File "D:\CDL\CDL-Barcode-Checker\cdl_barcode_checker\lib\site-packages\sqlalchemy\orm\query.py", line 3373, in all
    return list(self)
  File "D:\CDL\CDL-Barcode-Checker\cdl_barcode_checker\lib\site-packages\sqlalchemy\orm\query.py", line 3535, in __iter__
    return self._execute_and_instances(context)
  File "D:\CDL\CDL-Barcode-Checker\cdl_barcode_checker\lib\site-packages\sqlalchemy\orm\query.py", line 3556, in _execute_and_instances
    conn = self._get_bind_args(
  File "D:\CDL\CDL-Barcode-Checker\cdl_barcode_checker\lib\site-packages\sqlalchemy\orm\query.py", line 3571, in _get_bind_args
    return fn(
  File "D:\CDL\CDL-Barcode-Checker\cdl_barcode_checker\lib\site-packages\sqlalchemy\orm\query.py", line 3550, in _connection_from_session
    conn = self.session.connection(**kw)
  File "D:\CDL\CDL-Barcode-Checker\cdl_barcode_checker\lib\site-packages\sqlalchemy\orm\session.py", line 1142, in connection
    return self._connection_for_bind(
  File "D:\CDL\CDL-Barcode-Checker\cdl_barcode_checker\lib\site-packages\sqlalchemy\orm\session.py", line 1150, in _connection_for_bind
    return self.transaction._connection_for_bind(
  File "D:\CDL\CDL-Barcode-Checker\cdl_barcode_checker\lib\site-packages\sqlalchemy\orm\session.py", line 433, in _connection_for_bind
    conn = bind._contextual_connect()
  File "D:\CDL\CDL-Barcode-Checker\cdl_barcode_checker\lib\site-packages\sqlalchemy\engine\base.py", line 2302, in _contextual_connect
    self._wrap_pool_connect(self.pool.connect, None),
  File "D:\CDL\CDL-Barcode-Checker\cdl_barcode_checker\lib\site-packages\sqlalchemy\engine\base.py", line 2339, in _wrap_pool_connect
    Connection._handle_dbapi_exception_noconnection(
  File "D:\CDL\CDL-Barcode-Checker\cdl_barcode_checker\lib\site-packages\sqlalchemy\engine\base.py", line 1583, in _handle_dbapi_exception_noconnection
    util.raise_(
  File "D:\CDL\CDL-Barcode-Checker\cdl_barcode_checker\lib\site-packages\sqlalchemy\util\compat.py", line 182, in raise_
    raise exception
  File "D:\CDL\CDL-Barcode-Checker\cdl_barcode_checker\lib\site-packages\sqlalchemy\engine\base.py", line 2336, in _wrap_pool_connect
    return fn()
  File "D:\CDL\CDL-Barcode-Checker\cdl_barcode_checker\lib\site-packages\sqlalchemy\pool\base.py", line 364, in connect
    return _ConnectionFairy._checkout(self)
  File "D:\CDL\CDL-Barcode-Checker\cdl_barcode_checker\lib\site-packages\sqlalchemy\pool\base.py", line 778, in _checkout
    fairy = _ConnectionRecord.checkout(pool)
  File "D:\CDL\CDL-Barcode-Checker\cdl_barcode_checker\lib\site-packages\sqlalchemy\pool\base.py", line 495, in checkout
    rec = pool._do_get()
  File "D:\CDL\CDL-Barcode-Checker\cdl_barcode_checker\lib\site-packages\sqlalchemy\pool\impl.py", line 139, in _do_get
    with util.safe_reraise():
  File "D:\CDL\CDL-Barcode-Checker\cdl_barcode_checker\lib\site-packages\sqlalchemy\util\langhelpers.py", line 68, in __exit__
    compat.raise_(
  File "D:\CDL\CDL-Barcode-Checker\cdl_barcode_checker\lib\site-packages\sqlalchemy\util\compat.py", line 182, in raise_
    raise exception
  File "D:\CDL\CDL-Barcode-Checker\cdl_barcode_checker\lib\site-packages\sqlalchemy\pool\impl.py", line 137, in _do_get
    return self._create_connection()
  File "D:\CDL\CDL-Barcode-Checker\cdl_barcode_checker\lib\site-packages\sqlalchemy\pool\base.py", line 309, in _create_connection
    return _ConnectionRecord(self)
  File "D:\CDL\CDL-Barcode-Checker\cdl_barcode_checker\lib\site-packages\sqlalchemy\pool\base.py", line 440, in __init__
    self.__connect(first_connect_check=True)
  File "D:\CDL\CDL-Barcode-Checker\cdl_barcode_checker\lib\site-packages\sqlalchemy\pool\base.py", line 660, in __connect
    with util.safe_reraise():
  File "D:\CDL\CDL-Barcode-Checker\cdl_barcode_checker\lib\site-packages\sqlalchemy\util\langhelpers.py", line 68, in __exit__
    compat.raise_(
  File "D:\CDL\CDL-Barcode-Checker\cdl_barcode_checker\lib\site-packages\sqlalchemy\util\compat.py", line 182, in raise_
    raise exception
  File "D:\CDL\CDL-Barcode-Checker\cdl_barcode_checker\lib\site-packages\sqlalchemy\pool\base.py", line 656, in __connect
    connection = pool._invoke_creator(self)
  File "D:\CDL\CDL-Barcode-Checker\cdl_barcode_checker\lib\site-packages\sqlalchemy\engine\strategies.py", line 114, in connect
    return dialect.connect(*cargs, **cparams)
  File "D:\CDL\CDL-Barcode-Checker\cdl_barcode_checker\lib\site-packages\sqlalchemy\engine\default.py", line 508, in connect
    return self.dbapi.connect(*cargs, **cparams)
  File "src\pymssql\_pymssql.pyx", line 652, in pymssql._pymssql.connect
sqlalchemy.exc.OperationalError: (pymssql._pymssql.OperationalError) (18456, b'DB-Lib error message 20018, severity 14:\nGeneral SQL Server error: Check messages from the SQL Server\nDB-Lib error message 20002, severity 9:\nAdaptive Server connection failed (172.24.32.210)\nDB-Lib error message 20002, severity 9:\nAdaptive Server connection failed (172.24.32.210)\n')
(Background on this error at: http://sqlalche.me/e/13/e3q8)
2023-03-15 17:31:38,534 [31m[1mWARNING: This is a development server. Do not use it in a production deployment. Use a production WSGI server instead.[0m
 * Running on http://127.0.0.1:5000
2023-03-15 17:31:38,537 [33mPress CTRL+C to quit[0m
2023-03-15 17:31:48,546 127.0.0.1 - - [15/Mar/2023 17:31:48] "GET / HTTP/1.1" 200 -
2023-03-15 17:31:48,612 127.0.0.1 - - [15/Mar/2023 17:31:48] "GET /barcode-checker/static/logo.png HTTP/1.1" 200 -
2023-03-15 17:31:48,814 127.0.0.1 - - [15/Mar/2023 17:31:48] "[33mGET /favicon.ico HTTP/1.1[0m" 404 -
2023-03-15 17:31:59,836 127.0.0.1 - - [15/Mar/2023 17:31:59] "POST /barcode-checker/lookup HTTP/1.1" 200 -
2023-03-15 17:31:59,855 127.0.0.1 - - [15/Mar/2023 17:31:59] "[36mGET /barcode-checker/static/logo.png HTTP/1.1[0m" 304 -
2023-03-15 17:37:11,629 [31m[1mWARNING: This is a development server. Do not use it in a production deployment. Use a production WSGI server instead.[0m
 * Running on http://127.0.0.1:5000
2023-03-15 17:37:11,629 [33mPress CTRL+C to quit[0m
2023-03-15 17:37:25,061 127.0.0.1 - - [15/Mar/2023 17:37:25] "POST /barcode-checker/lookup HTTP/1.1" 200 -
2023-03-15 17:37:25,116 127.0.0.1 - - [15/Mar/2023 17:37:25] "[36mGET /barcode-checker/static/logo.png HTTP/1.1[0m" 304 -
2023-03-15 17:38:23,134 [31m[1mWARNING: This is a development server. Do not use it in a production deployment. Use a production WSGI server instead.[0m
 * Running on http://127.0.0.1:5000
2023-03-15 17:38:23,134 [33mPress CTRL+C to quit[0m
2023-03-15 17:38:31,740 127.0.0.1 - - [15/Mar/2023 17:38:31] "POST /barcode-checker/lookup HTTP/1.1" 200 -
2023-03-15 17:38:31,781 127.0.0.1 - - [15/Mar/2023 17:38:31] "[36mGET /barcode-checker/static/logo.png HTTP/1.1[0m" 304 -
2023-03-30 14:52:13,050 Exception on /lookup [POST]
Traceback (most recent call last):
  File "src\pymssql\_pymssql.pyx", line 646, in pymssql._pymssql.connect
  File "src\pymssql\_mssql.pyx", line 2108, in pymssql._mssql.connect
  File "src\pymssql\_mssql.pyx", line 700, in pymssql._mssql.MSSQLConnection.__init__
  File "src\pymssql\_mssql.pyx", line 1817, in pymssql._mssql.maybe_raise_MSSQLDatabaseException
  File "src\pymssql\_mssql.pyx", line 1834, in pymssql._mssql.raise_MSSQLDatabaseException
pymssql._mssql.MSSQLDatabaseException: (18456, b"Login failed for user 'CDL_VPOD'.DB-Lib error message 20018, severity 14:\nGeneral SQL Server error: Check messages from the SQL Server\nDB-Lib error message 20002, severity 9:\nAdaptive Server connection failed (172.24.32.210)\nDB-Lib error message 20002, severity 9:\nAdaptive Server connection failed (172.24.32.210)\n")

During handling of the above exception, another exception occurred:

Traceback (most recent call last):
  File "D:\CDL\CDL-Barcode-Checker\cdl_barcode_checker\lib\site-packages\sqlalchemy\engine\base.py", line 2336, in _wrap_pool_connect
    return fn()
  File "D:\CDL\CDL-Barcode-Checker\cdl_barcode_checker\lib\site-packages\sqlalchemy\pool\base.py", line 364, in connect
    return _ConnectionFairy._checkout(self)
  File "D:\CDL\CDL-Barcode-Checker\cdl_barcode_checker\lib\site-packages\sqlalchemy\pool\base.py", line 778, in _checkout
    fairy = _ConnectionRecord.checkout(pool)
  File "D:\CDL\CDL-Barcode-Checker\cdl_barcode_checker\lib\site-packages\sqlalchemy\pool\base.py", line 495, in checkout
    rec = pool._do_get()
  File "D:\CDL\CDL-Barcode-Checker\cdl_barcode_checker\lib\site-packages\sqlalchemy\pool\impl.py", line 139, in _do_get
    with util.safe_reraise():
  File "D:\CDL\CDL-Barcode-Checker\cdl_barcode_checker\lib\site-packages\sqlalchemy\util\langhelpers.py", line 68, in __exit__
    compat.raise_(
  File "D:\CDL\CDL-Barcode-Checker\cdl_barcode_checker\lib\site-packages\sqlalchemy\util\compat.py", line 182, in raise_
    raise exception
  File "D:\CDL\CDL-Barcode-Checker\cdl_barcode_checker\lib\site-packages\sqlalchemy\pool\impl.py", line 137, in _do_get
    return self._create_connection()
  File "D:\CDL\CDL-Barcode-Checker\cdl_barcode_checker\lib\site-packages\sqlalchemy\pool\base.py", line 309, in _create_connection
    return _ConnectionRecord(self)
  File "D:\CDL\CDL-Barcode-Checker\cdl_barcode_checker\lib\site-packages\sqlalchemy\pool\base.py", line 440, in __init__
    self.__connect(first_connect_check=True)
  File "D:\CDL\CDL-Barcode-Checker\cdl_barcode_checker\lib\site-packages\sqlalchemy\pool\base.py", line 660, in __connect
    with util.safe_reraise():
  File "D:\CDL\CDL-Barcode-Checker\cdl_barcode_checker\lib\site-packages\sqlalchemy\util\langhelpers.py", line 68, in __exit__
    compat.raise_(
  File "D:\CDL\CDL-Barcode-Checker\cdl_barcode_checker\lib\site-packages\sqlalchemy\util\compat.py", line 182, in raise_
    raise exception
  File "D:\CDL\CDL-Barcode-Checker\cdl_barcode_checker\lib\site-packages\sqlalchemy\pool\base.py", line 656, in __connect
    connection = pool._invoke_creator(self)
  File "D:\CDL\CDL-Barcode-Checker\cdl_barcode_checker\lib\site-packages\sqlalchemy\engine\strategies.py", line 114, in connect
    return dialect.connect(*cargs, **cparams)
  File "D:\CDL\CDL-Barcode-Checker\cdl_barcode_checker\lib\site-packages\sqlalchemy\engine\default.py", line 508, in connect
    return self.dbapi.connect(*cargs, **cparams)
  File "src\pymssql\_pymssql.pyx", line 652, in pymssql._pymssql.connect
pymssql._pymssql.OperationalError: (18456, b"Login failed for user 'CDL_VPOD'.DB-Lib error message 20018, severity 14:\nGeneral SQL Server error: Check messages from the SQL Server\nDB-Lib error message 20002, severity 9:\nAdaptive Server connection failed (172.24.32.210)\nDB-Lib error message 20002, severity 9:\nAdaptive Server connection failed (172.24.32.210)\n")

The above exception was the direct cause of the following exception:

Traceback (most recent call last):
  File "D:\CDL\CDL-Barcode-Checker\cdl_barcode_checker\lib\site-packages\flask\app.py", line 2525, in wsgi_app
    response = self.full_dispatch_request()
  File "D:\CDL\CDL-Barcode-Checker\cdl_barcode_checker\lib\site-packages\flask\app.py", line 1822, in full_dispatch_request
    rv = self.handle_user_exception(e)
  File "D:\CDL\CDL-Barcode-Checker\cdl_barcode_checker\lib\site-packages\flask\app.py", line 1820, in full_dispatch_request
    rv = self.dispatch_request()
  File "D:\CDL\CDL-Barcode-Checker\cdl_barcode_checker\lib\site-packages\flask\app.py", line 1796, in dispatch_request
    return self.ensure_sync(self.view_functions[rule.endpoint])(**view_args)
  File "D:\CDL\CDL-Barcode-Checker\.\barcode_checker\main\routes.py", line 48, in lookup_rte
    records = [r._asdict() for r in dbquery.all()]
  File "D:\CDL\CDL-Barcode-Checker\cdl_barcode_checker\lib\site-packages\sqlalchemy\orm\query.py", line 3373, in all
    return list(self)
  File "D:\CDL\CDL-Barcode-Checker\cdl_barcode_checker\lib\site-packages\sqlalchemy\orm\query.py", line 3535, in __iter__
    return self._execute_and_instances(context)
  File "D:\CDL\CDL-Barcode-Checker\cdl_barcode_checker\lib\site-packages\sqlalchemy\orm\query.py", line 3556, in _execute_and_instances
    conn = self._get_bind_args(
  File "D:\CDL\CDL-Barcode-Checker\cdl_barcode_checker\lib\site-packages\sqlalchemy\orm\query.py", line 3571, in _get_bind_args
    return fn(
  File "D:\CDL\CDL-Barcode-Checker\cdl_barcode_checker\lib\site-packages\sqlalchemy\orm\query.py", line 3550, in _connection_from_session
    conn = self.session.connection(**kw)
  File "D:\CDL\CDL-Barcode-Checker\cdl_barcode_checker\lib\site-packages\sqlalchemy\orm\session.py", line 1142, in connection
    return self._connection_for_bind(
  File "D:\CDL\CDL-Barcode-Checker\cdl_barcode_checker\lib\site-packages\sqlalchemy\orm\session.py", line 1150, in _connection_for_bind
    return self.transaction._connection_for_bind(
  File "D:\CDL\CDL-Barcode-Checker\cdl_barcode_checker\lib\site-packages\sqlalchemy\orm\session.py", line 433, in _connection_for_bind
    conn = bind._contextual_connect()
  File "D:\CDL\CDL-Barcode-Checker\cdl_barcode_checker\lib\site-packages\sqlalchemy\engine\base.py", line 2302, in _contextual_connect
    self._wrap_pool_connect(self.pool.connect, None),
  File "D:\CDL\CDL-Barcode-Checker\cdl_barcode_checker\lib\site-packages\sqlalchemy\engine\base.py", line 2339, in _wrap_pool_connect
    Connection._handle_dbapi_exception_noconnection(
  File "D:\CDL\CDL-Barcode-Checker\cdl_barcode_checker\lib\site-packages\sqlalchemy\engine\base.py", line 1583, in _handle_dbapi_exception_noconnection
    util.raise_(
  File "D:\CDL\CDL-Barcode-Checker\cdl_barcode_checker\lib\site-packages\sqlalchemy\util\compat.py", line 182, in raise_
    raise exception
  File "D:\CDL\CDL-Barcode-Checker\cdl_barcode_checker\lib\site-packages\sqlalchemy\engine\base.py", line 2336, in _wrap_pool_connect
    return fn()
  File "D:\CDL\CDL-Barcode-Checker\cdl_barcode_checker\lib\site-packages\sqlalchemy\pool\base.py", line 364, in connect
    return _ConnectionFairy._checkout(self)
  File "D:\CDL\CDL-Barcode-Checker\cdl_barcode_checker\lib\site-packages\sqlalchemy\pool\base.py", line 778, in _checkout
    fairy = _ConnectionRecord.checkout(pool)
  File "D:\CDL\CDL-Barcode-Checker\cdl_barcode_checker\lib\site-packages\sqlalchemy\pool\base.py", line 495, in checkout
    rec = pool._do_get()
  File "D:\CDL\CDL-Barcode-Checker\cdl_barcode_checker\lib\site-packages\sqlalchemy\pool\impl.py", line 139, in _do_get
    with util.safe_reraise():
  File "D:\CDL\CDL-Barcode-Checker\cdl_barcode_checker\lib\site-packages\sqlalchemy\util\langhelpers.py", line 68, in __exit__
    compat.raise_(
  File "D:\CDL\CDL-Barcode-Checker\cdl_barcode_checker\lib\site-packages\sqlalchemy\util\compat.py", line 182, in raise_
    raise exception
  File "D:\CDL\CDL-Barcode-Checker\cdl_barcode_checker\lib\site-packages\sqlalchemy\pool\impl.py", line 137, in _do_get
    return self._create_connection()
  File "D:\CDL\CDL-Barcode-Checker\cdl_barcode_checker\lib\site-packages\sqlalchemy\pool\base.py", line 309, in _create_connection
    return _ConnectionRecord(self)
  File "D:\CDL\CDL-Barcode-Checker\cdl_barcode_checker\lib\site-packages\sqlalchemy\pool\base.py", line 440, in __init__
    self.__connect(first_connect_check=True)
  File "D:\CDL\CDL-Barcode-Checker\cdl_barcode_checker\lib\site-packages\sqlalchemy\pool\base.py", line 660, in __connect
    with util.safe_reraise():
  File "D:\CDL\CDL-Barcode-Checker\cdl_barcode_checker\lib\site-packages\sqlalchemy\util\langhelpers.py", line 68, in __exit__
    compat.raise_(
  File "D:\CDL\CDL-Barcode-Checker\cdl_barcode_checker\lib\site-packages\sqlalchemy\util\compat.py", line 182, in raise_
    raise exception
  File "D:\CDL\CDL-Barcode-Checker\cdl_barcode_checker\lib\site-packages\sqlalchemy\pool\base.py", line 656, in __connect
    connection = pool._invoke_creator(self)
  File "D:\CDL\CDL-Barcode-Checker\cdl_barcode_checker\lib\site-packages\sqlalchemy\engine\strategies.py", line 114, in connect
    return dialect.connect(*cargs, **cparams)
  File "D:\CDL\CDL-Barcode-Checker\cdl_barcode_checker\lib\site-packages\sqlalchemy\engine\default.py", line 508, in connect
    return self.dbapi.connect(*cargs, **cparams)
  File "src\pymssql\_pymssql.pyx", line 652, in pymssql._pymssql.connect
sqlalchemy.exc.OperationalError: (pymssql._pymssql.OperationalError) (18456, b"Login failed for user 'CDL_VPOD'.DB-Lib error message 20018, severity 14:\nGeneral SQL Server error: Check messages from the SQL Server\nDB-Lib error message 20002, severity 9:\nAdaptive Server connection failed (172.24.32.210)\nDB-Lib error message 20002, severity 9:\nAdaptive Server connection failed (172.24.32.210)\n")
(Background on this error at: http://sqlalche.me/e/13/e3q8)
2023-03-30 14:52:20,175 Exception on /lookup [POST]
Traceback (most recent call last):
  File "src\pymssql\_pymssql.pyx", line 646, in pymssql._pymssql.connect
  File "src\pymssql\_mssql.pyx", line 2108, in pymssql._mssql.connect
  File "src\pymssql\_mssql.pyx", line 700, in pymssql._mssql.MSSQLConnection.__init__
  File "src\pymssql\_mssql.pyx", line 1817, in pymssql._mssql.maybe_raise_MSSQLDatabaseException
  File "src\pymssql\_mssql.pyx", line 1834, in pymssql._mssql.raise_MSSQLDatabaseException
pymssql._mssql.MSSQLDatabaseException: (18456, b"Login failed for user 'CDL_VPOD'.DB-Lib error message 20018, severity 14:\nGeneral SQL Server error: Check messages from the SQL Server\nDB-Lib error message 20002, severity 9:\nAdaptive Server connection failed (172.24.32.210)\nDB-Lib error message 20002, severity 9:\nAdaptive Server connection failed (172.24.32.210)\n")

During handling of the above exception, another exception occurred:

Traceback (most recent call last):
  File "D:\CDL\CDL-Barcode-Checker\cdl_barcode_checker\lib\site-packages\sqlalchemy\engine\base.py", line 2336, in _wrap_pool_connect
    return fn()
  File "D:\CDL\CDL-Barcode-Checker\cdl_barcode_checker\lib\site-packages\sqlalchemy\pool\base.py", line 364, in connect
    return _ConnectionFairy._checkout(self)
  File "D:\CDL\CDL-Barcode-Checker\cdl_barcode_checker\lib\site-packages\sqlalchemy\pool\base.py", line 778, in _checkout
    fairy = _ConnectionRecord.checkout(pool)
  File "D:\CDL\CDL-Barcode-Checker\cdl_barcode_checker\lib\site-packages\sqlalchemy\pool\base.py", line 495, in checkout
    rec = pool._do_get()
  File "D:\CDL\CDL-Barcode-Checker\cdl_barcode_checker\lib\site-packages\sqlalchemy\pool\impl.py", line 139, in _do_get
    with util.safe_reraise():
  File "D:\CDL\CDL-Barcode-Checker\cdl_barcode_checker\lib\site-packages\sqlalchemy\util\langhelpers.py", line 68, in __exit__
    compat.raise_(
  File "D:\CDL\CDL-Barcode-Checker\cdl_barcode_checker\lib\site-packages\sqlalchemy\util\compat.py", line 182, in raise_
    raise exception
  File "D:\CDL\CDL-Barcode-Checker\cdl_barcode_checker\lib\site-packages\sqlalchemy\pool\impl.py", line 137, in _do_get
    return self._create_connection()
  File "D:\CDL\CDL-Barcode-Checker\cdl_barcode_checker\lib\site-packages\sqlalchemy\pool\base.py", line 309, in _create_connection
    return _ConnectionRecord(self)
  File "D:\CDL\CDL-Barcode-Checker\cdl_barcode_checker\lib\site-packages\sqlalchemy\pool\base.py", line 440, in __init__
    self.__connect(first_connect_check=True)
  File "D:\CDL\CDL-Barcode-Checker\cdl_barcode_checker\lib\site-packages\sqlalchemy\pool\base.py", line 660, in __connect
    with util.safe_reraise():
  File "D:\CDL\CDL-Barcode-Checker\cdl_barcode_checker\lib\site-packages\sqlalchemy\util\langhelpers.py", line 68, in __exit__
    compat.raise_(
  File "D:\CDL\CDL-Barcode-Checker\cdl_barcode_checker\lib\site-packages\sqlalchemy\util\compat.py", line 182, in raise_
    raise exception
  File "D:\CDL\CDL-Barcode-Checker\cdl_barcode_checker\lib\site-packages\sqlalchemy\pool\base.py", line 656, in __connect
    connection = pool._invoke_creator(self)
  File "D:\CDL\CDL-Barcode-Checker\cdl_barcode_checker\lib\site-packages\sqlalchemy\engine\strategies.py", line 114, in connect
    return dialect.connect(*cargs, **cparams)
  File "D:\CDL\CDL-Barcode-Checker\cdl_barcode_checker\lib\site-packages\sqlalchemy\engine\default.py", line 508, in connect
    return self.dbapi.connect(*cargs, **cparams)
  File "src\pymssql\_pymssql.pyx", line 652, in pymssql._pymssql.connect
pymssql._pymssql.OperationalError: (18456, b"Login failed for user 'CDL_VPOD'.DB-Lib error message 20018, severity 14:\nGeneral SQL Server error: Check messages from the SQL Server\nDB-Lib error message 20002, severity 9:\nAdaptive Server connection failed (172.24.32.210)\nDB-Lib error message 20002, severity 9:\nAdaptive Server connection failed (172.24.32.210)\n")

The above exception was the direct cause of the following exception:

Traceback (most recent call last):
  File "D:\CDL\CDL-Barcode-Checker\cdl_barcode_checker\lib\site-packages\flask\app.py", line 2525, in wsgi_app
    response = self.full_dispatch_request()
  File "D:\CDL\CDL-Barcode-Checker\cdl_barcode_checker\lib\site-packages\flask\app.py", line 1822, in full_dispatch_request
    rv = self.handle_user_exception(e)
  File "D:\CDL\CDL-Barcode-Checker\cdl_barcode_checker\lib\site-packages\flask\app.py", line 1820, in full_dispatch_request
    rv = self.dispatch_request()
  File "D:\CDL\CDL-Barcode-Checker\cdl_barcode_checker\lib\site-packages\flask\app.py", line 1796, in dispatch_request
    return self.ensure_sync(self.view_functions[rule.endpoint])(**view_args)
  File "D:\CDL\CDL-Barcode-Checker\.\barcode_checker\main\routes.py", line 48, in lookup_rte
    records = [r._asdict() for r in dbquery.all()]
  File "D:\CDL\CDL-Barcode-Checker\cdl_barcode_checker\lib\site-packages\sqlalchemy\orm\query.py", line 3373, in all
    return list(self)
  File "D:\CDL\CDL-Barcode-Checker\cdl_barcode_checker\lib\site-packages\sqlalchemy\orm\query.py", line 3535, in __iter__
    return self._execute_and_instances(context)
  File "D:\CDL\CDL-Barcode-Checker\cdl_barcode_checker\lib\site-packages\sqlalchemy\orm\query.py", line 3556, in _execute_and_instances
    conn = self._get_bind_args(
  File "D:\CDL\CDL-Barcode-Checker\cdl_barcode_checker\lib\site-packages\sqlalchemy\orm\query.py", line 3571, in _get_bind_args
    return fn(
  File "D:\CDL\CDL-Barcode-Checker\cdl_barcode_checker\lib\site-packages\sqlalchemy\orm\query.py", line 3550, in _connection_from_session
    conn = self.session.connection(**kw)
  File "D:\CDL\CDL-Barcode-Checker\cdl_barcode_checker\lib\site-packages\sqlalchemy\orm\session.py", line 1142, in connection
    return self._connection_for_bind(
  File "D:\CDL\CDL-Barcode-Checker\cdl_barcode_checker\lib\site-packages\sqlalchemy\orm\session.py", line 1150, in _connection_for_bind
    return self.transaction._connection_for_bind(
  File "D:\CDL\CDL-Barcode-Checker\cdl_barcode_checker\lib\site-packages\sqlalchemy\orm\session.py", line 433, in _connection_for_bind
    conn = bind._contextual_connect()
  File "D:\CDL\CDL-Barcode-Checker\cdl_barcode_checker\lib\site-packages\sqlalchemy\engine\base.py", line 2302, in _contextual_connect
    self._wrap_pool_connect(self.pool.connect, None),
  File "D:\CDL\CDL-Barcode-Checker\cdl_barcode_checker\lib\site-packages\sqlalchemy\engine\base.py", line 2339, in _wrap_pool_connect
    Connection._handle_dbapi_exception_noconnection(
  File "D:\CDL\CDL-Barcode-Checker\cdl_barcode_checker\lib\site-packages\sqlalchemy\engine\base.py", line 1583, in _handle_dbapi_exception_noconnection
    util.raise_(
  File "D:\CDL\CDL-Barcode-Checker\cdl_barcode_checker\lib\site-packages\sqlalchemy\util\compat.py", line 182, in raise_
    raise exception
  File "D:\CDL\CDL-Barcode-Checker\cdl_barcode_checker\lib\site-packages\sqlalchemy\engine\base.py", line 2336, in _wrap_pool_connect
    return fn()
  File "D:\CDL\CDL-Barcode-Checker\cdl_barcode_checker\lib\site-packages\sqlalchemy\pool\base.py", line 364, in connect
    return _ConnectionFairy._checkout(self)
  File "D:\CDL\CDL-Barcode-Checker\cdl_barcode_checker\lib\site-packages\sqlalchemy\pool\base.py", line 778, in _checkout
    fairy = _ConnectionRecord.checkout(pool)
  File "D:\CDL\CDL-Barcode-Checker\cdl_barcode_checker\lib\site-packages\sqlalchemy\pool\base.py", line 495, in checkout
    rec = pool._do_get()
  File "D:\CDL\CDL-Barcode-Checker\cdl_barcode_checker\lib\site-packages\sqlalchemy\pool\impl.py", line 139, in _do_get
    with util.safe_reraise():
  File "D:\CDL\CDL-Barcode-Checker\cdl_barcode_checker\lib\site-packages\sqlalchemy\util\langhelpers.py", line 68, in __exit__
    compat.raise_(
  File "D:\CDL\CDL-Barcode-Checker\cdl_barcode_checker\lib\site-packages\sqlalchemy\util\compat.py", line 182, in raise_
    raise exception
  File "D:\CDL\CDL-Barcode-Checker\cdl_barcode_checker\lib\site-packages\sqlalchemy\pool\impl.py", line 137, in _do_get
    return self._create_connection()
  File "D:\CDL\CDL-Barcode-Checker\cdl_barcode_checker\lib\site-packages\sqlalchemy\pool\base.py", line 309, in _create_connection
    return _ConnectionRecord(self)
  File "D:\CDL\CDL-Barcode-Checker\cdl_barcode_checker\lib\site-packages\sqlalchemy\pool\base.py", line 440, in __init__
    self.__connect(first_connect_check=True)
  File "D:\CDL\CDL-Barcode-Checker\cdl_barcode_checker\lib\site-packages\sqlalchemy\pool\base.py", line 660, in __connect
    with util.safe_reraise():
  File "D:\CDL\CDL-Barcode-Checker\cdl_barcode_checker\lib\site-packages\sqlalchemy\util\langhelpers.py", line 68, in __exit__
    compat.raise_(
  File "D:\CDL\CDL-Barcode-Checker\cdl_barcode_checker\lib\site-packages\sqlalchemy\util\compat.py", line 182, in raise_
    raise exception
  File "D:\CDL\CDL-Barcode-Checker\cdl_barcode_checker\lib\site-packages\sqlalchemy\pool\base.py", line 656, in __connect
    connection = pool._invoke_creator(self)
  File "D:\CDL\CDL-Barcode-Checker\cdl_barcode_checker\lib\site-packages\sqlalchemy\engine\strategies.py", line 114, in connect
    return dialect.connect(*cargs, **cparams)
  File "D:\CDL\CDL-Barcode-Checker\cdl_barcode_checker\lib\site-packages\sqlalchemy\engine\default.py", line 508, in connect
    return self.dbapi.connect(*cargs, **cparams)
  File "src\pymssql\_pymssql.pyx", line 652, in pymssql._pymssql.connect
sqlalchemy.exc.OperationalError: (pymssql._pymssql.OperationalError) (18456, b"Login failed for user 'CDL_VPOD'.DB-Lib error message 20018, severity 14:\nGeneral SQL Server error: Check messages from the SQL Server\nDB-Lib error message 20002, severity 9:\nAdaptive Server connection failed (172.24.32.210)\nDB-Lib error message 20002, severity 9:\nAdaptive Server connection failed (172.24.32.210)\n")
(Background on this error at: http://sqlalche.me/e/13/e3q8)
2023-03-30 14:52:50,457 Exception on /lookup [POST]
Traceback (most recent call last):
  File "src\pymssql\_pymssql.pyx", line 646, in pymssql._pymssql.connect
  File "src\pymssql\_mssql.pyx", line 2108, in pymssql._mssql.connect
  File "src\pymssql\_mssql.pyx", line 700, in pymssql._mssql.MSSQLConnection.__init__
  File "src\pymssql\_mssql.pyx", line 1817, in pymssql._mssql.maybe_raise_MSSQLDatabaseException
  File "src\pymssql\_mssql.pyx", line 1834, in pymssql._mssql.raise_MSSQLDatabaseException
pymssql._mssql.MSSQLDatabaseException: (18456, b'DB-Lib error message 20018, severity 14:\nGeneral SQL Server error: Check messages from the SQL Server\nDB-Lib error message 20002, severity 9:\nAdaptive Server connection failed (172.24.32.210)\nDB-Lib error message 20002, severity 9:\nAdaptive Server connection failed (172.24.32.210)\n')

During handling of the above exception, another exception occurred:

Traceback (most recent call last):
  File "D:\CDL\CDL-Barcode-Checker\cdl_barcode_checker\lib\site-packages\sqlalchemy\engine\base.py", line 2336, in _wrap_pool_connect
    return fn()
  File "D:\CDL\CDL-Barcode-Checker\cdl_barcode_checker\lib\site-packages\sqlalchemy\pool\base.py", line 364, in connect
    return _ConnectionFairy._checkout(self)
  File "D:\CDL\CDL-Barcode-Checker\cdl_barcode_checker\lib\site-packages\sqlalchemy\pool\base.py", line 778, in _checkout
    fairy = _ConnectionRecord.checkout(pool)
  File "D:\CDL\CDL-Barcode-Checker\cdl_barcode_checker\lib\site-packages\sqlalchemy\pool\base.py", line 495, in checkout
    rec = pool._do_get()
  File "D:\CDL\CDL-Barcode-Checker\cdl_barcode_checker\lib\site-packages\sqlalchemy\pool\impl.py", line 139, in _do_get
    with util.safe_reraise():
  File "D:\CDL\CDL-Barcode-Checker\cdl_barcode_checker\lib\site-packages\sqlalchemy\util\langhelpers.py", line 68, in __exit__
    compat.raise_(
  File "D:\CDL\CDL-Barcode-Checker\cdl_barcode_checker\lib\site-packages\sqlalchemy\util\compat.py", line 182, in raise_
    raise exception
  File "D:\CDL\CDL-Barcode-Checker\cdl_barcode_checker\lib\site-packages\sqlalchemy\pool\impl.py", line 137, in _do_get
    return self._create_connection()
  File "D:\CDL\CDL-Barcode-Checker\cdl_barcode_checker\lib\site-packages\sqlalchemy\pool\base.py", line 309, in _create_connection
    return _ConnectionRecord(self)
  File "D:\CDL\CDL-Barcode-Checker\cdl_barcode_checker\lib\site-packages\sqlalchemy\pool\base.py", line 440, in __init__
    self.__connect(first_connect_check=True)
  File "D:\CDL\CDL-Barcode-Checker\cdl_barcode_checker\lib\site-packages\sqlalchemy\pool\base.py", line 660, in __connect
    with util.safe_reraise():
  File "D:\CDL\CDL-Barcode-Checker\cdl_barcode_checker\lib\site-packages\sqlalchemy\util\langhelpers.py", line 68, in __exit__
    compat.raise_(
  File "D:\CDL\CDL-Barcode-Checker\cdl_barcode_checker\lib\site-packages\sqlalchemy\util\compat.py", line 182, in raise_
    raise exception
  File "D:\CDL\CDL-Barcode-Checker\cdl_barcode_checker\lib\site-packages\sqlalchemy\pool\base.py", line 656, in __connect
    connection = pool._invoke_creator(self)
  File "D:\CDL\CDL-Barcode-Checker\cdl_barcode_checker\lib\site-packages\sqlalchemy\engine\strategies.py", line 114, in connect
    return dialect.connect(*cargs, **cparams)
  File "D:\CDL\CDL-Barcode-Checker\cdl_barcode_checker\lib\site-packages\sqlalchemy\engine\default.py", line 508, in connect
    return self.dbapi.connect(*cargs, **cparams)
  File "src\pymssql\_pymssql.pyx", line 652, in pymssql._pymssql.connect
pymssql._pymssql.OperationalError: (18456, b'DB-Lib error message 20018, severity 14:\nGeneral SQL Server error: Check messages from the SQL Server\nDB-Lib error message 20002, severity 9:\nAdaptive Server connection failed (172.24.32.210)\nDB-Lib error message 20002, severity 9:\nAdaptive Server connection failed (172.24.32.210)\n')

The above exception was the direct cause of the following exception:

Traceback (most recent call last):
  File "D:\CDL\CDL-Barcode-Checker\cdl_barcode_checker\lib\site-packages\flask\app.py", line 2525, in wsgi_app
    response = self.full_dispatch_request()
  File "D:\CDL\CDL-Barcode-Checker\cdl_barcode_checker\lib\site-packages\flask\app.py", line 1822, in full_dispatch_request
    rv = self.handle_user_exception(e)
  File "D:\CDL\CDL-Barcode-Checker\cdl_barcode_checker\lib\site-packages\flask\app.py", line 1820, in full_dispatch_request
    rv = self.dispatch_request()
  File "D:\CDL\CDL-Barcode-Checker\cdl_barcode_checker\lib\site-packages\flask\app.py", line 1796, in dispatch_request
    return self.ensure_sync(self.view_functions[rule.endpoint])(**view_args)
  File "D:\CDL\CDL-Barcode-Checker\.\barcode_checker\main\routes.py", line 48, in lookup_rte
    records = [r._asdict() for r in dbquery.all()]
  File "D:\CDL\CDL-Barcode-Checker\cdl_barcode_checker\lib\site-packages\sqlalchemy\orm\query.py", line 3373, in all
    return list(self)
  File "D:\CDL\CDL-Barcode-Checker\cdl_barcode_checker\lib\site-packages\sqlalchemy\orm\query.py", line 3535, in __iter__
    return self._execute_and_instances(context)
  File "D:\CDL\CDL-Barcode-Checker\cdl_barcode_checker\lib\site-packages\sqlalchemy\orm\query.py", line 3556, in _execute_and_instances
    conn = self._get_bind_args(
  File "D:\CDL\CDL-Barcode-Checker\cdl_barcode_checker\lib\site-packages\sqlalchemy\orm\query.py", line 3571, in _get_bind_args
    return fn(
  File "D:\CDL\CDL-Barcode-Checker\cdl_barcode_checker\lib\site-packages\sqlalchemy\orm\query.py", line 3550, in _connection_from_session
    conn = self.session.connection(**kw)
  File "D:\CDL\CDL-Barcode-Checker\cdl_barcode_checker\lib\site-packages\sqlalchemy\orm\session.py", line 1142, in connection
    return self._connection_for_bind(
  File "D:\CDL\CDL-Barcode-Checker\cdl_barcode_checker\lib\site-packages\sqlalchemy\orm\session.py", line 1150, in _connection_for_bind
    return self.transaction._connection_for_bind(
  File "D:\CDL\CDL-Barcode-Checker\cdl_barcode_checker\lib\site-packages\sqlalchemy\orm\session.py", line 433, in _connection_for_bind
    conn = bind._contextual_connect()
  File "D:\CDL\CDL-Barcode-Checker\cdl_barcode_checker\lib\site-packages\sqlalchemy\engine\base.py", line 2302, in _contextual_connect
    self._wrap_pool_connect(self.pool.connect, None),
  File "D:\CDL\CDL-Barcode-Checker\cdl_barcode_checker\lib\site-packages\sqlalchemy\engine\base.py", line 2339, in _wrap_pool_connect
    Connection._handle_dbapi_exception_noconnection(
  File "D:\CDL\CDL-Barcode-Checker\cdl_barcode_checker\lib\site-packages\sqlalchemy\engine\base.py", line 1583, in _handle_dbapi_exception_noconnection
    util.raise_(
  File "D:\CDL\CDL-Barcode-Checker\cdl_barcode_checker\lib\site-packages\sqlalchemy\util\compat.py", line 182, in raise_
    raise exception
  File "D:\CDL\CDL-Barcode-Checker\cdl_barcode_checker\lib\site-packages\sqlalchemy\engine\base.py", line 2336, in _wrap_pool_connect
    return fn()
  File "D:\CDL\CDL-Barcode-Checker\cdl_barcode_checker\lib\site-packages\sqlalchemy\pool\base.py", line 364, in connect
    return _ConnectionFairy._checkout(self)
  File "D:\CDL\CDL-Barcode-Checker\cdl_barcode_checker\lib\site-packages\sqlalchemy\pool\base.py", line 778, in _checkout
    fairy = _ConnectionRecord.checkout(pool)
  File "D:\CDL\CDL-Barcode-Checker\cdl_barcode_checker\lib\site-packages\sqlalchemy\pool\base.py", line 495, in checkout
    rec = pool._do_get()
  File "D:\CDL\CDL-Barcode-Checker\cdl_barcode_checker\lib\site-packages\sqlalchemy\pool\impl.py", line 139, in _do_get
    with util.safe_reraise():
  File "D:\CDL\CDL-Barcode-Checker\cdl_barcode_checker\lib\site-packages\sqlalchemy\util\langhelpers.py", line 68, in __exit__
    compat.raise_(
  File "D:\CDL\CDL-Barcode-Checker\cdl_barcode_checker\lib\site-packages\sqlalchemy\util\compat.py", line 182, in raise_
    raise exception
  File "D:\CDL\CDL-Barcode-Checker\cdl_barcode_checker\lib\site-packages\sqlalchemy\pool\impl.py", line 137, in _do_get
    return self._create_connection()
  File "D:\CDL\CDL-Barcode-Checker\cdl_barcode_checker\lib\site-packages\sqlalchemy\pool\base.py", line 309, in _create_connection
    return _ConnectionRecord(self)
  File "D:\CDL\CDL-Barcode-Checker\cdl_barcode_checker\lib\site-packages\sqlalchemy\pool\base.py", line 440, in __init__
    self.__connect(first_connect_check=True)
  File "D:\CDL\CDL-Barcode-Checker\cdl_barcode_checker\lib\site-packages\sqlalchemy\pool\base.py", line 660, in __connect
    with util.safe_reraise():
  File "D:\CDL\CDL-Barcode-Checker\cdl_barcode_checker\lib\site-packages\sqlalchemy\util\langhelpers.py", line 68, in __exit__
    compat.raise_(
  File "D:\CDL\CDL-Barcode-Checker\cdl_barcode_checker\lib\site-packages\sqlalchemy\util\compat.py", line 182, in raise_
    raise exception
  File "D:\CDL\CDL-Barcode-Checker\cdl_barcode_checker\lib\site-packages\sqlalchemy\pool\base.py", line 656, in __connect
    connection = pool._invoke_creator(self)
  File "D:\CDL\CDL-Barcode-Checker\cdl_barcode_checker\lib\site-packages\sqlalchemy\engine\strategies.py", line 114, in connect
    return dialect.connect(*cargs, **cparams)
  File "D:\CDL\CDL-Barcode-Checker\cdl_barcode_checker\lib\site-packages\sqlalchemy\engine\default.py", line 508, in connect
    return self.dbapi.connect(*cargs, **cparams)
  File "src\pymssql\_pymssql.pyx", line 652, in pymssql._pymssql.connect
sqlalchemy.exc.OperationalError: (pymssql._pymssql.OperationalError) (18456, b'DB-Lib error message 20018, severity 14:\nGeneral SQL Server error: Check messages from the SQL Server\nDB-Lib error message 20002, severity 9:\nAdaptive Server connection failed (172.24.32.210)\nDB-Lib error message 20002, severity 9:\nAdaptive Server connection failed (172.24.32.210)\n')
(Background on this error at: http://sqlalche.me/e/13/e3q8)
2023-03-30 14:54:49,316 Exception on /lookup [POST]
Traceback (most recent call last):
  File "src\pymssql\_pymssql.pyx", line 646, in pymssql._pymssql.connect
  File "src\pymssql\_mssql.pyx", line 2108, in pymssql._mssql.connect
  File "src\pymssql\_mssql.pyx", line 700, in pymssql._mssql.MSSQLConnection.__init__
  File "src\pymssql\_mssql.pyx", line 1817, in pymssql._mssql.maybe_raise_MSSQLDatabaseException
  File "src\pymssql\_mssql.pyx", line 1834, in pymssql._mssql.raise_MSSQLDatabaseException
pymssql._mssql.MSSQLDatabaseException: (18456, b'DB-Lib error message 20018, severity 14:\nGeneral SQL Server error: Check messages from the SQL Server\nDB-Lib error message 20002, severity 9:\nAdaptive Server connection failed (172.24.32.210)\nDB-Lib error message 20002, severity 9:\nAdaptive Server connection failed (172.24.32.210)\n')

During handling of the above exception, another exception occurred:

Traceback (most recent call last):
  File "D:\CDL\CDL-Barcode-Checker\cdl_barcode_checker\lib\site-packages\sqlalchemy\engine\base.py", line 2336, in _wrap_pool_connect
    return fn()
  File "D:\CDL\CDL-Barcode-Checker\cdl_barcode_checker\lib\site-packages\sqlalchemy\pool\base.py", line 364, in connect
    return _ConnectionFairy._checkout(self)
  File "D:\CDL\CDL-Barcode-Checker\cdl_barcode_checker\lib\site-packages\sqlalchemy\pool\base.py", line 778, in _checkout
    fairy = _ConnectionRecord.checkout(pool)
  File "D:\CDL\CDL-Barcode-Checker\cdl_barcode_checker\lib\site-packages\sqlalchemy\pool\base.py", line 495, in checkout
    rec = pool._do_get()
  File "D:\CDL\CDL-Barcode-Checker\cdl_barcode_checker\lib\site-packages\sqlalchemy\pool\impl.py", line 139, in _do_get
    with util.safe_reraise():
  File "D:\CDL\CDL-Barcode-Checker\cdl_barcode_checker\lib\site-packages\sqlalchemy\util\langhelpers.py", line 68, in __exit__
    compat.raise_(
  File "D:\CDL\CDL-Barcode-Checker\cdl_barcode_checker\lib\site-packages\sqlalchemy\util\compat.py", line 182, in raise_
    raise exception
  File "D:\CDL\CDL-Barcode-Checker\cdl_barcode_checker\lib\site-packages\sqlalchemy\pool\impl.py", line 137, in _do_get
    return self._create_connection()
  File "D:\CDL\CDL-Barcode-Checker\cdl_barcode_checker\lib\site-packages\sqlalchemy\pool\base.py", line 309, in _create_connection
    return _ConnectionRecord(self)
  File "D:\CDL\CDL-Barcode-Checker\cdl_barcode_checker\lib\site-packages\sqlalchemy\pool\base.py", line 440, in __init__
    self.__connect(first_connect_check=True)
  File "D:\CDL\CDL-Barcode-Checker\cdl_barcode_checker\lib\site-packages\sqlalchemy\pool\base.py", line 660, in __connect
    with util.safe_reraise():
  File "D:\CDL\CDL-Barcode-Checker\cdl_barcode_checker\lib\site-packages\sqlalchemy\util\langhelpers.py", line 68, in __exit__
    compat.raise_(
  File "D:\CDL\CDL-Barcode-Checker\cdl_barcode_checker\lib\site-packages\sqlalchemy\util\compat.py", line 182, in raise_
    raise exception
  File "D:\CDL\CDL-Barcode-Checker\cdl_barcode_checker\lib\site-packages\sqlalchemy\pool\base.py", line 656, in __connect
    connection = pool._invoke_creator(self)
  File "D:\CDL\CDL-Barcode-Checker\cdl_barcode_checker\lib\site-packages\sqlalchemy\engine\strategies.py", line 114, in connect
    return dialect.connect(*cargs, **cparams)
  File "D:\CDL\CDL-Barcode-Checker\cdl_barcode_checker\lib\site-packages\sqlalchemy\engine\default.py", line 508, in connect
    return self.dbapi.connect(*cargs, **cparams)
  File "src\pymssql\_pymssql.pyx", line 652, in pymssql._pymssql.connect
pymssql._pymssql.OperationalError: (18456, b'DB-Lib error message 20018, severity 14:\nGeneral SQL Server error: Check messages from the SQL Server\nDB-Lib error message 20002, severity 9:\nAdaptive Server connection failed (172.24.32.210)\nDB-Lib error message 20002, severity 9:\nAdaptive Server connection failed (172.24.32.210)\n')

The above exception was the direct cause of the following exception:

Traceback (most recent call last):
  File "D:\CDL\CDL-Barcode-Checker\cdl_barcode_checker\lib\site-packages\flask\app.py", line 2525, in wsgi_app
    response = self.full_dispatch_request()
  File "D:\CDL\CDL-Barcode-Checker\cdl_barcode_checker\lib\site-packages\flask\app.py", line 1822, in full_dispatch_request
    rv = self.handle_user_exception(e)
  File "D:\CDL\CDL-Barcode-Checker\cdl_barcode_checker\lib\site-packages\flask\app.py", line 1820, in full_dispatch_request
    rv = self.dispatch_request()
  File "D:\CDL\CDL-Barcode-Checker\cdl_barcode_checker\lib\site-packages\flask\app.py", line 1796, in dispatch_request
    return self.ensure_sync(self.view_functions[rule.endpoint])(**view_args)
  File "D:\CDL\CDL-Barcode-Checker\.\barcode_checker\main\routes.py", line 48, in lookup_rte
    records = [r._asdict() for r in dbquery.all()]
  File "D:\CDL\CDL-Barcode-Checker\cdl_barcode_checker\lib\site-packages\sqlalchemy\orm\query.py", line 3373, in all
    return list(self)
  File "D:\CDL\CDL-Barcode-Checker\cdl_barcode_checker\lib\site-packages\sqlalchemy\orm\query.py", line 3535, in __iter__
    return self._execute_and_instances(context)
  File "D:\CDL\CDL-Barcode-Checker\cdl_barcode_checker\lib\site-packages\sqlalchemy\orm\query.py", line 3556, in _execute_and_instances
    conn = self._get_bind_args(
  File "D:\CDL\CDL-Barcode-Checker\cdl_barcode_checker\lib\site-packages\sqlalchemy\orm\query.py", line 3571, in _get_bind_args
    return fn(
  File "D:\CDL\CDL-Barcode-Checker\cdl_barcode_checker\lib\site-packages\sqlalchemy\orm\query.py", line 3550, in _connection_from_session
    conn = self.session.connection(**kw)
  File "D:\CDL\CDL-Barcode-Checker\cdl_barcode_checker\lib\site-packages\sqlalchemy\orm\session.py", line 1142, in connection
    return self._connection_for_bind(
  File "D:\CDL\CDL-Barcode-Checker\cdl_barcode_checker\lib\site-packages\sqlalchemy\orm\session.py", line 1150, in _connection_for_bind
    return self.transaction._connection_for_bind(
  File "D:\CDL\CDL-Barcode-Checker\cdl_barcode_checker\lib\site-packages\sqlalchemy\orm\session.py", line 433, in _connection_for_bind
    conn = bind._contextual_connect()
  File "D:\CDL\CDL-Barcode-Checker\cdl_barcode_checker\lib\site-packages\sqlalchemy\engine\base.py", line 2302, in _contextual_connect
    self._wrap_pool_connect(self.pool.connect, None),
  File "D:\CDL\CDL-Barcode-Checker\cdl_barcode_checker\lib\site-packages\sqlalchemy\engine\base.py", line 2339, in _wrap_pool_connect
    Connection._handle_dbapi_exception_noconnection(
  File "D:\CDL\CDL-Barcode-Checker\cdl_barcode_checker\lib\site-packages\sqlalchemy\engine\base.py", line 1583, in _handle_dbapi_exception_noconnection
    util.raise_(
  File "D:\CDL\CDL-Barcode-Checker\cdl_barcode_checker\lib\site-packages\sqlalchemy\util\compat.py", line 182, in raise_
    raise exception
  File "D:\CDL\CDL-Barcode-Checker\cdl_barcode_checker\lib\site-packages\sqlalchemy\engine\base.py", line 2336, in _wrap_pool_connect
    return fn()
  File "D:\CDL\CDL-Barcode-Checker\cdl_barcode_checker\lib\site-packages\sqlalchemy\pool\base.py", line 364, in connect
    return _ConnectionFairy._checkout(self)
  File "D:\CDL\CDL-Barcode-Checker\cdl_barcode_checker\lib\site-packages\sqlalchemy\pool\base.py", line 778, in _checkout
    fairy = _ConnectionRecord.checkout(pool)
  File "D:\CDL\CDL-Barcode-Checker\cdl_barcode_checker\lib\site-packages\sqlalchemy\pool\base.py", line 495, in checkout
    rec = pool._do_get()
  File "D:\CDL\CDL-Barcode-Checker\cdl_barcode_checker\lib\site-packages\sqlalchemy\pool\impl.py", line 139, in _do_get
    with util.safe_reraise():
  File "D:\CDL\CDL-Barcode-Checker\cdl_barcode_checker\lib\site-packages\sqlalchemy\util\langhelpers.py", line 68, in __exit__
    compat.raise_(
  File "D:\CDL\CDL-Barcode-Checker\cdl_barcode_checker\lib\site-packages\sqlalchemy\util\compat.py", line 182, in raise_
    raise exception
  File "D:\CDL\CDL-Barcode-Checker\cdl_barcode_checker\lib\site-packages\sqlalchemy\pool\impl.py", line 137, in _do_get
    return self._create_connection()
  File "D:\CDL\CDL-Barcode-Checker\cdl_barcode_checker\lib\site-packages\sqlalchemy\pool\base.py", line 309, in _create_connection
    return _ConnectionRecord(self)
  File "D:\CDL\CDL-Barcode-Checker\cdl_barcode_checker\lib\site-packages\sqlalchemy\pool\base.py", line 440, in __init__
    self.__connect(first_connect_check=True)
  File "D:\CDL\CDL-Barcode-Checker\cdl_barcode_checker\lib\site-packages\sqlalchemy\pool\base.py", line 660, in __connect
    with util.safe_reraise():
  File "D:\CDL\CDL-Barcode-Checker\cdl_barcode_checker\lib\site-packages\sqlalchemy\util\langhelpers.py", line 68, in __exit__
    compat.raise_(
  File "D:\CDL\CDL-Barcode-Checker\cdl_barcode_checker\lib\site-packages\sqlalchemy\util\compat.py", line 182, in raise_
    raise exception
  File "D:\CDL\CDL-Barcode-Checker\cdl_barcode_checker\lib\site-packages\sqlalchemy\pool\base.py", line 656, in __connect
    connection = pool._invoke_creator(self)
  File "D:\CDL\CDL-Barcode-Checker\cdl_barcode_checker\lib\site-packages\sqlalchemy\engine\strategies.py", line 114, in connect
    return dialect.connect(*cargs, **cparams)
  File "D:\CDL\CDL-Barcode-Checker\cdl_barcode_checker\lib\site-packages\sqlalchemy\engine\default.py", line 508, in connect
    return self.dbapi.connect(*cargs, **cparams)
  File "src\pymssql\_pymssql.pyx", line 652, in pymssql._pymssql.connect
sqlalchemy.exc.OperationalError: (pymssql._pymssql.OperationalError) (18456, b'DB-Lib error message 20018, severity 14:\nGeneral SQL Server error: Check messages from the SQL Server\nDB-Lib error message 20002, severity 9:\nAdaptive Server connection failed (172.24.32.210)\nDB-Lib error message 20002, severity 9:\nAdaptive Server connection failed (172.24.32.210)\n')
(Background on this error at: http://sqlalche.me/e/13/e3q8)
2023-04-28 15:03:24,324 Exception on /lookup [POST]
Traceback (most recent call last):
  File "src\pymssql\_pymssql.pyx", line 460, in pymssql._pymssql.Cursor.execute
  File "src\pymssql\_mssql.pyx", line 1086, in pymssql._mssql.MSSQLConnection.execute_query
  File "src\pymssql\_mssql.pyx", line 1117, in pymssql._mssql.MSSQLConnection.execute_query
  File "src\pymssql\_mssql.pyx", line 1250, in pymssql._mssql.MSSQLConnection.format_and_run_query
  File "src\pymssql\_mssql.pyx", line 1788, in pymssql._mssql.check_cancel_and_raise
  File "src\pymssql\_mssql.pyx", line 1834, in pymssql._mssql.raise_MSSQLDatabaseException
pymssql._mssql.MSSQLDatabaseException: (20047, b'DB-Lib error message 20047, severity 9:\nDBPROCESS is dead or not enabled\n')

During handling of the above exception, another exception occurred:

Traceback (most recent call last):
  File "D:\CDL\CDL-Barcode-Checker\cdl_barcode_checker\lib\site-packages\sqlalchemy\engine\base.py", line 1276, in _execute_context
    self.dialect.do_execute(
  File "D:\CDL\CDL-Barcode-Checker\cdl_barcode_checker\lib\site-packages\sqlalchemy\engine\default.py", line 608, in do_execute
    cursor.execute(statement, parameters)
  File "src\pymssql\_pymssql.pyx", line 478, in pymssql._pymssql.Cursor.execute
pymssql._pymssql.OperationalError: (20047, b'DB-Lib error message 20047, severity 9:\nDBPROCESS is dead or not enabled\n')

The above exception was the direct cause of the following exception:

Traceback (most recent call last):
  File "D:\CDL\CDL-Barcode-Checker\cdl_barcode_checker\lib\site-packages\flask\app.py", line 2525, in wsgi_app
    response = self.full_dispatch_request()
  File "D:\CDL\CDL-Barcode-Checker\cdl_barcode_checker\lib\site-packages\flask\app.py", line 1822, in full_dispatch_request
    rv = self.handle_user_exception(e)
  File "D:\CDL\CDL-Barcode-Checker\cdl_barcode_checker\lib\site-packages\flask\app.py", line 1820, in full_dispatch_request
    rv = self.dispatch_request()
  File "D:\CDL\CDL-Barcode-Checker\cdl_barcode_checker\lib\site-packages\flask\app.py", line 1796, in dispatch_request
    return self.ensure_sync(self.view_functions[rule.endpoint])(**view_args)
  File "D:\CDL\CDL-Barcode-Checker\.\barcode_checker\main\routes.py", line 48, in lookup_rte
    records = [r._asdict() for r in dbquery.all()]
  File "D:\CDL\CDL-Barcode-Checker\cdl_barcode_checker\lib\site-packages\sqlalchemy\orm\query.py", line 3373, in all
    return list(self)
  File "D:\CDL\CDL-Barcode-Checker\cdl_barcode_checker\lib\site-packages\sqlalchemy\orm\query.py", line 3535, in __iter__
    return self._execute_and_instances(context)
  File "D:\CDL\CDL-Barcode-Checker\cdl_barcode_checker\lib\site-packages\sqlalchemy\orm\query.py", line 3560, in _execute_and_instances
    result = conn.execute(querycontext.statement, self._params)
  File "D:\CDL\CDL-Barcode-Checker\cdl_barcode_checker\lib\site-packages\sqlalchemy\engine\base.py", line 1011, in execute
    return meth(self, multiparams, params)
  File "D:\CDL\CDL-Barcode-Checker\cdl_barcode_checker\lib\site-packages\sqlalchemy\sql\elements.py", line 298, in _execute_on_connection
    return connection._execute_clauseelement(self, multiparams, params)
  File "D:\CDL\CDL-Barcode-Checker\cdl_barcode_checker\lib\site-packages\sqlalchemy\engine\base.py", line 1124, in _execute_clauseelement
    ret = self._execute_context(
  File "D:\CDL\CDL-Barcode-Checker\cdl_barcode_checker\lib\site-packages\sqlalchemy\engine\base.py", line 1316, in _execute_context
    self._handle_dbapi_exception(
  File "D:\CDL\CDL-Barcode-Checker\cdl_barcode_checker\lib\site-packages\sqlalchemy\engine\base.py", line 1510, in _handle_dbapi_exception
    util.raise_(
  File "D:\CDL\CDL-Barcode-Checker\cdl_barcode_checker\lib\site-packages\sqlalchemy\util\compat.py", line 182, in raise_
    raise exception
  File "D:\CDL\CDL-Barcode-Checker\cdl_barcode_checker\lib\site-packages\sqlalchemy\engine\base.py", line 1276, in _execute_context
    self.dialect.do_execute(
  File "D:\CDL\CDL-Barcode-Checker\cdl_barcode_checker\lib\site-packages\sqlalchemy\engine\default.py", line 608, in do_execute
    cursor.execute(statement, parameters)
  File "src\pymssql\_pymssql.pyx", line 478, in pymssql._pymssql.Cursor.execute
sqlalchemy.exc.OperationalError: (pymssql._pymssql.OperationalError) (20047, b'DB-Lib error message 20047, severity 9:\nDBPROCESS is dead or not enabled\n')
[SQL: SELECT [ClientMaster].[AccountNo] AS [ClientMaster_AccountNo], [ClientMaster].[CompanyName] AS [ClientMaster_CompanyName], [Orders].[OrderTrackingID] AS [Orders_OrderTrackingID], [Orders].[ClientRefNo] AS [Orders_ClientRefNo], [OrderPackageItems].[RefNo] AS [OrderPackageItems_RefNo], [Orders].[DSortCode] AS [Orders_DSortCode] 
FROM [OrderPackageItems] JOIN [Orders] ON [OrderPackageItems].[OrderTrackingID] = [Orders].[OrderTrackingID] JOIN [ClientMaster] ON [Orders].[ClientID] = [ClientMaster].[ClientID] 
WHERE [OrderPackageItems].[RefNo] = %(RefNo_1)s AND [Orders].[Status] = %(Status_1)s]
[parameters: {'RefNo_1': 'SPXHEF005001867318', 'Status_1': 'N'}]
(Background on this error at: http://sqlalche.me/e/13/e3q8)
2023-04-28 15:03:30,827 Exception on /lookup [POST]
Traceback (most recent call last):
  File "src\pymssql\_pymssql.pyx", line 646, in pymssql._pymssql.connect
  File "src\pymssql\_mssql.pyx", line 2108, in pymssql._mssql.connect
  File "src\pymssql\_mssql.pyx", line 700, in pymssql._mssql.MSSQLConnection.__init__
  File "src\pymssql\_mssql.pyx", line 1817, in pymssql._mssql.maybe_raise_MSSQLDatabaseException
  File "src\pymssql\_mssql.pyx", line 1834, in pymssql._mssql.raise_MSSQLDatabaseException
pymssql._mssql.MSSQLDatabaseException: (18456, b"Login failed for user 'CDL_VPOD'.DB-Lib error message 20018, severity 14:\nGeneral SQL Server error: Check messages from the SQL Server\nDB-Lib error message 20002, severity 9:\nAdaptive Server connection failed (172.24.32.210)\nDB-Lib error message 20002, severity 9:\nAdaptive Server connection failed (172.24.32.210)\n")

During handling of the above exception, another exception occurred:

Traceback (most recent call last):
  File "D:\CDL\CDL-Barcode-Checker\cdl_barcode_checker\lib\site-packages\sqlalchemy\engine\base.py", line 2336, in _wrap_pool_connect
    return fn()
  File "D:\CDL\CDL-Barcode-Checker\cdl_barcode_checker\lib\site-packages\sqlalchemy\pool\base.py", line 364, in connect
    return _ConnectionFairy._checkout(self)
  File "D:\CDL\CDL-Barcode-Checker\cdl_barcode_checker\lib\site-packages\sqlalchemy\pool\base.py", line 778, in _checkout
    fairy = _ConnectionRecord.checkout(pool)
  File "D:\CDL\CDL-Barcode-Checker\cdl_barcode_checker\lib\site-packages\sqlalchemy\pool\base.py", line 495, in checkout
    rec = pool._do_get()
  File "D:\CDL\CDL-Barcode-Checker\cdl_barcode_checker\lib\site-packages\sqlalchemy\pool\impl.py", line 139, in _do_get
    with util.safe_reraise():
  File "D:\CDL\CDL-Barcode-Checker\cdl_barcode_checker\lib\site-packages\sqlalchemy\util\langhelpers.py", line 68, in __exit__
    compat.raise_(
  File "D:\CDL\CDL-Barcode-Checker\cdl_barcode_checker\lib\site-packages\sqlalchemy\util\compat.py", line 182, in raise_
    raise exception
  File "D:\CDL\CDL-Barcode-Checker\cdl_barcode_checker\lib\site-packages\sqlalchemy\pool\impl.py", line 137, in _do_get
    return self._create_connection()
  File "D:\CDL\CDL-Barcode-Checker\cdl_barcode_checker\lib\site-packages\sqlalchemy\pool\base.py", line 309, in _create_connection
    return _ConnectionRecord(self)
  File "D:\CDL\CDL-Barcode-Checker\cdl_barcode_checker\lib\site-packages\sqlalchemy\pool\base.py", line 440, in __init__
    self.__connect(first_connect_check=True)
  File "D:\CDL\CDL-Barcode-Checker\cdl_barcode_checker\lib\site-packages\sqlalchemy\pool\base.py", line 660, in __connect
    with util.safe_reraise():
  File "D:\CDL\CDL-Barcode-Checker\cdl_barcode_checker\lib\site-packages\sqlalchemy\util\langhelpers.py", line 68, in __exit__
    compat.raise_(
  File "D:\CDL\CDL-Barcode-Checker\cdl_barcode_checker\lib\site-packages\sqlalchemy\util\compat.py", line 182, in raise_
    raise exception
  File "D:\CDL\CDL-Barcode-Checker\cdl_barcode_checker\lib\site-packages\sqlalchemy\pool\base.py", line 656, in __connect
    connection = pool._invoke_creator(self)
  File "D:\CDL\CDL-Barcode-Checker\cdl_barcode_checker\lib\site-packages\sqlalchemy\engine\strategies.py", line 114, in connect
    return dialect.connect(*cargs, **cparams)
  File "D:\CDL\CDL-Barcode-Checker\cdl_barcode_checker\lib\site-packages\sqlalchemy\engine\default.py", line 508, in connect
    return self.dbapi.connect(*cargs, **cparams)
  File "src\pymssql\_pymssql.pyx", line 652, in pymssql._pymssql.connect
pymssql._pymssql.OperationalError: (18456, b"Login failed for user 'CDL_VPOD'.DB-Lib error message 20018, severity 14:\nGeneral SQL Server error: Check messages from the SQL Server\nDB-Lib error message 20002, severity 9:\nAdaptive Server connection failed (172.24.32.210)\nDB-Lib error message 20002, severity 9:\nAdaptive Server connection failed (172.24.32.210)\n")

The above exception was the direct cause of the following exception:

Traceback (most recent call last):
  File "D:\CDL\CDL-Barcode-Checker\cdl_barcode_checker\lib\site-packages\flask\app.py", line 2525, in wsgi_app
    response = self.full_dispatch_request()
  File "D:\CDL\CDL-Barcode-Checker\cdl_barcode_checker\lib\site-packages\flask\app.py", line 1822, in full_dispatch_request
    rv = self.handle_user_exception(e)
  File "D:\CDL\CDL-Barcode-Checker\cdl_barcode_checker\lib\site-packages\flask\app.py", line 1820, in full_dispatch_request
    rv = self.dispatch_request()
  File "D:\CDL\CDL-Barcode-Checker\cdl_barcode_checker\lib\site-packages\flask\app.py", line 1796, in dispatch_request
    return self.ensure_sync(self.view_functions[rule.endpoint])(**view_args)
  File "D:\CDL\CDL-Barcode-Checker\.\barcode_checker\main\routes.py", line 48, in lookup_rte
    records = [r._asdict() for r in dbquery.all()]
  File "D:\CDL\CDL-Barcode-Checker\cdl_barcode_checker\lib\site-packages\sqlalchemy\orm\query.py", line 3373, in all
    return list(self)
  File "D:\CDL\CDL-Barcode-Checker\cdl_barcode_checker\lib\site-packages\sqlalchemy\orm\query.py", line 3535, in __iter__
    return self._execute_and_instances(context)
  File "D:\CDL\CDL-Barcode-Checker\cdl_barcode_checker\lib\site-packages\sqlalchemy\orm\query.py", line 3556, in _execute_and_instances
    conn = self._get_bind_args(
  File "D:\CDL\CDL-Barcode-Checker\cdl_barcode_checker\lib\site-packages\sqlalchemy\orm\query.py", line 3571, in _get_bind_args
    return fn(
  File "D:\CDL\CDL-Barcode-Checker\cdl_barcode_checker\lib\site-packages\sqlalchemy\orm\query.py", line 3550, in _connection_from_session
    conn = self.session.connection(**kw)
  File "D:\CDL\CDL-Barcode-Checker\cdl_barcode_checker\lib\site-packages\sqlalchemy\orm\session.py", line 1142, in connection
    return self._connection_for_bind(
  File "D:\CDL\CDL-Barcode-Checker\cdl_barcode_checker\lib\site-packages\sqlalchemy\orm\session.py", line 1150, in _connection_for_bind
    return self.transaction._connection_for_bind(
  File "D:\CDL\CDL-Barcode-Checker\cdl_barcode_checker\lib\site-packages\sqlalchemy\orm\session.py", line 433, in _connection_for_bind
    conn = bind._contextual_connect()
  File "D:\CDL\CDL-Barcode-Checker\cdl_barcode_checker\lib\site-packages\sqlalchemy\engine\base.py", line 2302, in _contextual_connect
    self._wrap_pool_connect(self.pool.connect, None),
  File "D:\CDL\CDL-Barcode-Checker\cdl_barcode_checker\lib\site-packages\sqlalchemy\engine\base.py", line 2339, in _wrap_pool_connect
    Connection._handle_dbapi_exception_noconnection(
  File "D:\CDL\CDL-Barcode-Checker\cdl_barcode_checker\lib\site-packages\sqlalchemy\engine\base.py", line 1583, in _handle_dbapi_exception_noconnection
    util.raise_(
  File "D:\CDL\CDL-Barcode-Checker\cdl_barcode_checker\lib\site-packages\sqlalchemy\util\compat.py", line 182, in raise_
    raise exception
  File "D:\CDL\CDL-Barcode-Checker\cdl_barcode_checker\lib\site-packages\sqlalchemy\engine\base.py", line 2336, in _wrap_pool_connect
    return fn()
  File "D:\CDL\CDL-Barcode-Checker\cdl_barcode_checker\lib\site-packages\sqlalchemy\pool\base.py", line 364, in connect
    return _ConnectionFairy._checkout(self)
  File "D:\CDL\CDL-Barcode-Checker\cdl_barcode_checker\lib\site-packages\sqlalchemy\pool\base.py", line 778, in _checkout
    fairy = _ConnectionRecord.checkout(pool)
  File "D:\CDL\CDL-Barcode-Checker\cdl_barcode_checker\lib\site-packages\sqlalchemy\pool\base.py", line 495, in checkout
    rec = pool._do_get()
  File "D:\CDL\CDL-Barcode-Checker\cdl_barcode_checker\lib\site-packages\sqlalchemy\pool\impl.py", line 139, in _do_get
    with util.safe_reraise():
  File "D:\CDL\CDL-Barcode-Checker\cdl_barcode_checker\lib\site-packages\sqlalchemy\util\langhelpers.py", line 68, in __exit__
    compat.raise_(
  File "D:\CDL\CDL-Barcode-Checker\cdl_barcode_checker\lib\site-packages\sqlalchemy\util\compat.py", line 182, in raise_
    raise exception
  File "D:\CDL\CDL-Barcode-Checker\cdl_barcode_checker\lib\site-packages\sqlalchemy\pool\impl.py", line 137, in _do_get
    return self._create_connection()
  File "D:\CDL\CDL-Barcode-Checker\cdl_barcode_checker\lib\site-packages\sqlalchemy\pool\base.py", line 309, in _create_connection
    return _ConnectionRecord(self)
  File "D:\CDL\CDL-Barcode-Checker\cdl_barcode_checker\lib\site-packages\sqlalchemy\pool\base.py", line 440, in __init__
    self.__connect(first_connect_check=True)
  File "D:\CDL\CDL-Barcode-Checker\cdl_barcode_checker\lib\site-packages\sqlalchemy\pool\base.py", line 660, in __connect
    with util.safe_reraise():
  File "D:\CDL\CDL-Barcode-Checker\cdl_barcode_checker\lib\site-packages\sqlalchemy\util\langhelpers.py", line 68, in __exit__
    compat.raise_(
  File "D:\CDL\CDL-Barcode-Checker\cdl_barcode_checker\lib\site-packages\sqlalchemy\util\compat.py", line 182, in raise_
    raise exception
  File "D:\CDL\CDL-Barcode-Checker\cdl_barcode_checker\lib\site-packages\sqlalchemy\pool\base.py", line 656, in __connect
    connection = pool._invoke_creator(self)
  File "D:\CDL\CDL-Barcode-Checker\cdl_barcode_checker\lib\site-packages\sqlalchemy\engine\strategies.py", line 114, in connect
    return dialect.connect(*cargs, **cparams)
  File "D:\CDL\CDL-Barcode-Checker\cdl_barcode_checker\lib\site-packages\sqlalchemy\engine\default.py", line 508, in connect
    return self.dbapi.connect(*cargs, **cparams)
  File "src\pymssql\_pymssql.pyx", line 652, in pymssql._pymssql.connect
sqlalchemy.exc.OperationalError: (pymssql._pymssql.OperationalError) (18456, b"Login failed for user 'CDL_VPOD'.DB-Lib error message 20018, severity 14:\nGeneral SQL Server error: Check messages from the SQL Server\nDB-Lib error message 20002, severity 9:\nAdaptive Server connection failed (172.24.32.210)\nDB-Lib error message 20002, severity 9:\nAdaptive Server connection failed (172.24.32.210)\n")
(Background on this error at: http://sqlalche.me/e/13/e3q8)
2023-04-28 15:03:44,804 Exception on /lookup [POST]
Traceback (most recent call last):
  File "src\pymssql\_pymssql.pyx", line 646, in pymssql._pymssql.connect
  File "src\pymssql\_mssql.pyx", line 2108, in pymssql._mssql.connect
  File "src\pymssql\_mssql.pyx", line 700, in pymssql._mssql.MSSQLConnection.__init__
  File "src\pymssql\_mssql.pyx", line 1817, in pymssql._mssql.maybe_raise_MSSQLDatabaseException
  File "src\pymssql\_mssql.pyx", line 1834, in pymssql._mssql.raise_MSSQLDatabaseException
pymssql._mssql.MSSQLDatabaseException: (18456, b'DB-Lib error message 20018, severity 14:\nGeneral SQL Server error: Check messages from the SQL Server\nDB-Lib error message 20002, severity 9:\nAdaptive Server connection failed (172.24.32.210)\nDB-Lib error message 20002, severity 9:\nAdaptive Server connection failed (172.24.32.210)\n')

During handling of the above exception, another exception occurred:

Traceback (most recent call last):
  File "D:\CDL\CDL-Barcode-Checker\cdl_barcode_checker\lib\site-packages\sqlalchemy\engine\base.py", line 2336, in _wrap_pool_connect
    return fn()
  File "D:\CDL\CDL-Barcode-Checker\cdl_barcode_checker\lib\site-packages\sqlalchemy\pool\base.py", line 364, in connect
    return _ConnectionFairy._checkout(self)
  File "D:\CDL\CDL-Barcode-Checker\cdl_barcode_checker\lib\site-packages\sqlalchemy\pool\base.py", line 778, in _checkout
    fairy = _ConnectionRecord.checkout(pool)
  File "D:\CDL\CDL-Barcode-Checker\cdl_barcode_checker\lib\site-packages\sqlalchemy\pool\base.py", line 495, in checkout
    rec = pool._do_get()
  File "D:\CDL\CDL-Barcode-Checker\cdl_barcode_checker\lib\site-packages\sqlalchemy\pool\impl.py", line 139, in _do_get
    with util.safe_reraise():
  File "D:\CDL\CDL-Barcode-Checker\cdl_barcode_checker\lib\site-packages\sqlalchemy\util\langhelpers.py", line 68, in __exit__
    compat.raise_(
  File "D:\CDL\CDL-Barcode-Checker\cdl_barcode_checker\lib\site-packages\sqlalchemy\util\compat.py", line 182, in raise_
    raise exception
  File "D:\CDL\CDL-Barcode-Checker\cdl_barcode_checker\lib\site-packages\sqlalchemy\pool\impl.py", line 137, in _do_get
    return self._create_connection()
  File "D:\CDL\CDL-Barcode-Checker\cdl_barcode_checker\lib\site-packages\sqlalchemy\pool\base.py", line 309, in _create_connection
    return _ConnectionRecord(self)
  File "D:\CDL\CDL-Barcode-Checker\cdl_barcode_checker\lib\site-packages\sqlalchemy\pool\base.py", line 440, in __init__
    self.__connect(first_connect_check=True)
  File "D:\CDL\CDL-Barcode-Checker\cdl_barcode_checker\lib\site-packages\sqlalchemy\pool\base.py", line 660, in __connect
    with util.safe_reraise():
  File "D:\CDL\CDL-Barcode-Checker\cdl_barcode_checker\lib\site-packages\sqlalchemy\util\langhelpers.py", line 68, in __exit__
    compat.raise_(
  File "D:\CDL\CDL-Barcode-Checker\cdl_barcode_checker\lib\site-packages\sqlalchemy\util\compat.py", line 182, in raise_
    raise exception
  File "D:\CDL\CDL-Barcode-Checker\cdl_barcode_checker\lib\site-packages\sqlalchemy\pool\base.py", line 656, in __connect
    connection = pool._invoke_creator(self)
  File "D:\CDL\CDL-Barcode-Checker\cdl_barcode_checker\lib\site-packages\sqlalchemy\engine\strategies.py", line 114, in connect
    return dialect.connect(*cargs, **cparams)
  File "D:\CDL\CDL-Barcode-Checker\cdl_barcode_checker\lib\site-packages\sqlalchemy\engine\default.py", line 508, in connect
    return self.dbapi.connect(*cargs, **cparams)
  File "src\pymssql\_pymssql.pyx", line 652, in pymssql._pymssql.connect
pymssql._pymssql.OperationalError: (18456, b'DB-Lib error message 20018, severity 14:\nGeneral SQL Server error: Check messages from the SQL Server\nDB-Lib error message 20002, severity 9:\nAdaptive Server connection failed (172.24.32.210)\nDB-Lib error message 20002, severity 9:\nAdaptive Server connection failed (172.24.32.210)\n')

The above exception was the direct cause of the following exception:

Traceback (most recent call last):
  File "D:\CDL\CDL-Barcode-Checker\cdl_barcode_checker\lib\site-packages\flask\app.py", line 2525, in wsgi_app
    response = self.full_dispatch_request()
  File "D:\CDL\CDL-Barcode-Checker\cdl_barcode_checker\lib\site-packages\flask\app.py", line 1822, in full_dispatch_request
    rv = self.handle_user_exception(e)
  File "D:\CDL\CDL-Barcode-Checker\cdl_barcode_checker\lib\site-packages\flask\app.py", line 1820, in full_dispatch_request
    rv = self.dispatch_request()
  File "D:\CDL\CDL-Barcode-Checker\cdl_barcode_checker\lib\site-packages\flask\app.py", line 1796, in dispatch_request
    return self.ensure_sync(self.view_functions[rule.endpoint])(**view_args)
  File "D:\CDL\CDL-Barcode-Checker\.\barcode_checker\main\routes.py", line 48, in lookup_rte
    records = [r._asdict() for r in dbquery.all()]
  File "D:\CDL\CDL-Barcode-Checker\cdl_barcode_checker\lib\site-packages\sqlalchemy\orm\query.py", line 3373, in all
    return list(self)
  File "D:\CDL\CDL-Barcode-Checker\cdl_barcode_checker\lib\site-packages\sqlalchemy\orm\query.py", line 3535, in __iter__
    return self._execute_and_instances(context)
  File "D:\CDL\CDL-Barcode-Checker\cdl_barcode_checker\lib\site-packages\sqlalchemy\orm\query.py", line 3556, in _execute_and_instances
    conn = self._get_bind_args(
  File "D:\CDL\CDL-Barcode-Checker\cdl_barcode_checker\lib\site-packages\sqlalchemy\orm\query.py", line 3571, in _get_bind_args
    return fn(
  File "D:\CDL\CDL-Barcode-Checker\cdl_barcode_checker\lib\site-packages\sqlalchemy\orm\query.py", line 3550, in _connection_from_session
    conn = self.session.connection(**kw)
  File "D:\CDL\CDL-Barcode-Checker\cdl_barcode_checker\lib\site-packages\sqlalchemy\orm\session.py", line 1142, in connection
    return self._connection_for_bind(
  File "D:\CDL\CDL-Barcode-Checker\cdl_barcode_checker\lib\site-packages\sqlalchemy\orm\session.py", line 1150, in _connection_for_bind
    return self.transaction._connection_for_bind(
  File "D:\CDL\CDL-Barcode-Checker\cdl_barcode_checker\lib\site-packages\sqlalchemy\orm\session.py", line 433, in _connection_for_bind
    conn = bind._contextual_connect()
  File "D:\CDL\CDL-Barcode-Checker\cdl_barcode_checker\lib\site-packages\sqlalchemy\engine\base.py", line 2302, in _contextual_connect
    self._wrap_pool_connect(self.pool.connect, None),
  File "D:\CDL\CDL-Barcode-Checker\cdl_barcode_checker\lib\site-packages\sqlalchemy\engine\base.py", line 2339, in _wrap_pool_connect
    Connection._handle_dbapi_exception_noconnection(
  File "D:\CDL\CDL-Barcode-Checker\cdl_barcode_checker\lib\site-packages\sqlalchemy\engine\base.py", line 1583, in _handle_dbapi_exception_noconnection
    util.raise_(
  File "D:\CDL\CDL-Barcode-Checker\cdl_barcode_checker\lib\site-packages\sqlalchemy\util\compat.py", line 182, in raise_
    raise exception
  File "D:\CDL\CDL-Barcode-Checker\cdl_barcode_checker\lib\site-packages\sqlalchemy\engine\base.py", line 2336, in _wrap_pool_connect
    return fn()
  File "D:\CDL\CDL-Barcode-Checker\cdl_barcode_checker\lib\site-packages\sqlalchemy\pool\base.py", line 364, in connect
    return _ConnectionFairy._checkout(self)
  File "D:\CDL\CDL-Barcode-Checker\cdl_barcode_checker\lib\site-packages\sqlalchemy\pool\base.py", line 778, in _checkout
    fairy = _ConnectionRecord.checkout(pool)
  File "D:\CDL\CDL-Barcode-Checker\cdl_barcode_checker\lib\site-packages\sqlalchemy\pool\base.py", line 495, in checkout
    rec = pool._do_get()
  File "D:\CDL\CDL-Barcode-Checker\cdl_barcode_checker\lib\site-packages\sqlalchemy\pool\impl.py", line 139, in _do_get
    with util.safe_reraise():
  File "D:\CDL\CDL-Barcode-Checker\cdl_barcode_checker\lib\site-packages\sqlalchemy\util\langhelpers.py", line 68, in __exit__
    compat.raise_(
  File "D:\CDL\CDL-Barcode-Checker\cdl_barcode_checker\lib\site-packages\sqlalchemy\util\compat.py", line 182, in raise_
    raise exception
  File "D:\CDL\CDL-Barcode-Checker\cdl_barcode_checker\lib\site-packages\sqlalchemy\pool\impl.py", line 137, in _do_get
    return self._create_connection()
  File "D:\CDL\CDL-Barcode-Checker\cdl_barcode_checker\lib\site-packages\sqlalchemy\pool\base.py", line 309, in _create_connection
    return _ConnectionRecord(self)
  File "D:\CDL\CDL-Barcode-Checker\cdl_barcode_checker\lib\site-packages\sqlalchemy\pool\base.py", line 440, in __init__
    self.__connect(first_connect_check=True)
  File "D:\CDL\CDL-Barcode-Checker\cdl_barcode_checker\lib\site-packages\sqlalchemy\pool\base.py", line 660, in __connect
    with util.safe_reraise():
  File "D:\CDL\CDL-Barcode-Checker\cdl_barcode_checker\lib\site-packages\sqlalchemy\util\langhelpers.py", line 68, in __exit__
    compat.raise_(
  File "D:\CDL\CDL-Barcode-Checker\cdl_barcode_checker\lib\site-packages\sqlalchemy\util\compat.py", line 182, in raise_
    raise exception
  File "D:\CDL\CDL-Barcode-Checker\cdl_barcode_checker\lib\site-packages\sqlalchemy\pool\base.py", line 656, in __connect
    connection = pool._invoke_creator(self)
  File "D:\CDL\CDL-Barcode-Checker\cdl_barcode_checker\lib\site-packages\sqlalchemy\engine\strategies.py", line 114, in connect
    return dialect.connect(*cargs, **cparams)
  File "D:\CDL\CDL-Barcode-Checker\cdl_barcode_checker\lib\site-packages\sqlalchemy\engine\default.py", line 508, in connect
    return self.dbapi.connect(*cargs, **cparams)
  File "src\pymssql\_pymssql.pyx", line 652, in pymssql._pymssql.connect
sqlalchemy.exc.OperationalError: (pymssql._pymssql.OperationalError) (18456, b'DB-Lib error message 20018, severity 14:\nGeneral SQL Server error: Check messages from the SQL Server\nDB-Lib error message 20002, severity 9:\nAdaptive Server connection failed (172.24.32.210)\nDB-Lib error message 20002, severity 9:\nAdaptive Server connection failed (172.24.32.210)\n')
(Background on this error at: http://sqlalche.me/e/13/e3q8)
2023-04-28 15:03:49,012 Exception on /lookup [POST]
Traceback (most recent call last):
  File "src\pymssql\_pymssql.pyx", line 646, in pymssql._pymssql.connect
  File "src\pymssql\_mssql.pyx", line 2108, in pymssql._mssql.connect
  File "src\pymssql\_mssql.pyx", line 700, in pymssql._mssql.MSSQLConnection.__init__
  File "src\pymssql\_mssql.pyx", line 1817, in pymssql._mssql.maybe_raise_MSSQLDatabaseException
  File "src\pymssql\_mssql.pyx", line 1834, in pymssql._mssql.raise_MSSQLDatabaseException
pymssql._mssql.MSSQLDatabaseException: (18456, b"Login failed for user 'CDL_VPOD'.DB-Lib error message 20018, severity 14:\nGeneral SQL Server error: Check messages from the SQL Server\nDB-Lib error message 20002, severity 9:\nAdaptive Server connection failed (172.24.32.210)\nDB-Lib error message 20002, severity 9:\nAdaptive Server connection failed (172.24.32.210)\n")

During handling of the above exception, another exception occurred:

Traceback (most recent call last):
  File "D:\CDL\CDL-Barcode-Checker\cdl_barcode_checker\lib\site-packages\sqlalchemy\engine\base.py", line 2336, in _wrap_pool_connect
    return fn()
  File "D:\CDL\CDL-Barcode-Checker\cdl_barcode_checker\lib\site-packages\sqlalchemy\pool\base.py", line 364, in connect
    return _ConnectionFairy._checkout(self)
  File "D:\CDL\CDL-Barcode-Checker\cdl_barcode_checker\lib\site-packages\sqlalchemy\pool\base.py", line 778, in _checkout
    fairy = _ConnectionRecord.checkout(pool)
  File "D:\CDL\CDL-Barcode-Checker\cdl_barcode_checker\lib\site-packages\sqlalchemy\pool\base.py", line 499, in checkout
    with util.safe_reraise():
  File "D:\CDL\CDL-Barcode-Checker\cdl_barcode_checker\lib\site-packages\sqlalchemy\util\langhelpers.py", line 68, in __exit__
    compat.raise_(
  File "D:\CDL\CDL-Barcode-Checker\cdl_barcode_checker\lib\site-packages\sqlalchemy\util\compat.py", line 182, in raise_
    raise exception
  File "D:\CDL\CDL-Barcode-Checker\cdl_barcode_checker\lib\site-packages\sqlalchemy\pool\base.py", line 497, in checkout
    dbapi_connection = rec.get_connection()
  File "D:\CDL\CDL-Barcode-Checker\cdl_barcode_checker\lib\site-packages\sqlalchemy\pool\base.py", line 610, in get_connection
    self.__connect()
  File "D:\CDL\CDL-Barcode-Checker\cdl_barcode_checker\lib\site-packages\sqlalchemy\pool\base.py", line 660, in __connect
    with util.safe_reraise():
  File "D:\CDL\CDL-Barcode-Checker\cdl_barcode_checker\lib\site-packages\sqlalchemy\util\langhelpers.py", line 68, in __exit__
    compat.raise_(
  File "D:\CDL\CDL-Barcode-Checker\cdl_barcode_checker\lib\site-packages\sqlalchemy\util\compat.py", line 182, in raise_
    raise exception
  File "D:\CDL\CDL-Barcode-Checker\cdl_barcode_checker\lib\site-packages\sqlalchemy\pool\base.py", line 656, in __connect
    connection = pool._invoke_creator(self)
  File "D:\CDL\CDL-Barcode-Checker\cdl_barcode_checker\lib\site-packages\sqlalchemy\engine\strategies.py", line 114, in connect
    return dialect.connect(*cargs, **cparams)
  File "D:\CDL\CDL-Barcode-Checker\cdl_barcode_checker\lib\site-packages\sqlalchemy\engine\default.py", line 508, in connect
    return self.dbapi.connect(*cargs, **cparams)
  File "src\pymssql\_pymssql.pyx", line 652, in pymssql._pymssql.connect
pymssql._pymssql.OperationalError: (18456, b"Login failed for user 'CDL_VPOD'.DB-Lib error message 20018, severity 14:\nGeneral SQL Server error: Check messages from the SQL Server\nDB-Lib error message 20002, severity 9:\nAdaptive Server connection failed (172.24.32.210)\nDB-Lib error message 20002, severity 9:\nAdaptive Server connection failed (172.24.32.210)\n")

The above exception was the direct cause of the following exception:

Traceback (most recent call last):
  File "D:\CDL\CDL-Barcode-Checker\cdl_barcode_checker\lib\site-packages\flask\app.py", line 2525, in wsgi_app
    response = self.full_dispatch_request()
  File "D:\CDL\CDL-Barcode-Checker\cdl_barcode_checker\lib\site-packages\flask\app.py", line 1822, in full_dispatch_request
    rv = self.handle_user_exception(e)
  File "D:\CDL\CDL-Barcode-Checker\cdl_barcode_checker\lib\site-packages\flask\app.py", line 1820, in full_dispatch_request
    rv = self.dispatch_request()
  File "D:\CDL\CDL-Barcode-Checker\cdl_barcode_checker\lib\site-packages\flask\app.py", line 1796, in dispatch_request
    return self.ensure_sync(self.view_functions[rule.endpoint])(**view_args)
  File "D:\CDL\CDL-Barcode-Checker\.\barcode_checker\main\routes.py", line 48, in lookup_rte
    records = [r._asdict() for r in dbquery.all()]
  File "D:\CDL\CDL-Barcode-Checker\cdl_barcode_checker\lib\site-packages\sqlalchemy\orm\query.py", line 3373, in all
    return list(self)
  File "D:\CDL\CDL-Barcode-Checker\cdl_barcode_checker\lib\site-packages\sqlalchemy\orm\query.py", line 3535, in __iter__
    return self._execute_and_instances(context)
  File "D:\CDL\CDL-Barcode-Checker\cdl_barcode_checker\lib\site-packages\sqlalchemy\orm\query.py", line 3556, in _execute_and_instances
    conn = self._get_bind_args(
  File "D:\CDL\CDL-Barcode-Checker\cdl_barcode_checker\lib\site-packages\sqlalchemy\orm\query.py", line 3571, in _get_bind_args
    return fn(
  File "D:\CDL\CDL-Barcode-Checker\cdl_barcode_checker\lib\site-packages\sqlalchemy\orm\query.py", line 3550, in _connection_from_session
    conn = self.session.connection(**kw)
  File "D:\CDL\CDL-Barcode-Checker\cdl_barcode_checker\lib\site-packages\sqlalchemy\orm\session.py", line 1142, in connection
    return self._connection_for_bind(
  File "D:\CDL\CDL-Barcode-Checker\cdl_barcode_checker\lib\site-packages\sqlalchemy\orm\session.py", line 1150, in _connection_for_bind
    return self.transaction._connection_for_bind(
  File "D:\CDL\CDL-Barcode-Checker\cdl_barcode_checker\lib\site-packages\sqlalchemy\orm\session.py", line 433, in _connection_for_bind
    conn = bind._contextual_connect()
  File "D:\CDL\CDL-Barcode-Checker\cdl_barcode_checker\lib\site-packages\sqlalchemy\engine\base.py", line 2302, in _contextual_connect
    self._wrap_pool_connect(self.pool.connect, None),
  File "D:\CDL\CDL-Barcode-Checker\cdl_barcode_checker\lib\site-packages\sqlalchemy\engine\base.py", line 2339, in _wrap_pool_connect
    Connection._handle_dbapi_exception_noconnection(
  File "D:\CDL\CDL-Barcode-Checker\cdl_barcode_checker\lib\site-packages\sqlalchemy\engine\base.py", line 1583, in _handle_dbapi_exception_noconnection
    util.raise_(
  File "D:\CDL\CDL-Barcode-Checker\cdl_barcode_checker\lib\site-packages\sqlalchemy\util\compat.py", line 182, in raise_
    raise exception
  File "D:\CDL\CDL-Barcode-Checker\cdl_barcode_checker\lib\site-packages\sqlalchemy\engine\base.py", line 2336, in _wrap_pool_connect
    return fn()
  File "D:\CDL\CDL-Barcode-Checker\cdl_barcode_checker\lib\site-packages\sqlalchemy\pool\base.py", line 364, in connect
    return _ConnectionFairy._checkout(self)
  File "D:\CDL\CDL-Barcode-Checker\cdl_barcode_checker\lib\site-packages\sqlalchemy\pool\base.py", line 778, in _checkout
    fairy = _ConnectionRecord.checkout(pool)
  File "D:\CDL\CDL-Barcode-Checker\cdl_barcode_checker\lib\site-packages\sqlalchemy\pool\base.py", line 499, in checkout
    with util.safe_reraise():
  File "D:\CDL\CDL-Barcode-Checker\cdl_barcode_checker\lib\site-packages\sqlalchemy\util\langhelpers.py", line 68, in __exit__
    compat.raise_(
  File "D:\CDL\CDL-Barcode-Checker\cdl_barcode_checker\lib\site-packages\sqlalchemy\util\compat.py", line 182, in raise_
    raise exception
  File "D:\CDL\CDL-Barcode-Checker\cdl_barcode_checker\lib\site-packages\sqlalchemy\pool\base.py", line 497, in checkout
    dbapi_connection = rec.get_connection()
  File "D:\CDL\CDL-Barcode-Checker\cdl_barcode_checker\lib\site-packages\sqlalchemy\pool\base.py", line 610, in get_connection
    self.__connect()
  File "D:\CDL\CDL-Barcode-Checker\cdl_barcode_checker\lib\site-packages\sqlalchemy\pool\base.py", line 660, in __connect
    with util.safe_reraise():
  File "D:\CDL\CDL-Barcode-Checker\cdl_barcode_checker\lib\site-packages\sqlalchemy\util\langhelpers.py", line 68, in __exit__
    compat.raise_(
  File "D:\CDL\CDL-Barcode-Checker\cdl_barcode_checker\lib\site-packages\sqlalchemy\util\compat.py", line 182, in raise_
    raise exception
  File "D:\CDL\CDL-Barcode-Checker\cdl_barcode_checker\lib\site-packages\sqlalchemy\pool\base.py", line 656, in __connect
    connection = pool._invoke_creator(self)
  File "D:\CDL\CDL-Barcode-Checker\cdl_barcode_checker\lib\site-packages\sqlalchemy\engine\strategies.py", line 114, in connect
    return dialect.connect(*cargs, **cparams)
  File "D:\CDL\CDL-Barcode-Checker\cdl_barcode_checker\lib\site-packages\sqlalchemy\engine\default.py", line 508, in connect
    return self.dbapi.connect(*cargs, **cparams)
  File "src\pymssql\_pymssql.pyx", line 652, in pymssql._pymssql.connect
sqlalchemy.exc.OperationalError: (pymssql._pymssql.OperationalError) (18456, b"Login failed for user 'CDL_VPOD'.DB-Lib error message 20018, severity 14:\nGeneral SQL Server error: Check messages from the SQL Server\nDB-Lib error message 20002, severity 9:\nAdaptive Server connection failed (172.24.32.210)\nDB-Lib error message 20002, severity 9:\nAdaptive Server connection failed (172.24.32.210)\n")
(Background on this error at: http://sqlalche.me/e/13/e3q8)
2023-04-28 15:04:07,669 Exception on /lookup [POST]
Traceback (most recent call last):
  File "src\pymssql\_pymssql.pyx", line 646, in pymssql._pymssql.connect
  File "src\pymssql\_mssql.pyx", line 2108, in pymssql._mssql.connect
  File "src\pymssql\_mssql.pyx", line 700, in pymssql._mssql.MSSQLConnection.__init__
  File "src\pymssql\_mssql.pyx", line 1817, in pymssql._mssql.maybe_raise_MSSQLDatabaseException
  File "src\pymssql\_mssql.pyx", line 1834, in pymssql._mssql.raise_MSSQLDatabaseException
pymssql._mssql.MSSQLDatabaseException: (18456, b'DB-Lib error message 20018, severity 14:\nGeneral SQL Server error: Check messages from the SQL Server\nDB-Lib error message 20002, severity 9:\nAdaptive Server connection failed (172.24.32.210)\nDB-Lib error message 20002, severity 9:\nAdaptive Server connection failed (172.24.32.210)\n')

During handling of the above exception, another exception occurred:

Traceback (most recent call last):
  File "D:\CDL\CDL-Barcode-Checker\cdl_barcode_checker\lib\site-packages\sqlalchemy\engine\base.py", line 2336, in _wrap_pool_connect
    return fn()
  File "D:\CDL\CDL-Barcode-Checker\cdl_barcode_checker\lib\site-packages\sqlalchemy\pool\base.py", line 364, in connect
    return _ConnectionFairy._checkout(self)
  File "D:\CDL\CDL-Barcode-Checker\cdl_barcode_checker\lib\site-packages\sqlalchemy\pool\base.py", line 778, in _checkout
    fairy = _ConnectionRecord.checkout(pool)
  File "D:\CDL\CDL-Barcode-Checker\cdl_barcode_checker\lib\site-packages\sqlalchemy\pool\base.py", line 499, in checkout
    with util.safe_reraise():
  File "D:\CDL\CDL-Barcode-Checker\cdl_barcode_checker\lib\site-packages\sqlalchemy\util\langhelpers.py", line 68, in __exit__
    compat.raise_(
  File "D:\CDL\CDL-Barcode-Checker\cdl_barcode_checker\lib\site-packages\sqlalchemy\util\compat.py", line 182, in raise_
    raise exception
  File "D:\CDL\CDL-Barcode-Checker\cdl_barcode_checker\lib\site-packages\sqlalchemy\pool\base.py", line 497, in checkout
    dbapi_connection = rec.get_connection()
  File "D:\CDL\CDL-Barcode-Checker\cdl_barcode_checker\lib\site-packages\sqlalchemy\pool\base.py", line 610, in get_connection
    self.__connect()
  File "D:\CDL\CDL-Barcode-Checker\cdl_barcode_checker\lib\site-packages\sqlalchemy\pool\base.py", line 660, in __connect
    with util.safe_reraise():
  File "D:\CDL\CDL-Barcode-Checker\cdl_barcode_checker\lib\site-packages\sqlalchemy\util\langhelpers.py", line 68, in __exit__
    compat.raise_(
  File "D:\CDL\CDL-Barcode-Checker\cdl_barcode_checker\lib\site-packages\sqlalchemy\util\compat.py", line 182, in raise_
    raise exception
  File "D:\CDL\CDL-Barcode-Checker\cdl_barcode_checker\lib\site-packages\sqlalchemy\pool\base.py", line 656, in __connect
    connection = pool._invoke_creator(self)
  File "D:\CDL\CDL-Barcode-Checker\cdl_barcode_checker\lib\site-packages\sqlalchemy\engine\strategies.py", line 114, in connect
    return dialect.connect(*cargs, **cparams)
  File "D:\CDL\CDL-Barcode-Checker\cdl_barcode_checker\lib\site-packages\sqlalchemy\engine\default.py", line 508, in connect
    return self.dbapi.connect(*cargs, **cparams)
  File "src\pymssql\_pymssql.pyx", line 652, in pymssql._pymssql.connect
pymssql._pymssql.OperationalError: (18456, b'DB-Lib error message 20018, severity 14:\nGeneral SQL Server error: Check messages from the SQL Server\nDB-Lib error message 20002, severity 9:\nAdaptive Server connection failed (172.24.32.210)\nDB-Lib error message 20002, severity 9:\nAdaptive Server connection failed (172.24.32.210)\n')

The above exception was the direct cause of the following exception:

Traceback (most recent call last):
  File "D:\CDL\CDL-Barcode-Checker\cdl_barcode_checker\lib\site-packages\flask\app.py", line 2525, in wsgi_app
    response = self.full_dispatch_request()
  File "D:\CDL\CDL-Barcode-Checker\cdl_barcode_checker\lib\site-packages\flask\app.py", line 1822, in full_dispatch_request
    rv = self.handle_user_exception(e)
  File "D:\CDL\CDL-Barcode-Checker\cdl_barcode_checker\lib\site-packages\flask\app.py", line 1820, in full_dispatch_request
    rv = self.dispatch_request()
  File "D:\CDL\CDL-Barcode-Checker\cdl_barcode_checker\lib\site-packages\flask\app.py", line 1796, in dispatch_request
    return self.ensure_sync(self.view_functions[rule.endpoint])(**view_args)
  File "D:\CDL\CDL-Barcode-Checker\.\barcode_checker\main\routes.py", line 48, in lookup_rte
    records = [r._asdict() for r in dbquery.all()]
  File "D:\CDL\CDL-Barcode-Checker\cdl_barcode_checker\lib\site-packages\sqlalchemy\orm\query.py", line 3373, in all
    return list(self)
  File "D:\CDL\CDL-Barcode-Checker\cdl_barcode_checker\lib\site-packages\sqlalchemy\orm\query.py", line 3535, in __iter__
    return self._execute_and_instances(context)
  File "D:\CDL\CDL-Barcode-Checker\cdl_barcode_checker\lib\site-packages\sqlalchemy\orm\query.py", line 3556, in _execute_and_instances
    conn = self._get_bind_args(
  File "D:\CDL\CDL-Barcode-Checker\cdl_barcode_checker\lib\site-packages\sqlalchemy\orm\query.py", line 3571, in _get_bind_args
    return fn(
  File "D:\CDL\CDL-Barcode-Checker\cdl_barcode_checker\lib\site-packages\sqlalchemy\orm\query.py", line 3550, in _connection_from_session
    conn = self.session.connection(**kw)
  File "D:\CDL\CDL-Barcode-Checker\cdl_barcode_checker\lib\site-packages\sqlalchemy\orm\session.py", line 1142, in connection
    return self._connection_for_bind(
  File "D:\CDL\CDL-Barcode-Checker\cdl_barcode_checker\lib\site-packages\sqlalchemy\orm\session.py", line 1150, in _connection_for_bind
    return self.transaction._connection_for_bind(
  File "D:\CDL\CDL-Barcode-Checker\cdl_barcode_checker\lib\site-packages\sqlalchemy\orm\session.py", line 433, in _connection_for_bind
    conn = bind._contextual_connect()
  File "D:\CDL\CDL-Barcode-Checker\cdl_barcode_checker\lib\site-packages\sqlalchemy\engine\base.py", line 2302, in _contextual_connect
    self._wrap_pool_connect(self.pool.connect, None),
  File "D:\CDL\CDL-Barcode-Checker\cdl_barcode_checker\lib\site-packages\sqlalchemy\engine\base.py", line 2339, in _wrap_pool_connect
    Connection._handle_dbapi_exception_noconnection(
  File "D:\CDL\CDL-Barcode-Checker\cdl_barcode_checker\lib\site-packages\sqlalchemy\engine\base.py", line 1583, in _handle_dbapi_exception_noconnection
    util.raise_(
  File "D:\CDL\CDL-Barcode-Checker\cdl_barcode_checker\lib\site-packages\sqlalchemy\util\compat.py", line 182, in raise_
    raise exception
  File "D:\CDL\CDL-Barcode-Checker\cdl_barcode_checker\lib\site-packages\sqlalchemy\engine\base.py", line 2336, in _wrap_pool_connect
    return fn()
  File "D:\CDL\CDL-Barcode-Checker\cdl_barcode_checker\lib\site-packages\sqlalchemy\pool\base.py", line 364, in connect
    return _ConnectionFairy._checkout(self)
  File "D:\CDL\CDL-Barcode-Checker\cdl_barcode_checker\lib\site-packages\sqlalchemy\pool\base.py", line 778, in _checkout
    fairy = _ConnectionRecord.checkout(pool)
  File "D:\CDL\CDL-Barcode-Checker\cdl_barcode_checker\lib\site-packages\sqlalchemy\pool\base.py", line 499, in checkout
    with util.safe_reraise():
  File "D:\CDL\CDL-Barcode-Checker\cdl_barcode_checker\lib\site-packages\sqlalchemy\util\langhelpers.py", line 68, in __exit__
    compat.raise_(
  File "D:\CDL\CDL-Barcode-Checker\cdl_barcode_checker\lib\site-packages\sqlalchemy\util\compat.py", line 182, in raise_
    raise exception
  File "D:\CDL\CDL-Barcode-Checker\cdl_barcode_checker\lib\site-packages\sqlalchemy\pool\base.py", line 497, in checkout
    dbapi_connection = rec.get_connection()
  File "D:\CDL\CDL-Barcode-Checker\cdl_barcode_checker\lib\site-packages\sqlalchemy\pool\base.py", line 610, in get_connection
    self.__connect()
  File "D:\CDL\CDL-Barcode-Checker\cdl_barcode_checker\lib\site-packages\sqlalchemy\pool\base.py", line 660, in __connect
    with util.safe_reraise():
  File "D:\CDL\CDL-Barcode-Checker\cdl_barcode_checker\lib\site-packages\sqlalchemy\util\langhelpers.py", line 68, in __exit__
    compat.raise_(
  File "D:\CDL\CDL-Barcode-Checker\cdl_barcode_checker\lib\site-packages\sqlalchemy\util\compat.py", line 182, in raise_
    raise exception
  File "D:\CDL\CDL-Barcode-Checker\cdl_barcode_checker\lib\site-packages\sqlalchemy\pool\base.py", line 656, in __connect
    connection = pool._invoke_creator(self)
  File "D:\CDL\CDL-Barcode-Checker\cdl_barcode_checker\lib\site-packages\sqlalchemy\engine\strategies.py", line 114, in connect
    return dialect.connect(*cargs, **cparams)
  File "D:\CDL\CDL-Barcode-Checker\cdl_barcode_checker\lib\site-packages\sqlalchemy\engine\default.py", line 508, in connect
    return self.dbapi.connect(*cargs, **cparams)
  File "src\pymssql\_pymssql.pyx", line 652, in pymssql._pymssql.connect
sqlalchemy.exc.OperationalError: (pymssql._pymssql.OperationalError) (18456, b'DB-Lib error message 20018, severity 14:\nGeneral SQL Server error: Check messages from the SQL Server\nDB-Lib error message 20002, severity 9:\nAdaptive Server connection failed (172.24.32.210)\nDB-Lib error message 20002, severity 9:\nAdaptive Server connection failed (172.24.32.210)\n')
(Background on this error at: http://sqlalche.me/e/13/e3q8)
2023-04-28 15:04:15,635 Exception on /lookup [POST]
Traceback (most recent call last):
  File "src\pymssql\_pymssql.pyx", line 646, in pymssql._pymssql.connect
  File "src\pymssql\_mssql.pyx", line 2108, in pymssql._mssql.connect
  File "src\pymssql\_mssql.pyx", line 700, in pymssql._mssql.MSSQLConnection.__init__
  File "src\pymssql\_mssql.pyx", line 1817, in pymssql._mssql.maybe_raise_MSSQLDatabaseException
  File "src\pymssql\_mssql.pyx", line 1834, in pymssql._mssql.raise_MSSQLDatabaseException
pymssql._mssql.MSSQLDatabaseException: (18456, b'DB-Lib error message 20018, severity 14:\nGeneral SQL Server error: Check messages from the SQL Server\nDB-Lib error message 20002, severity 9:\nAdaptive Server connection failed (172.24.32.210)\nDB-Lib error message 20002, severity 9:\nAdaptive Server connection failed (172.24.32.210)\n')

During handling of the above exception, another exception occurred:

Traceback (most recent call last):
  File "D:\CDL\CDL-Barcode-Checker\cdl_barcode_checker\lib\site-packages\sqlalchemy\engine\base.py", line 2336, in _wrap_pool_connect
    return fn()
  File "D:\CDL\CDL-Barcode-Checker\cdl_barcode_checker\lib\site-packages\sqlalchemy\pool\base.py", line 364, in connect
    return _ConnectionFairy._checkout(self)
  File "D:\CDL\CDL-Barcode-Checker\cdl_barcode_checker\lib\site-packages\sqlalchemy\pool\base.py", line 778, in _checkout
    fairy = _ConnectionRecord.checkout(pool)
  File "D:\CDL\CDL-Barcode-Checker\cdl_barcode_checker\lib\site-packages\sqlalchemy\pool\base.py", line 495, in checkout
    rec = pool._do_get()
  File "D:\CDL\CDL-Barcode-Checker\cdl_barcode_checker\lib\site-packages\sqlalchemy\pool\impl.py", line 139, in _do_get
    with util.safe_reraise():
  File "D:\CDL\CDL-Barcode-Checker\cdl_barcode_checker\lib\site-packages\sqlalchemy\util\langhelpers.py", line 68, in __exit__
    compat.raise_(
  File "D:\CDL\CDL-Barcode-Checker\cdl_barcode_checker\lib\site-packages\sqlalchemy\util\compat.py", line 182, in raise_
    raise exception
  File "D:\CDL\CDL-Barcode-Checker\cdl_barcode_checker\lib\site-packages\sqlalchemy\pool\impl.py", line 137, in _do_get
    return self._create_connection()
  File "D:\CDL\CDL-Barcode-Checker\cdl_barcode_checker\lib\site-packages\sqlalchemy\pool\base.py", line 309, in _create_connection
    return _ConnectionRecord(self)
  File "D:\CDL\CDL-Barcode-Checker\cdl_barcode_checker\lib\site-packages\sqlalchemy\pool\base.py", line 440, in __init__
    self.__connect(first_connect_check=True)
  File "D:\CDL\CDL-Barcode-Checker\cdl_barcode_checker\lib\site-packages\sqlalchemy\pool\base.py", line 660, in __connect
    with util.safe_reraise():
  File "D:\CDL\CDL-Barcode-Checker\cdl_barcode_checker\lib\site-packages\sqlalchemy\util\langhelpers.py", line 68, in __exit__
    compat.raise_(
  File "D:\CDL\CDL-Barcode-Checker\cdl_barcode_checker\lib\site-packages\sqlalchemy\util\compat.py", line 182, in raise_
    raise exception
  File "D:\CDL\CDL-Barcode-Checker\cdl_barcode_checker\lib\site-packages\sqlalchemy\pool\base.py", line 656, in __connect
    connection = pool._invoke_creator(self)
  File "D:\CDL\CDL-Barcode-Checker\cdl_barcode_checker\lib\site-packages\sqlalchemy\engine\strategies.py", line 114, in connect
    return dialect.connect(*cargs, **cparams)
  File "D:\CDL\CDL-Barcode-Checker\cdl_barcode_checker\lib\site-packages\sqlalchemy\engine\default.py", line 508, in connect
    return self.dbapi.connect(*cargs, **cparams)
  File "src\pymssql\_pymssql.pyx", line 652, in pymssql._pymssql.connect
pymssql._pymssql.OperationalError: (18456, b'DB-Lib error message 20018, severity 14:\nGeneral SQL Server error: Check messages from the SQL Server\nDB-Lib error message 20002, severity 9:\nAdaptive Server connection failed (172.24.32.210)\nDB-Lib error message 20002, severity 9:\nAdaptive Server connection failed (172.24.32.210)\n')

The above exception was the direct cause of the following exception:

Traceback (most recent call last):
  File "D:\CDL\CDL-Barcode-Checker\cdl_barcode_checker\lib\site-packages\flask\app.py", line 2525, in wsgi_app
    response = self.full_dispatch_request()
  File "D:\CDL\CDL-Barcode-Checker\cdl_barcode_checker\lib\site-packages\flask\app.py", line 1822, in full_dispatch_request
    rv = self.handle_user_exception(e)
  File "D:\CDL\CDL-Barcode-Checker\cdl_barcode_checker\lib\site-packages\flask\app.py", line 1820, in full_dispatch_request
    rv = self.dispatch_request()
  File "D:\CDL\CDL-Barcode-Checker\cdl_barcode_checker\lib\site-packages\flask\app.py", line 1796, in dispatch_request
    return self.ensure_sync(self.view_functions[rule.endpoint])(**view_args)
  File "D:\CDL\CDL-Barcode-Checker\.\barcode_checker\main\routes.py", line 48, in lookup_rte
    records = [r._asdict() for r in dbquery.all()]
  File "D:\CDL\CDL-Barcode-Checker\cdl_barcode_checker\lib\site-packages\sqlalchemy\orm\query.py", line 3373, in all
    return list(self)
  File "D:\CDL\CDL-Barcode-Checker\cdl_barcode_checker\lib\site-packages\sqlalchemy\orm\query.py", line 3535, in __iter__
    return self._execute_and_instances(context)
  File "D:\CDL\CDL-Barcode-Checker\cdl_barcode_checker\lib\site-packages\sqlalchemy\orm\query.py", line 3556, in _execute_and_instances
    conn = self._get_bind_args(
  File "D:\CDL\CDL-Barcode-Checker\cdl_barcode_checker\lib\site-packages\sqlalchemy\orm\query.py", line 3571, in _get_bind_args
    return fn(
  File "D:\CDL\CDL-Barcode-Checker\cdl_barcode_checker\lib\site-packages\sqlalchemy\orm\query.py", line 3550, in _connection_from_session
    conn = self.session.connection(**kw)
  File "D:\CDL\CDL-Barcode-Checker\cdl_barcode_checker\lib\site-packages\sqlalchemy\orm\session.py", line 1142, in connection
    return self._connection_for_bind(
  File "D:\CDL\CDL-Barcode-Checker\cdl_barcode_checker\lib\site-packages\sqlalchemy\orm\session.py", line 1150, in _connection_for_bind
    return self.transaction._connection_for_bind(
  File "D:\CDL\CDL-Barcode-Checker\cdl_barcode_checker\lib\site-packages\sqlalchemy\orm\session.py", line 433, in _connection_for_bind
    conn = bind._contextual_connect()
  File "D:\CDL\CDL-Barcode-Checker\cdl_barcode_checker\lib\site-packages\sqlalchemy\engine\base.py", line 2302, in _contextual_connect
    self._wrap_pool_connect(self.pool.connect, None),
  File "D:\CDL\CDL-Barcode-Checker\cdl_barcode_checker\lib\site-packages\sqlalchemy\engine\base.py", line 2339, in _wrap_pool_connect
    Connection._handle_dbapi_exception_noconnection(
  File "D:\CDL\CDL-Barcode-Checker\cdl_barcode_checker\lib\site-packages\sqlalchemy\engine\base.py", line 1583, in _handle_dbapi_exception_noconnection
    util.raise_(
  File "D:\CDL\CDL-Barcode-Checker\cdl_barcode_checker\lib\site-packages\sqlalchemy\util\compat.py", line 182, in raise_
    raise exception
  File "D:\CDL\CDL-Barcode-Checker\cdl_barcode_checker\lib\site-packages\sqlalchemy\engine\base.py", line 2336, in _wrap_pool_connect
    return fn()
  File "D:\CDL\CDL-Barcode-Checker\cdl_barcode_checker\lib\site-packages\sqlalchemy\pool\base.py", line 364, in connect
    return _ConnectionFairy._checkout(self)
  File "D:\CDL\CDL-Barcode-Checker\cdl_barcode_checker\lib\site-packages\sqlalchemy\pool\base.py", line 778, in _checkout
    fairy = _ConnectionRecord.checkout(pool)
  File "D:\CDL\CDL-Barcode-Checker\cdl_barcode_checker\lib\site-packages\sqlalchemy\pool\base.py", line 495, in checkout
    rec = pool._do_get()
  File "D:\CDL\CDL-Barcode-Checker\cdl_barcode_checker\lib\site-packages\sqlalchemy\pool\impl.py", line 139, in _do_get
    with util.safe_reraise():
  File "D:\CDL\CDL-Barcode-Checker\cdl_barcode_checker\lib\site-packages\sqlalchemy\util\langhelpers.py", line 68, in __exit__
    compat.raise_(
  File "D:\CDL\CDL-Barcode-Checker\cdl_barcode_checker\lib\site-packages\sqlalchemy\util\compat.py", line 182, in raise_
    raise exception
  File "D:\CDL\CDL-Barcode-Checker\cdl_barcode_checker\lib\site-packages\sqlalchemy\pool\impl.py", line 137, in _do_get
    return self._create_connection()
  File "D:\CDL\CDL-Barcode-Checker\cdl_barcode_checker\lib\site-packages\sqlalchemy\pool\base.py", line 309, in _create_connection
    return _ConnectionRecord(self)
  File "D:\CDL\CDL-Barcode-Checker\cdl_barcode_checker\lib\site-packages\sqlalchemy\pool\base.py", line 440, in __init__
    self.__connect(first_connect_check=True)
  File "D:\CDL\CDL-Barcode-Checker\cdl_barcode_checker\lib\site-packages\sqlalchemy\pool\base.py", line 660, in __connect
    with util.safe_reraise():
  File "D:\CDL\CDL-Barcode-Checker\cdl_barcode_checker\lib\site-packages\sqlalchemy\util\langhelpers.py", line 68, in __exit__
    compat.raise_(
  File "D:\CDL\CDL-Barcode-Checker\cdl_barcode_checker\lib\site-packages\sqlalchemy\util\compat.py", line 182, in raise_
    raise exception
  File "D:\CDL\CDL-Barcode-Checker\cdl_barcode_checker\lib\site-packages\sqlalchemy\pool\base.py", line 656, in __connect
    connection = pool._invoke_creator(self)
  File "D:\CDL\CDL-Barcode-Checker\cdl_barcode_checker\lib\site-packages\sqlalchemy\engine\strategies.py", line 114, in connect
    return dialect.connect(*cargs, **cparams)
  File "D:\CDL\CDL-Barcode-Checker\cdl_barcode_checker\lib\site-packages\sqlalchemy\engine\default.py", line 508, in connect
    return self.dbapi.connect(*cargs, **cparams)
  File "src\pymssql\_pymssql.pyx", line 652, in pymssql._pymssql.connect
sqlalchemy.exc.OperationalError: (pymssql._pymssql.OperationalError) (18456, b'DB-Lib error message 20018, severity 14:\nGeneral SQL Server error: Check messages from the SQL Server\nDB-Lib error message 20002, severity 9:\nAdaptive Server connection failed (172.24.32.210)\nDB-Lib error message 20002, severity 9:\nAdaptive Server connection failed (172.24.32.210)\n')
(Background on this error at: http://sqlalche.me/e/13/e3q8)
2023-04-28 15:04:49,661 Exception on /lookup [POST]
Traceback (most recent call last):
  File "src\pymssql\_pymssql.pyx", line 646, in pymssql._pymssql.connect
  File "src\pymssql\_mssql.pyx", line 2108, in pymssql._mssql.connect
  File "src\pymssql\_mssql.pyx", line 700, in pymssql._mssql.MSSQLConnection.__init__
  File "src\pymssql\_mssql.pyx", line 1817, in pymssql._mssql.maybe_raise_MSSQLDatabaseException
  File "src\pymssql\_mssql.pyx", line 1834, in pymssql._mssql.raise_MSSQLDatabaseException
pymssql._mssql.MSSQLDatabaseException: (18456, b'DB-Lib error message 20018, severity 14:\nGeneral SQL Server error: Check messages from the SQL Server\nDB-Lib error message 20002, severity 9:\nAdaptive Server connection failed (172.24.32.210)\nDB-Lib error message 20002, severity 9:\nAdaptive Server connection failed (172.24.32.210)\n')

During handling of the above exception, another exception occurred:

Traceback (most recent call last):
  File "D:\CDL\CDL-Barcode-Checker\cdl_barcode_checker\lib\site-packages\sqlalchemy\engine\base.py", line 2336, in _wrap_pool_connect
    return fn()
  File "D:\CDL\CDL-Barcode-Checker\cdl_barcode_checker\lib\site-packages\sqlalchemy\pool\base.py", line 364, in connect
    return _ConnectionFairy._checkout(self)
  File "D:\CDL\CDL-Barcode-Checker\cdl_barcode_checker\lib\site-packages\sqlalchemy\pool\base.py", line 778, in _checkout
    fairy = _ConnectionRecord.checkout(pool)
  File "D:\CDL\CDL-Barcode-Checker\cdl_barcode_checker\lib\site-packages\sqlalchemy\pool\base.py", line 495, in checkout
    rec = pool._do_get()
  File "D:\CDL\CDL-Barcode-Checker\cdl_barcode_checker\lib\site-packages\sqlalchemy\pool\impl.py", line 139, in _do_get
    with util.safe_reraise():
  File "D:\CDL\CDL-Barcode-Checker\cdl_barcode_checker\lib\site-packages\sqlalchemy\util\langhelpers.py", line 68, in __exit__
    compat.raise_(
  File "D:\CDL\CDL-Barcode-Checker\cdl_barcode_checker\lib\site-packages\sqlalchemy\util\compat.py", line 182, in raise_
    raise exception
  File "D:\CDL\CDL-Barcode-Checker\cdl_barcode_checker\lib\site-packages\sqlalchemy\pool\impl.py", line 137, in _do_get
    return self._create_connection()
  File "D:\CDL\CDL-Barcode-Checker\cdl_barcode_checker\lib\site-packages\sqlalchemy\pool\base.py", line 309, in _create_connection
    return _ConnectionRecord(self)
  File "D:\CDL\CDL-Barcode-Checker\cdl_barcode_checker\lib\site-packages\sqlalchemy\pool\base.py", line 440, in __init__
    self.__connect(first_connect_check=True)
  File "D:\CDL\CDL-Barcode-Checker\cdl_barcode_checker\lib\site-packages\sqlalchemy\pool\base.py", line 660, in __connect
    with util.safe_reraise():
  File "D:\CDL\CDL-Barcode-Checker\cdl_barcode_checker\lib\site-packages\sqlalchemy\util\langhelpers.py", line 68, in __exit__
    compat.raise_(
  File "D:\CDL\CDL-Barcode-Checker\cdl_barcode_checker\lib\site-packages\sqlalchemy\util\compat.py", line 182, in raise_
    raise exception
  File "D:\CDL\CDL-Barcode-Checker\cdl_barcode_checker\lib\site-packages\sqlalchemy\pool\base.py", line 656, in __connect
    connection = pool._invoke_creator(self)
  File "D:\CDL\CDL-Barcode-Checker\cdl_barcode_checker\lib\site-packages\sqlalchemy\engine\strategies.py", line 114, in connect
    return dialect.connect(*cargs, **cparams)
  File "D:\CDL\CDL-Barcode-Checker\cdl_barcode_checker\lib\site-packages\sqlalchemy\engine\default.py", line 508, in connect
    return self.dbapi.connect(*cargs, **cparams)
  File "src\pymssql\_pymssql.pyx", line 652, in pymssql._pymssql.connect
pymssql._pymssql.OperationalError: (18456, b'DB-Lib error message 20018, severity 14:\nGeneral SQL Server error: Check messages from the SQL Server\nDB-Lib error message 20002, severity 9:\nAdaptive Server connection failed (172.24.32.210)\nDB-Lib error message 20002, severity 9:\nAdaptive Server connection failed (172.24.32.210)\n')

The above exception was the direct cause of the following exception:

Traceback (most recent call last):
  File "D:\CDL\CDL-Barcode-Checker\cdl_barcode_checker\lib\site-packages\flask\app.py", line 2525, in wsgi_app
    response = self.full_dispatch_request()
  File "D:\CDL\CDL-Barcode-Checker\cdl_barcode_checker\lib\site-packages\flask\app.py", line 1822, in full_dispatch_request
    rv = self.handle_user_exception(e)
  File "D:\CDL\CDL-Barcode-Checker\cdl_barcode_checker\lib\site-packages\flask\app.py", line 1820, in full_dispatch_request
    rv = self.dispatch_request()
  File "D:\CDL\CDL-Barcode-Checker\cdl_barcode_checker\lib\site-packages\flask\app.py", line 1796, in dispatch_request
    return self.ensure_sync(self.view_functions[rule.endpoint])(**view_args)
  File "D:\CDL\CDL-Barcode-Checker\.\barcode_checker\main\routes.py", line 48, in lookup_rte
    records = [r._asdict() for r in dbquery.all()]
  File "D:\CDL\CDL-Barcode-Checker\cdl_barcode_checker\lib\site-packages\sqlalchemy\orm\query.py", line 3373, in all
    return list(self)
  File "D:\CDL\CDL-Barcode-Checker\cdl_barcode_checker\lib\site-packages\sqlalchemy\orm\query.py", line 3535, in __iter__
    return self._execute_and_instances(context)
  File "D:\CDL\CDL-Barcode-Checker\cdl_barcode_checker\lib\site-packages\sqlalchemy\orm\query.py", line 3556, in _execute_and_instances
    conn = self._get_bind_args(
  File "D:\CDL\CDL-Barcode-Checker\cdl_barcode_checker\lib\site-packages\sqlalchemy\orm\query.py", line 3571, in _get_bind_args
    return fn(
  File "D:\CDL\CDL-Barcode-Checker\cdl_barcode_checker\lib\site-packages\sqlalchemy\orm\query.py", line 3550, in _connection_from_session
    conn = self.session.connection(**kw)
  File "D:\CDL\CDL-Barcode-Checker\cdl_barcode_checker\lib\site-packages\sqlalchemy\orm\session.py", line 1142, in connection
    return self._connection_for_bind(
  File "D:\CDL\CDL-Barcode-Checker\cdl_barcode_checker\lib\site-packages\sqlalchemy\orm\session.py", line 1150, in _connection_for_bind
    return self.transaction._connection_for_bind(
  File "D:\CDL\CDL-Barcode-Checker\cdl_barcode_checker\lib\site-packages\sqlalchemy\orm\session.py", line 433, in _connection_for_bind
    conn = bind._contextual_connect()
  File "D:\CDL\CDL-Barcode-Checker\cdl_barcode_checker\lib\site-packages\sqlalchemy\engine\base.py", line 2302, in _contextual_connect
    self._wrap_pool_connect(self.pool.connect, None),
  File "D:\CDL\CDL-Barcode-Checker\cdl_barcode_checker\lib\site-packages\sqlalchemy\engine\base.py", line 2339, in _wrap_pool_connect
    Connection._handle_dbapi_exception_noconnection(
  File "D:\CDL\CDL-Barcode-Checker\cdl_barcode_checker\lib\site-packages\sqlalchemy\engine\base.py", line 1583, in _handle_dbapi_exception_noconnection
    util.raise_(
  File "D:\CDL\CDL-Barcode-Checker\cdl_barcode_checker\lib\site-packages\sqlalchemy\util\compat.py", line 182, in raise_
    raise exception
  File "D:\CDL\CDL-Barcode-Checker\cdl_barcode_checker\lib\site-packages\sqlalchemy\engine\base.py", line 2336, in _wrap_pool_connect
    return fn()
  File "D:\CDL\CDL-Barcode-Checker\cdl_barcode_checker\lib\site-packages\sqlalchemy\pool\base.py", line 364, in connect
    return _ConnectionFairy._checkout(self)
  File "D:\CDL\CDL-Barcode-Checker\cdl_barcode_checker\lib\site-packages\sqlalchemy\pool\base.py", line 778, in _checkout
    fairy = _ConnectionRecord.checkout(pool)
  File "D:\CDL\CDL-Barcode-Checker\cdl_barcode_checker\lib\site-packages\sqlalchemy\pool\base.py", line 495, in checkout
    rec = pool._do_get()
  File "D:\CDL\CDL-Barcode-Checker\cdl_barcode_checker\lib\site-packages\sqlalchemy\pool\impl.py", line 139, in _do_get
    with util.safe_reraise():
  File "D:\CDL\CDL-Barcode-Checker\cdl_barcode_checker\lib\site-packages\sqlalchemy\util\langhelpers.py", line 68, in __exit__
    compat.raise_(
  File "D:\CDL\CDL-Barcode-Checker\cdl_barcode_checker\lib\site-packages\sqlalchemy\util\compat.py", line 182, in raise_
    raise exception
  File "D:\CDL\CDL-Barcode-Checker\cdl_barcode_checker\lib\site-packages\sqlalchemy\pool\impl.py", line 137, in _do_get
    return self._create_connection()
  File "D:\CDL\CDL-Barcode-Checker\cdl_barcode_checker\lib\site-packages\sqlalchemy\pool\base.py", line 309, in _create_connection
    return _ConnectionRecord(self)
  File "D:\CDL\CDL-Barcode-Checker\cdl_barcode_checker\lib\site-packages\sqlalchemy\pool\base.py", line 440, in __init__
    self.__connect(first_connect_check=True)
  File "D:\CDL\CDL-Barcode-Checker\cdl_barcode_checker\lib\site-packages\sqlalchemy\pool\base.py", line 660, in __connect
    with util.safe_reraise():
  File "D:\CDL\CDL-Barcode-Checker\cdl_barcode_checker\lib\site-packages\sqlalchemy\util\langhelpers.py", line 68, in __exit__
    compat.raise_(
  File "D:\CDL\CDL-Barcode-Checker\cdl_barcode_checker\lib\site-packages\sqlalchemy\util\compat.py", line 182, in raise_
    raise exception
  File "D:\CDL\CDL-Barcode-Checker\cdl_barcode_checker\lib\site-packages\sqlalchemy\pool\base.py", line 656, in __connect
    connection = pool._invoke_creator(self)
  File "D:\CDL\CDL-Barcode-Checker\cdl_barcode_checker\lib\site-packages\sqlalchemy\engine\strategies.py", line 114, in connect
    return dialect.connect(*cargs, **cparams)
  File "D:\CDL\CDL-Barcode-Checker\cdl_barcode_checker\lib\site-packages\sqlalchemy\engine\default.py", line 508, in connect
    return self.dbapi.connect(*cargs, **cparams)
  File "src\pymssql\_pymssql.pyx", line 652, in pymssql._pymssql.connect
sqlalchemy.exc.OperationalError: (pymssql._pymssql.OperationalError) (18456, b'DB-Lib error message 20018, severity 14:\nGeneral SQL Server error: Check messages from the SQL Server\nDB-Lib error message 20002, severity 9:\nAdaptive Server connection failed (172.24.32.210)\nDB-Lib error message 20002, severity 9:\nAdaptive Server connection failed (172.24.32.210)\n')
(Background on this error at: http://sqlalche.me/e/13/e3q8)
2023-04-28 15:04:51,364 Exception on /lookup [POST]
Traceback (most recent call last):
  File "src\pymssql\_pymssql.pyx", line 646, in pymssql._pymssql.connect
  File "src\pymssql\_mssql.pyx", line 2108, in pymssql._mssql.connect
  File "src\pymssql\_mssql.pyx", line 700, in pymssql._mssql.MSSQLConnection.__init__
  File "src\pymssql\_mssql.pyx", line 1817, in pymssql._mssql.maybe_raise_MSSQLDatabaseException
  File "src\pymssql\_mssql.pyx", line 1834, in pymssql._mssql.raise_MSSQLDatabaseException
pymssql._mssql.MSSQLDatabaseException: (18456, b'DB-Lib error message 20018, severity 14:\nGeneral SQL Server error: Check messages from the SQL Server\nDB-Lib error message 20002, severity 9:\nAdaptive Server connection failed (172.24.32.210)\nDB-Lib error message 20002, severity 9:\nAdaptive Server connection failed (172.24.32.210)\n')

During handling of the above exception, another exception occurred:

Traceback (most recent call last):
  File "D:\CDL\CDL-Barcode-Checker\cdl_barcode_checker\lib\site-packages\sqlalchemy\engine\base.py", line 2336, in _wrap_pool_connect
    return fn()
  File "D:\CDL\CDL-Barcode-Checker\cdl_barcode_checker\lib\site-packages\sqlalchemy\pool\base.py", line 364, in connect
    return _ConnectionFairy._checkout(self)
  File "D:\CDL\CDL-Barcode-Checker\cdl_barcode_checker\lib\site-packages\sqlalchemy\pool\base.py", line 778, in _checkout
    fairy = _ConnectionRecord.checkout(pool)
  File "D:\CDL\CDL-Barcode-Checker\cdl_barcode_checker\lib\site-packages\sqlalchemy\pool\base.py", line 499, in checkout
    with util.safe_reraise():
  File "D:\CDL\CDL-Barcode-Checker\cdl_barcode_checker\lib\site-packages\sqlalchemy\util\langhelpers.py", line 68, in __exit__
    compat.raise_(
  File "D:\CDL\CDL-Barcode-Checker\cdl_barcode_checker\lib\site-packages\sqlalchemy\util\compat.py", line 182, in raise_
    raise exception
  File "D:\CDL\CDL-Barcode-Checker\cdl_barcode_checker\lib\site-packages\sqlalchemy\pool\base.py", line 497, in checkout
    dbapi_connection = rec.get_connection()
  File "D:\CDL\CDL-Barcode-Checker\cdl_barcode_checker\lib\site-packages\sqlalchemy\pool\base.py", line 610, in get_connection
    self.__connect()
  File "D:\CDL\CDL-Barcode-Checker\cdl_barcode_checker\lib\site-packages\sqlalchemy\pool\base.py", line 660, in __connect
    with util.safe_reraise():
  File "D:\CDL\CDL-Barcode-Checker\cdl_barcode_checker\lib\site-packages\sqlalchemy\util\langhelpers.py", line 68, in __exit__
    compat.raise_(
  File "D:\CDL\CDL-Barcode-Checker\cdl_barcode_checker\lib\site-packages\sqlalchemy\util\compat.py", line 182, in raise_
    raise exception
  File "D:\CDL\CDL-Barcode-Checker\cdl_barcode_checker\lib\site-packages\sqlalchemy\pool\base.py", line 656, in __connect
    connection = pool._invoke_creator(self)
  File "D:\CDL\CDL-Barcode-Checker\cdl_barcode_checker\lib\site-packages\sqlalchemy\engine\strategies.py", line 114, in connect
    return dialect.connect(*cargs, **cparams)
  File "D:\CDL\CDL-Barcode-Checker\cdl_barcode_checker\lib\site-packages\sqlalchemy\engine\default.py", line 508, in connect
    return self.dbapi.connect(*cargs, **cparams)
  File "src\pymssql\_pymssql.pyx", line 652, in pymssql._pymssql.connect
pymssql._pymssql.OperationalError: (18456, b'DB-Lib error message 20018, severity 14:\nGeneral SQL Server error: Check messages from the SQL Server\nDB-Lib error message 20002, severity 9:\nAdaptive Server connection failed (172.24.32.210)\nDB-Lib error message 20002, severity 9:\nAdaptive Server connection failed (172.24.32.210)\n')

The above exception was the direct cause of the following exception:

Traceback (most recent call last):
  File "D:\CDL\CDL-Barcode-Checker\cdl_barcode_checker\lib\site-packages\flask\app.py", line 2525, in wsgi_app
    response = self.full_dispatch_request()
  File "D:\CDL\CDL-Barcode-Checker\cdl_barcode_checker\lib\site-packages\flask\app.py", line 1822, in full_dispatch_request
    rv = self.handle_user_exception(e)
  File "D:\CDL\CDL-Barcode-Checker\cdl_barcode_checker\lib\site-packages\flask\app.py", line 1820, in full_dispatch_request
    rv = self.dispatch_request()
  File "D:\CDL\CDL-Barcode-Checker\cdl_barcode_checker\lib\site-packages\flask\app.py", line 1796, in dispatch_request
    return self.ensure_sync(self.view_functions[rule.endpoint])(**view_args)
  File "D:\CDL\CDL-Barcode-Checker\.\barcode_checker\main\routes.py", line 48, in lookup_rte
    records = [r._asdict() for r in dbquery.all()]
  File "D:\CDL\CDL-Barcode-Checker\cdl_barcode_checker\lib\site-packages\sqlalchemy\orm\query.py", line 3373, in all
    return list(self)
  File "D:\CDL\CDL-Barcode-Checker\cdl_barcode_checker\lib\site-packages\sqlalchemy\orm\query.py", line 3535, in __iter__
    return self._execute_and_instances(context)
  File "D:\CDL\CDL-Barcode-Checker\cdl_barcode_checker\lib\site-packages\sqlalchemy\orm\query.py", line 3556, in _execute_and_instances
    conn = self._get_bind_args(
  File "D:\CDL\CDL-Barcode-Checker\cdl_barcode_checker\lib\site-packages\sqlalchemy\orm\query.py", line 3571, in _get_bind_args
    return fn(
  File "D:\CDL\CDL-Barcode-Checker\cdl_barcode_checker\lib\site-packages\sqlalchemy\orm\query.py", line 3550, in _connection_from_session
    conn = self.session.connection(**kw)
  File "D:\CDL\CDL-Barcode-Checker\cdl_barcode_checker\lib\site-packages\sqlalchemy\orm\session.py", line 1142, in connection
    return self._connection_for_bind(
  File "D:\CDL\CDL-Barcode-Checker\cdl_barcode_checker\lib\site-packages\sqlalchemy\orm\session.py", line 1150, in _connection_for_bind
    return self.transaction._connection_for_bind(
  File "D:\CDL\CDL-Barcode-Checker\cdl_barcode_checker\lib\site-packages\sqlalchemy\orm\session.py", line 433, in _connection_for_bind
    conn = bind._contextual_connect()
  File "D:\CDL\CDL-Barcode-Checker\cdl_barcode_checker\lib\site-packages\sqlalchemy\engine\base.py", line 2302, in _contextual_connect
    self._wrap_pool_connect(self.pool.connect, None),
  File "D:\CDL\CDL-Barcode-Checker\cdl_barcode_checker\lib\site-packages\sqlalchemy\engine\base.py", line 2339, in _wrap_pool_connect
    Connection._handle_dbapi_exception_noconnection(
  File "D:\CDL\CDL-Barcode-Checker\cdl_barcode_checker\lib\site-packages\sqlalchemy\engine\base.py", line 1583, in _handle_dbapi_exception_noconnection
    util.raise_(
  File "D:\CDL\CDL-Barcode-Checker\cdl_barcode_checker\lib\site-packages\sqlalchemy\util\compat.py", line 182, in raise_
    raise exception
  File "D:\CDL\CDL-Barcode-Checker\cdl_barcode_checker\lib\site-packages\sqlalchemy\engine\base.py", line 2336, in _wrap_pool_connect
    return fn()
  File "D:\CDL\CDL-Barcode-Checker\cdl_barcode_checker\lib\site-packages\sqlalchemy\pool\base.py", line 364, in connect
    return _ConnectionFairy._checkout(self)
  File "D:\CDL\CDL-Barcode-Checker\cdl_barcode_checker\lib\site-packages\sqlalchemy\pool\base.py", line 778, in _checkout
    fairy = _ConnectionRecord.checkout(pool)
  File "D:\CDL\CDL-Barcode-Checker\cdl_barcode_checker\lib\site-packages\sqlalchemy\pool\base.py", line 499, in checkout
    with util.safe_reraise():
  File "D:\CDL\CDL-Barcode-Checker\cdl_barcode_checker\lib\site-packages\sqlalchemy\util\langhelpers.py", line 68, in __exit__
    compat.raise_(
  File "D:\CDL\CDL-Barcode-Checker\cdl_barcode_checker\lib\site-packages\sqlalchemy\util\compat.py", line 182, in raise_
    raise exception
  File "D:\CDL\CDL-Barcode-Checker\cdl_barcode_checker\lib\site-packages\sqlalchemy\pool\base.py", line 497, in checkout
    dbapi_connection = rec.get_connection()
  File "D:\CDL\CDL-Barcode-Checker\cdl_barcode_checker\lib\site-packages\sqlalchemy\pool\base.py", line 610, in get_connection
    self.__connect()
  File "D:\CDL\CDL-Barcode-Checker\cdl_barcode_checker\lib\site-packages\sqlalchemy\pool\base.py", line 660, in __connect
    with util.safe_reraise():
  File "D:\CDL\CDL-Barcode-Checker\cdl_barcode_checker\lib\site-packages\sqlalchemy\util\langhelpers.py", line 68, in __exit__
    compat.raise_(
  File "D:\CDL\CDL-Barcode-Checker\cdl_barcode_checker\lib\site-packages\sqlalchemy\util\compat.py", line 182, in raise_
    raise exception
  File "D:\CDL\CDL-Barcode-Checker\cdl_barcode_checker\lib\site-packages\sqlalchemy\pool\base.py", line 656, in __connect
    connection = pool._invoke_creator(self)
  File "D:\CDL\CDL-Barcode-Checker\cdl_barcode_checker\lib\site-packages\sqlalchemy\engine\strategies.py", line 114, in connect
    return dialect.connect(*cargs, **cparams)
  File "D:\CDL\CDL-Barcode-Checker\cdl_barcode_checker\lib\site-packages\sqlalchemy\engine\default.py", line 508, in connect
    return self.dbapi.connect(*cargs, **cparams)
  File "src\pymssql\_pymssql.pyx", line 652, in pymssql._pymssql.connect
sqlalchemy.exc.OperationalError: (pymssql._pymssql.OperationalError) (18456, b'DB-Lib error message 20018, severity 14:\nGeneral SQL Server error: Check messages from the SQL Server\nDB-Lib error message 20002, severity 9:\nAdaptive Server connection failed (172.24.32.210)\nDB-Lib error message 20002, severity 9:\nAdaptive Server connection failed (172.24.32.210)\n')
(Background on this error at: http://sqlalche.me/e/13/e3q8)
2023-04-28 15:04:56,099 Exception on /lookup [POST]
Traceback (most recent call last):
  File "src\pymssql\_pymssql.pyx", line 646, in pymssql._pymssql.connect
  File "src\pymssql\_mssql.pyx", line 2108, in pymssql._mssql.connect
  File "src\pymssql\_mssql.pyx", line 700, in pymssql._mssql.MSSQLConnection.__init__
  File "src\pymssql\_mssql.pyx", line 1817, in pymssql._mssql.maybe_raise_MSSQLDatabaseException
  File "src\pymssql\_mssql.pyx", line 1834, in pymssql._mssql.raise_MSSQLDatabaseException
pymssql._mssql.MSSQLDatabaseException: (18456, b"Login failed for user 'CDL_VPOD'.DB-Lib error message 20018, severity 14:\nGeneral SQL Server error: Check messages from the SQL Server\nDB-Lib error message 20002, severity 9:\nAdaptive Server connection failed (172.24.32.210)\nDB-Lib error message 20002, severity 9:\nAdaptive Server connection failed (172.24.32.210)\n")

During handling of the above exception, another exception occurred:

Traceback (most recent call last):
  File "D:\CDL\CDL-Barcode-Checker\cdl_barcode_checker\lib\site-packages\sqlalchemy\engine\base.py", line 2336, in _wrap_pool_connect
    return fn()
  File "D:\CDL\CDL-Barcode-Checker\cdl_barcode_checker\lib\site-packages\sqlalchemy\pool\base.py", line 364, in connect
    return _ConnectionFairy._checkout(self)
  File "D:\CDL\CDL-Barcode-Checker\cdl_barcode_checker\lib\site-packages\sqlalchemy\pool\base.py", line 778, in _checkout
    fairy = _ConnectionRecord.checkout(pool)
  File "D:\CDL\CDL-Barcode-Checker\cdl_barcode_checker\lib\site-packages\sqlalchemy\pool\base.py", line 495, in checkout
    rec = pool._do_get()
  File "D:\CDL\CDL-Barcode-Checker\cdl_barcode_checker\lib\site-packages\sqlalchemy\pool\impl.py", line 139, in _do_get
    with util.safe_reraise():
  File "D:\CDL\CDL-Barcode-Checker\cdl_barcode_checker\lib\site-packages\sqlalchemy\util\langhelpers.py", line 68, in __exit__
    compat.raise_(
  File "D:\CDL\CDL-Barcode-Checker\cdl_barcode_checker\lib\site-packages\sqlalchemy\util\compat.py", line 182, in raise_
    raise exception
  File "D:\CDL\CDL-Barcode-Checker\cdl_barcode_checker\lib\site-packages\sqlalchemy\pool\impl.py", line 137, in _do_get
    return self._create_connection()
  File "D:\CDL\CDL-Barcode-Checker\cdl_barcode_checker\lib\site-packages\sqlalchemy\pool\base.py", line 309, in _create_connection
    return _ConnectionRecord(self)
  File "D:\CDL\CDL-Barcode-Checker\cdl_barcode_checker\lib\site-packages\sqlalchemy\pool\base.py", line 440, in __init__
    self.__connect(first_connect_check=True)
  File "D:\CDL\CDL-Barcode-Checker\cdl_barcode_checker\lib\site-packages\sqlalchemy\pool\base.py", line 660, in __connect
    with util.safe_reraise():
  File "D:\CDL\CDL-Barcode-Checker\cdl_barcode_checker\lib\site-packages\sqlalchemy\util\langhelpers.py", line 68, in __exit__
    compat.raise_(
  File "D:\CDL\CDL-Barcode-Checker\cdl_barcode_checker\lib\site-packages\sqlalchemy\util\compat.py", line 182, in raise_
    raise exception
  File "D:\CDL\CDL-Barcode-Checker\cdl_barcode_checker\lib\site-packages\sqlalchemy\pool\base.py", line 656, in __connect
    connection = pool._invoke_creator(self)
  File "D:\CDL\CDL-Barcode-Checker\cdl_barcode_checker\lib\site-packages\sqlalchemy\engine\strategies.py", line 114, in connect
    return dialect.connect(*cargs, **cparams)
  File "D:\CDL\CDL-Barcode-Checker\cdl_barcode_checker\lib\site-packages\sqlalchemy\engine\default.py", line 508, in connect
    return self.dbapi.connect(*cargs, **cparams)
  File "src\pymssql\_pymssql.pyx", line 652, in pymssql._pymssql.connect
pymssql._pymssql.OperationalError: (18456, b"Login failed for user 'CDL_VPOD'.DB-Lib error message 20018, severity 14:\nGeneral SQL Server error: Check messages from the SQL Server\nDB-Lib error message 20002, severity 9:\nAdaptive Server connection failed (172.24.32.210)\nDB-Lib error message 20002, severity 9:\nAdaptive Server connection failed (172.24.32.210)\n")

The above exception was the direct cause of the following exception:

Traceback (most recent call last):
  File "D:\CDL\CDL-Barcode-Checker\cdl_barcode_checker\lib\site-packages\flask\app.py", line 2525, in wsgi_app
    response = self.full_dispatch_request()
  File "D:\CDL\CDL-Barcode-Checker\cdl_barcode_checker\lib\site-packages\flask\app.py", line 1822, in full_dispatch_request
    rv = self.handle_user_exception(e)
  File "D:\CDL\CDL-Barcode-Checker\cdl_barcode_checker\lib\site-packages\flask\app.py", line 1820, in full_dispatch_request
    rv = self.dispatch_request()
  File "D:\CDL\CDL-Barcode-Checker\cdl_barcode_checker\lib\site-packages\flask\app.py", line 1796, in dispatch_request
    return self.ensure_sync(self.view_functions[rule.endpoint])(**view_args)
  File "D:\CDL\CDL-Barcode-Checker\.\barcode_checker\main\routes.py", line 48, in lookup_rte
    records = [r._asdict() for r in dbquery.all()]
  File "D:\CDL\CDL-Barcode-Checker\cdl_barcode_checker\lib\site-packages\sqlalchemy\orm\query.py", line 3373, in all
    return list(self)
  File "D:\CDL\CDL-Barcode-Checker\cdl_barcode_checker\lib\site-packages\sqlalchemy\orm\query.py", line 3535, in __iter__
    return self._execute_and_instances(context)
  File "D:\CDL\CDL-Barcode-Checker\cdl_barcode_checker\lib\site-packages\sqlalchemy\orm\query.py", line 3556, in _execute_and_instances
    conn = self._get_bind_args(
  File "D:\CDL\CDL-Barcode-Checker\cdl_barcode_checker\lib\site-packages\sqlalchemy\orm\query.py", line 3571, in _get_bind_args
    return fn(
  File "D:\CDL\CDL-Barcode-Checker\cdl_barcode_checker\lib\site-packages\sqlalchemy\orm\query.py", line 3550, in _connection_from_session
    conn = self.session.connection(**kw)
  File "D:\CDL\CDL-Barcode-Checker\cdl_barcode_checker\lib\site-packages\sqlalchemy\orm\session.py", line 1142, in connection
    return self._connection_for_bind(
  File "D:\CDL\CDL-Barcode-Checker\cdl_barcode_checker\lib\site-packages\sqlalchemy\orm\session.py", line 1150, in _connection_for_bind
    return self.transaction._connection_for_bind(
  File "D:\CDL\CDL-Barcode-Checker\cdl_barcode_checker\lib\site-packages\sqlalchemy\orm\session.py", line 433, in _connection_for_bind
    conn = bind._contextual_connect()
  File "D:\CDL\CDL-Barcode-Checker\cdl_barcode_checker\lib\site-packages\sqlalchemy\engine\base.py", line 2302, in _contextual_connect
    self._wrap_pool_connect(self.pool.connect, None),
  File "D:\CDL\CDL-Barcode-Checker\cdl_barcode_checker\lib\site-packages\sqlalchemy\engine\base.py", line 2339, in _wrap_pool_connect
    Connection._handle_dbapi_exception_noconnection(
  File "D:\CDL\CDL-Barcode-Checker\cdl_barcode_checker\lib\site-packages\sqlalchemy\engine\base.py", line 1583, in _handle_dbapi_exception_noconnection
    util.raise_(
  File "D:\CDL\CDL-Barcode-Checker\cdl_barcode_checker\lib\site-packages\sqlalchemy\util\compat.py", line 182, in raise_
    raise exception
  File "D:\CDL\CDL-Barcode-Checker\cdl_barcode_checker\lib\site-packages\sqlalchemy\engine\base.py", line 2336, in _wrap_pool_connect
    return fn()
  File "D:\CDL\CDL-Barcode-Checker\cdl_barcode_checker\lib\site-packages\sqlalchemy\pool\base.py", line 364, in connect
    return _ConnectionFairy._checkout(self)
  File "D:\CDL\CDL-Barcode-Checker\cdl_barcode_checker\lib\site-packages\sqlalchemy\pool\base.py", line 778, in _checkout
    fairy = _ConnectionRecord.checkout(pool)
  File "D:\CDL\CDL-Barcode-Checker\cdl_barcode_checker\lib\site-packages\sqlalchemy\pool\base.py", line 495, in checkout
    rec = pool._do_get()
  File "D:\CDL\CDL-Barcode-Checker\cdl_barcode_checker\lib\site-packages\sqlalchemy\pool\impl.py", line 139, in _do_get
    with util.safe_reraise():
  File "D:\CDL\CDL-Barcode-Checker\cdl_barcode_checker\lib\site-packages\sqlalchemy\util\langhelpers.py", line 68, in __exit__
    compat.raise_(
  File "D:\CDL\CDL-Barcode-Checker\cdl_barcode_checker\lib\site-packages\sqlalchemy\util\compat.py", line 182, in raise_
    raise exception
  File "D:\CDL\CDL-Barcode-Checker\cdl_barcode_checker\lib\site-packages\sqlalchemy\pool\impl.py", line 137, in _do_get
    return self._create_connection()
  File "D:\CDL\CDL-Barcode-Checker\cdl_barcode_checker\lib\site-packages\sqlalchemy\pool\base.py", line 309, in _create_connection
    return _ConnectionRecord(self)
  File "D:\CDL\CDL-Barcode-Checker\cdl_barcode_checker\lib\site-packages\sqlalchemy\pool\base.py", line 440, in __init__
    self.__connect(first_connect_check=True)
  File "D:\CDL\CDL-Barcode-Checker\cdl_barcode_checker\lib\site-packages\sqlalchemy\pool\base.py", line 660, in __connect
    with util.safe_reraise():
  File "D:\CDL\CDL-Barcode-Checker\cdl_barcode_checker\lib\site-packages\sqlalchemy\util\langhelpers.py", line 68, in __exit__
    compat.raise_(
  File "D:\CDL\CDL-Barcode-Checker\cdl_barcode_checker\lib\site-packages\sqlalchemy\util\compat.py", line 182, in raise_
    raise exception
  File "D:\CDL\CDL-Barcode-Checker\cdl_barcode_checker\lib\site-packages\sqlalchemy\pool\base.py", line 656, in __connect
    connection = pool._invoke_creator(self)
  File "D:\CDL\CDL-Barcode-Checker\cdl_barcode_checker\lib\site-packages\sqlalchemy\engine\strategies.py", line 114, in connect
    return dialect.connect(*cargs, **cparams)
  File "D:\CDL\CDL-Barcode-Checker\cdl_barcode_checker\lib\site-packages\sqlalchemy\engine\default.py", line 508, in connect
    return self.dbapi.connect(*cargs, **cparams)
  File "src\pymssql\_pymssql.pyx", line 652, in pymssql._pymssql.connect
sqlalchemy.exc.OperationalError: (pymssql._pymssql.OperationalError) (18456, b"Login failed for user 'CDL_VPOD'.DB-Lib error message 20018, severity 14:\nGeneral SQL Server error: Check messages from the SQL Server\nDB-Lib error message 20002, severity 9:\nAdaptive Server connection failed (172.24.32.210)\nDB-Lib error message 20002, severity 9:\nAdaptive Server connection failed (172.24.32.210)\n")
(Background on this error at: http://sqlalche.me/e/13/e3q8)
2023-04-28 15:04:56,521 Exception on /lookup [POST]
Traceback (most recent call last):
  File "src\pymssql\_pymssql.pyx", line 646, in pymssql._pymssql.connect
  File "src\pymssql\_mssql.pyx", line 2108, in pymssql._mssql.connect
  File "src\pymssql\_mssql.pyx", line 700, in pymssql._mssql.MSSQLConnection.__init__
  File "src\pymssql\_mssql.pyx", line 1817, in pymssql._mssql.maybe_raise_MSSQLDatabaseException
  File "src\pymssql\_mssql.pyx", line 1834, in pymssql._mssql.raise_MSSQLDatabaseException
pymssql._mssql.MSSQLDatabaseException: (18456, b'DB-Lib error message 20018, severity 14:\nGeneral SQL Server error: Check messages from the SQL Server\nDB-Lib error message 20002, severity 9:\nAdaptive Server connection failed (172.24.32.210)\nDB-Lib error message 20002, severity 9:\nAdaptive Server connection failed (172.24.32.210)\n')

During handling of the above exception, another exception occurred:

Traceback (most recent call last):
  File "D:\CDL\CDL-Barcode-Checker\cdl_barcode_checker\lib\site-packages\sqlalchemy\engine\base.py", line 2336, in _wrap_pool_connect
    return fn()
  File "D:\CDL\CDL-Barcode-Checker\cdl_barcode_checker\lib\site-packages\sqlalchemy\pool\base.py", line 364, in connect
    return _ConnectionFairy._checkout(self)
  File "D:\CDL\CDL-Barcode-Checker\cdl_barcode_checker\lib\site-packages\sqlalchemy\pool\base.py", line 778, in _checkout
    fairy = _ConnectionRecord.checkout(pool)
  File "D:\CDL\CDL-Barcode-Checker\cdl_barcode_checker\lib\site-packages\sqlalchemy\pool\base.py", line 495, in checkout
    rec = pool._do_get()
  File "D:\CDL\CDL-Barcode-Checker\cdl_barcode_checker\lib\site-packages\sqlalchemy\pool\impl.py", line 139, in _do_get
    with util.safe_reraise():
  File "D:\CDL\CDL-Barcode-Checker\cdl_barcode_checker\lib\site-packages\sqlalchemy\util\langhelpers.py", line 68, in __exit__
    compat.raise_(
  File "D:\CDL\CDL-Barcode-Checker\cdl_barcode_checker\lib\site-packages\sqlalchemy\util\compat.py", line 182, in raise_
    raise exception
  File "D:\CDL\CDL-Barcode-Checker\cdl_barcode_checker\lib\site-packages\sqlalchemy\pool\impl.py", line 137, in _do_get
    return self._create_connection()
  File "D:\CDL\CDL-Barcode-Checker\cdl_barcode_checker\lib\site-packages\sqlalchemy\pool\base.py", line 309, in _create_connection
    return _ConnectionRecord(self)
  File "D:\CDL\CDL-Barcode-Checker\cdl_barcode_checker\lib\site-packages\sqlalchemy\pool\base.py", line 440, in __init__
    self.__connect(first_connect_check=True)
  File "D:\CDL\CDL-Barcode-Checker\cdl_barcode_checker\lib\site-packages\sqlalchemy\pool\base.py", line 660, in __connect
    with util.safe_reraise():
  File "D:\CDL\CDL-Barcode-Checker\cdl_barcode_checker\lib\site-packages\sqlalchemy\util\langhelpers.py", line 68, in __exit__
    compat.raise_(
  File "D:\CDL\CDL-Barcode-Checker\cdl_barcode_checker\lib\site-packages\sqlalchemy\util\compat.py", line 182, in raise_
    raise exception
  File "D:\CDL\CDL-Barcode-Checker\cdl_barcode_checker\lib\site-packages\sqlalchemy\pool\base.py", line 656, in __connect
    connection = pool._invoke_creator(self)
  File "D:\CDL\CDL-Barcode-Checker\cdl_barcode_checker\lib\site-packages\sqlalchemy\engine\strategies.py", line 114, in connect
    return dialect.connect(*cargs, **cparams)
  File "D:\CDL\CDL-Barcode-Checker\cdl_barcode_checker\lib\site-packages\sqlalchemy\engine\default.py", line 508, in connect
    return self.dbapi.connect(*cargs, **cparams)
  File "src\pymssql\_pymssql.pyx", line 652, in pymssql._pymssql.connect
pymssql._pymssql.OperationalError: (18456, b'DB-Lib error message 20018, severity 14:\nGeneral SQL Server error: Check messages from the SQL Server\nDB-Lib error message 20002, severity 9:\nAdaptive Server connection failed (172.24.32.210)\nDB-Lib error message 20002, severity 9:\nAdaptive Server connection failed (172.24.32.210)\n')

The above exception was the direct cause of the following exception:

Traceback (most recent call last):
  File "D:\CDL\CDL-Barcode-Checker\cdl_barcode_checker\lib\site-packages\flask\app.py", line 2525, in wsgi_app
    response = self.full_dispatch_request()
  File "D:\CDL\CDL-Barcode-Checker\cdl_barcode_checker\lib\site-packages\flask\app.py", line 1822, in full_dispatch_request
    rv = self.handle_user_exception(e)
  File "D:\CDL\CDL-Barcode-Checker\cdl_barcode_checker\lib\site-packages\flask\app.py", line 1820, in full_dispatch_request
    rv = self.dispatch_request()
  File "D:\CDL\CDL-Barcode-Checker\cdl_barcode_checker\lib\site-packages\flask\app.py", line 1796, in dispatch_request
    return self.ensure_sync(self.view_functions[rule.endpoint])(**view_args)
  File "D:\CDL\CDL-Barcode-Checker\.\barcode_checker\main\routes.py", line 48, in lookup_rte
    records = [r._asdict() for r in dbquery.all()]
  File "D:\CDL\CDL-Barcode-Checker\cdl_barcode_checker\lib\site-packages\sqlalchemy\orm\query.py", line 3373, in all
    return list(self)
  File "D:\CDL\CDL-Barcode-Checker\cdl_barcode_checker\lib\site-packages\sqlalchemy\orm\query.py", line 3535, in __iter__
    return self._execute_and_instances(context)
  File "D:\CDL\CDL-Barcode-Checker\cdl_barcode_checker\lib\site-packages\sqlalchemy\orm\query.py", line 3556, in _execute_and_instances
    conn = self._get_bind_args(
  File "D:\CDL\CDL-Barcode-Checker\cdl_barcode_checker\lib\site-packages\sqlalchemy\orm\query.py", line 3571, in _get_bind_args
    return fn(
  File "D:\CDL\CDL-Barcode-Checker\cdl_barcode_checker\lib\site-packages\sqlalchemy\orm\query.py", line 3550, in _connection_from_session
    conn = self.session.connection(**kw)
  File "D:\CDL\CDL-Barcode-Checker\cdl_barcode_checker\lib\site-packages\sqlalchemy\orm\session.py", line 1142, in connection
    return self._connection_for_bind(
  File "D:\CDL\CDL-Barcode-Checker\cdl_barcode_checker\lib\site-packages\sqlalchemy\orm\session.py", line 1150, in _connection_for_bind
    return self.transaction._connection_for_bind(
  File "D:\CDL\CDL-Barcode-Checker\cdl_barcode_checker\lib\site-packages\sqlalchemy\orm\session.py", line 433, in _connection_for_bind
    conn = bind._contextual_connect()
  File "D:\CDL\CDL-Barcode-Checker\cdl_barcode_checker\lib\site-packages\sqlalchemy\engine\base.py", line 2302, in _contextual_connect
    self._wrap_pool_connect(self.pool.connect, None),
  File "D:\CDL\CDL-Barcode-Checker\cdl_barcode_checker\lib\site-packages\sqlalchemy\engine\base.py", line 2339, in _wrap_pool_connect
    Connection._handle_dbapi_exception_noconnection(
  File "D:\CDL\CDL-Barcode-Checker\cdl_barcode_checker\lib\site-packages\sqlalchemy\engine\base.py", line 1583, in _handle_dbapi_exception_noconnection
    util.raise_(
  File "D:\CDL\CDL-Barcode-Checker\cdl_barcode_checker\lib\site-packages\sqlalchemy\util\compat.py", line 182, in raise_
    raise exception
  File "D:\CDL\CDL-Barcode-Checker\cdl_barcode_checker\lib\site-packages\sqlalchemy\engine\base.py", line 2336, in _wrap_pool_connect
    return fn()
  File "D:\CDL\CDL-Barcode-Checker\cdl_barcode_checker\lib\site-packages\sqlalchemy\pool\base.py", line 364, in connect
    return _ConnectionFairy._checkout(self)
  File "D:\CDL\CDL-Barcode-Checker\cdl_barcode_checker\lib\site-packages\sqlalchemy\pool\base.py", line 778, in _checkout
    fairy = _ConnectionRecord.checkout(pool)
  File "D:\CDL\CDL-Barcode-Checker\cdl_barcode_checker\lib\site-packages\sqlalchemy\pool\base.py", line 495, in checkout
    rec = pool._do_get()
  File "D:\CDL\CDL-Barcode-Checker\cdl_barcode_checker\lib\site-packages\sqlalchemy\pool\impl.py", line 139, in _do_get
    with util.safe_reraise():
  File "D:\CDL\CDL-Barcode-Checker\cdl_barcode_checker\lib\site-packages\sqlalchemy\util\langhelpers.py", line 68, in __exit__
    compat.raise_(
  File "D:\CDL\CDL-Barcode-Checker\cdl_barcode_checker\lib\site-packages\sqlalchemy\util\compat.py", line 182, in raise_
    raise exception
  File "D:\CDL\CDL-Barcode-Checker\cdl_barcode_checker\lib\site-packages\sqlalchemy\pool\impl.py", line 137, in _do_get
    return self._create_connection()
  File "D:\CDL\CDL-Barcode-Checker\cdl_barcode_checker\lib\site-packages\sqlalchemy\pool\base.py", line 309, in _create_connection
    return _ConnectionRecord(self)
  File "D:\CDL\CDL-Barcode-Checker\cdl_barcode_checker\lib\site-packages\sqlalchemy\pool\base.py", line 440, in __init__
    self.__connect(first_connect_check=True)
  File "D:\CDL\CDL-Barcode-Checker\cdl_barcode_checker\lib\site-packages\sqlalchemy\pool\base.py", line 660, in __connect
    with util.safe_reraise():
  File "D:\CDL\CDL-Barcode-Checker\cdl_barcode_checker\lib\site-packages\sqlalchemy\util\langhelpers.py", line 68, in __exit__
    compat.raise_(
  File "D:\CDL\CDL-Barcode-Checker\cdl_barcode_checker\lib\site-packages\sqlalchemy\util\compat.py", line 182, in raise_
    raise exception
  File "D:\CDL\CDL-Barcode-Checker\cdl_barcode_checker\lib\site-packages\sqlalchemy\pool\base.py", line 656, in __connect
    connection = pool._invoke_creator(self)
  File "D:\CDL\CDL-Barcode-Checker\cdl_barcode_checker\lib\site-packages\sqlalchemy\engine\strategies.py", line 114, in connect
    return dialect.connect(*cargs, **cparams)
  File "D:\CDL\CDL-Barcode-Checker\cdl_barcode_checker\lib\site-packages\sqlalchemy\engine\default.py", line 508, in connect
    return self.dbapi.connect(*cargs, **cparams)
  File "src\pymssql\_pymssql.pyx", line 652, in pymssql._pymssql.connect
sqlalchemy.exc.OperationalError: (pymssql._pymssql.OperationalError) (18456, b'DB-Lib error message 20018, severity 14:\nGeneral SQL Server error: Check messages from the SQL Server\nDB-Lib error message 20002, severity 9:\nAdaptive Server connection failed (172.24.32.210)\nDB-Lib error message 20002, severity 9:\nAdaptive Server connection failed (172.24.32.210)\n')
(Background on this error at: http://sqlalche.me/e/13/e3q8)
2023-04-28 15:05:01,210 Exception on /lookup [POST]
Traceback (most recent call last):
  File "src\pymssql\_pymssql.pyx", line 646, in pymssql._pymssql.connect
  File "src\pymssql\_mssql.pyx", line 2108, in pymssql._mssql.connect
  File "src\pymssql\_mssql.pyx", line 700, in pymssql._mssql.MSSQLConnection.__init__
  File "src\pymssql\_mssql.pyx", line 1817, in pymssql._mssql.maybe_raise_MSSQLDatabaseException
  File "src\pymssql\_mssql.pyx", line 1834, in pymssql._mssql.raise_MSSQLDatabaseException
pymssql._mssql.MSSQLDatabaseException: (18456, b'DB-Lib error message 20018, severity 14:\nGeneral SQL Server error: Check messages from the SQL Server\nDB-Lib error message 20002, severity 9:\nAdaptive Server connection failed (172.24.32.210)\nDB-Lib error message 20002, severity 9:\nAdaptive Server connection failed (172.24.32.210)\n')

During handling of the above exception, another exception occurred:

Traceback (most recent call last):
  File "D:\CDL\CDL-Barcode-Checker\cdl_barcode_checker\lib\site-packages\sqlalchemy\engine\base.py", line 2336, in _wrap_pool_connect
    return fn()
  File "D:\CDL\CDL-Barcode-Checker\cdl_barcode_checker\lib\site-packages\sqlalchemy\pool\base.py", line 364, in connect
    return _ConnectionFairy._checkout(self)
  File "D:\CDL\CDL-Barcode-Checker\cdl_barcode_checker\lib\site-packages\sqlalchemy\pool\base.py", line 778, in _checkout
    fairy = _ConnectionRecord.checkout(pool)
  File "D:\CDL\CDL-Barcode-Checker\cdl_barcode_checker\lib\site-packages\sqlalchemy\pool\base.py", line 499, in checkout
    with util.safe_reraise():
  File "D:\CDL\CDL-Barcode-Checker\cdl_barcode_checker\lib\site-packages\sqlalchemy\util\langhelpers.py", line 68, in __exit__
    compat.raise_(
  File "D:\CDL\CDL-Barcode-Checker\cdl_barcode_checker\lib\site-packages\sqlalchemy\util\compat.py", line 182, in raise_
    raise exception
  File "D:\CDL\CDL-Barcode-Checker\cdl_barcode_checker\lib\site-packages\sqlalchemy\pool\base.py", line 497, in checkout
    dbapi_connection = rec.get_connection()
  File "D:\CDL\CDL-Barcode-Checker\cdl_barcode_checker\lib\site-packages\sqlalchemy\pool\base.py", line 610, in get_connection
    self.__connect()
  File "D:\CDL\CDL-Barcode-Checker\cdl_barcode_checker\lib\site-packages\sqlalchemy\pool\base.py", line 660, in __connect
    with util.safe_reraise():
  File "D:\CDL\CDL-Barcode-Checker\cdl_barcode_checker\lib\site-packages\sqlalchemy\util\langhelpers.py", line 68, in __exit__
    compat.raise_(
  File "D:\CDL\CDL-Barcode-Checker\cdl_barcode_checker\lib\site-packages\sqlalchemy\util\compat.py", line 182, in raise_
    raise exception
  File "D:\CDL\CDL-Barcode-Checker\cdl_barcode_checker\lib\site-packages\sqlalchemy\pool\base.py", line 656, in __connect
    connection = pool._invoke_creator(self)
  File "D:\CDL\CDL-Barcode-Checker\cdl_barcode_checker\lib\site-packages\sqlalchemy\engine\strategies.py", line 114, in connect
    return dialect.connect(*cargs, **cparams)
  File "D:\CDL\CDL-Barcode-Checker\cdl_barcode_checker\lib\site-packages\sqlalchemy\engine\default.py", line 508, in connect
    return self.dbapi.connect(*cargs, **cparams)
  File "src\pymssql\_pymssql.pyx", line 652, in pymssql._pymssql.connect
pymssql._pymssql.OperationalError: (18456, b'DB-Lib error message 20018, severity 14:\nGeneral SQL Server error: Check messages from the SQL Server\nDB-Lib error message 20002, severity 9:\nAdaptive Server connection failed (172.24.32.210)\nDB-Lib error message 20002, severity 9:\nAdaptive Server connection failed (172.24.32.210)\n')

The above exception was the direct cause of the following exception:

Traceback (most recent call last):
  File "D:\CDL\CDL-Barcode-Checker\cdl_barcode_checker\lib\site-packages\flask\app.py", line 2525, in wsgi_app
    response = self.full_dispatch_request()
  File "D:\CDL\CDL-Barcode-Checker\cdl_barcode_checker\lib\site-packages\flask\app.py", line 1822, in full_dispatch_request
    rv = self.handle_user_exception(e)
  File "D:\CDL\CDL-Barcode-Checker\cdl_barcode_checker\lib\site-packages\flask\app.py", line 1820, in full_dispatch_request
    rv = self.dispatch_request()
  File "D:\CDL\CDL-Barcode-Checker\cdl_barcode_checker\lib\site-packages\flask\app.py", line 1796, in dispatch_request
    return self.ensure_sync(self.view_functions[rule.endpoint])(**view_args)
  File "D:\CDL\CDL-Barcode-Checker\.\barcode_checker\main\routes.py", line 48, in lookup_rte
    records = [r._asdict() for r in dbquery.all()]
  File "D:\CDL\CDL-Barcode-Checker\cdl_barcode_checker\lib\site-packages\sqlalchemy\orm\query.py", line 3373, in all
    return list(self)
  File "D:\CDL\CDL-Barcode-Checker\cdl_barcode_checker\lib\site-packages\sqlalchemy\orm\query.py", line 3535, in __iter__
    return self._execute_and_instances(context)
  File "D:\CDL\CDL-Barcode-Checker\cdl_barcode_checker\lib\site-packages\sqlalchemy\orm\query.py", line 3556, in _execute_and_instances
    conn = self._get_bind_args(
  File "D:\CDL\CDL-Barcode-Checker\cdl_barcode_checker\lib\site-packages\sqlalchemy\orm\query.py", line 3571, in _get_bind_args
    return fn(
  File "D:\CDL\CDL-Barcode-Checker\cdl_barcode_checker\lib\site-packages\sqlalchemy\orm\query.py", line 3550, in _connection_from_session
    conn = self.session.connection(**kw)
  File "D:\CDL\CDL-Barcode-Checker\cdl_barcode_checker\lib\site-packages\sqlalchemy\orm\session.py", line 1142, in connection
    return self._connection_for_bind(
  File "D:\CDL\CDL-Barcode-Checker\cdl_barcode_checker\lib\site-packages\sqlalchemy\orm\session.py", line 1150, in _connection_for_bind
    return self.transaction._connection_for_bind(
  File "D:\CDL\CDL-Barcode-Checker\cdl_barcode_checker\lib\site-packages\sqlalchemy\orm\session.py", line 433, in _connection_for_bind
    conn = bind._contextual_connect()
  File "D:\CDL\CDL-Barcode-Checker\cdl_barcode_checker\lib\site-packages\sqlalchemy\engine\base.py", line 2302, in _contextual_connect
    self._wrap_pool_connect(self.pool.connect, None),
  File "D:\CDL\CDL-Barcode-Checker\cdl_barcode_checker\lib\site-packages\sqlalchemy\engine\base.py", line 2339, in _wrap_pool_connect
    Connection._handle_dbapi_exception_noconnection(
  File "D:\CDL\CDL-Barcode-Checker\cdl_barcode_checker\lib\site-packages\sqlalchemy\engine\base.py", line 1583, in _handle_dbapi_exception_noconnection
    util.raise_(
  File "D:\CDL\CDL-Barcode-Checker\cdl_barcode_checker\lib\site-packages\sqlalchemy\util\compat.py", line 182, in raise_
    raise exception
  File "D:\CDL\CDL-Barcode-Checker\cdl_barcode_checker\lib\site-packages\sqlalchemy\engine\base.py", line 2336, in _wrap_pool_connect
    return fn()
  File "D:\CDL\CDL-Barcode-Checker\cdl_barcode_checker\lib\site-packages\sqlalchemy\pool\base.py", line 364, in connect
    return _ConnectionFairy._checkout(self)
  File "D:\CDL\CDL-Barcode-Checker\cdl_barcode_checker\lib\site-packages\sqlalchemy\pool\base.py", line 778, in _checkout
    fairy = _ConnectionRecord.checkout(pool)
  File "D:\CDL\CDL-Barcode-Checker\cdl_barcode_checker\lib\site-packages\sqlalchemy\pool\base.py", line 499, in checkout
    with util.safe_reraise():
  File "D:\CDL\CDL-Barcode-Checker\cdl_barcode_checker\lib\site-packages\sqlalchemy\util\langhelpers.py", line 68, in __exit__
    compat.raise_(
  File "D:\CDL\CDL-Barcode-Checker\cdl_barcode_checker\lib\site-packages\sqlalchemy\util\compat.py", line 182, in raise_
    raise exception
  File "D:\CDL\CDL-Barcode-Checker\cdl_barcode_checker\lib\site-packages\sqlalchemy\pool\base.py", line 497, in checkout
    dbapi_connection = rec.get_connection()
  File "D:\CDL\CDL-Barcode-Checker\cdl_barcode_checker\lib\site-packages\sqlalchemy\pool\base.py", line 610, in get_connection
    self.__connect()
  File "D:\CDL\CDL-Barcode-Checker\cdl_barcode_checker\lib\site-packages\sqlalchemy\pool\base.py", line 660, in __connect
    with util.safe_reraise():
  File "D:\CDL\CDL-Barcode-Checker\cdl_barcode_checker\lib\site-packages\sqlalchemy\util\langhelpers.py", line 68, in __exit__
    compat.raise_(
  File "D:\CDL\CDL-Barcode-Checker\cdl_barcode_checker\lib\site-packages\sqlalchemy\util\compat.py", line 182, in raise_
    raise exception
  File "D:\CDL\CDL-Barcode-Checker\cdl_barcode_checker\lib\site-packages\sqlalchemy\pool\base.py", line 656, in __connect
    connection = pool._invoke_creator(self)
  File "D:\CDL\CDL-Barcode-Checker\cdl_barcode_checker\lib\site-packages\sqlalchemy\engine\strategies.py", line 114, in connect
    return dialect.connect(*cargs, **cparams)
  File "D:\CDL\CDL-Barcode-Checker\cdl_barcode_checker\lib\site-packages\sqlalchemy\engine\default.py", line 508, in connect
    return self.dbapi.connect(*cargs, **cparams)
  File "src\pymssql\_pymssql.pyx", line 652, in pymssql._pymssql.connect
sqlalchemy.exc.OperationalError: (pymssql._pymssql.OperationalError) (18456, b'DB-Lib error message 20018, severity 14:\nGeneral SQL Server error: Check messages from the SQL Server\nDB-Lib error message 20002, severity 9:\nAdaptive Server connection failed (172.24.32.210)\nDB-Lib error message 20002, severity 9:\nAdaptive Server connection failed (172.24.32.210)\n')
(Background on this error at: http://sqlalche.me/e/13/e3q8)
2023-06-18 18:50:24,143 Exception on /lookup [POST]
Traceback (most recent call last):
  File "D:\CDL\CDL-Barcode-Checker\cdl_barcode_checker\lib\site-packages\flask\app.py", line 2525, in wsgi_app
    response = self.full_dispatch_request()
  File "D:\CDL\CDL-Barcode-Checker\cdl_barcode_checker\lib\site-packages\flask\app.py", line 1822, in full_dispatch_request
    rv = self.handle_user_exception(e)
  File "D:\CDL\CDL-Barcode-Checker\cdl_barcode_checker\lib\site-packages\flask\app.py", line 1820, in full_dispatch_request
    rv = self.dispatch_request()
  File "D:\CDL\CDL-Barcode-Checker\cdl_barcode_checker\lib\site-packages\flask\app.py", line 1796, in dispatch_request
    return self.ensure_sync(self.view_functions[rule.endpoint])(**view_args)
  File "D:\CDL\CDL-Barcode-Checker\.\barcode_checker\main\routes.py", line 34, in lookup_rte
    f.write(str(datetime.now()) + ' - '  + str(barcode))
  File "C:\Python310\lib\encodings\cp1252.py", line 19, in encode
    return codecs.charmap_encode(input,self.errors,encoding_table)[0]
UnicodeEncodeError: 'charmap' codec can't encode character '\ufffd' in position 31: character maps to <undefined>
